Workbook
Name HU_ord: HU!$B$17:$B$36
Name Qp_calc: Convolucao!$F$100
Name w1_DBT5: Pesos_postos!$B$24

Sheet Roteiro
A1: EVENTO 11 (04-08/jul/2019) - Planilha 01: dados observados e hidrologia
A3: Cores: celula AMARELA = dado de entrada (digitado/copiado das planilhas do projeto); celula VERDE = resultado-chave; demais = formulas do Excel (clique na celula para ver a conta).
A5: Abas, na ordem do raciocinio:
A6: Evento - a linha do evento 11 em eventos_processados_manuais.xlsx (todas as colunas) e o que cada uma faz no modelo.
A7: Serie_horaria - 92 leituras horarias (chuva nos 2 postos, vazao, CSS). Reproduz T_R_m3, SYY_t, SSY_Ris, SSY_Fall e Q_pico da planilha de eventos. Tambem calcula a chuva de bacia, o escoamento SCS-CN concentrado e a separacao de vazao de base.
A8: Pesos_postos - peso w1 do posto DBT5 (minimos quadrados nos 17 eventos), usado na chuva de bacia.
A9: HU - Tc (Giandotti), Tp, Tb e ordenadas do hidrograma unitario triangular do SCS.
A10: Convolucao - matriz de convolucao (chuva efetiva x HU) -> hidrograma calculado e Qp. Serve SO para validar o Qp: o Qp NAO alimenta o mapa de sedimentos.
A11: Checagem - tabela final: valor da planilha do projeto x valor recalculado aqui.
A13: A parte espacial (pixel a pixel) esta na planilha 02.

Sheet Evento
A1: Linha do evento 11 em eventos_processados_manuais.xlsx (aba Sheet1, linha de indice 11)
A3: Coluna | B3: Valor | C3: Uso no modelo
A4: Inicio | B4: 43650.5 | C4: janela do evento (inicio) - recorta a serie horaria
A5: Fim | B5: 43654.292 | C5: janela do evento (fim) - recorta a serie horaria
A6: Qb_inicio | B6: 0.9447559 | C6: vazao de base no inicio do evento (m3/s)
A7: Q_pico | B7: 20.95 | C7: Qp MEDIDO (validacao da convolucao HU)
A8: Q_min | B8: 1.819
A9: Q_mean | B9: 7.3571304
A10: Q_range | B10: 19.131
A11: T_Qmax_h | B11: 31
A12: T_Qmin_h | B12: 60
A13: Iflow | B13: 0.64533045
A14: Ris_R_m3 | B14: 1283688 | C14: parcela do volume ate o pico (ramo ascendente)
A15: Fall_R_m3 | B15: 1152993.6 | C15: parcela do volume apos o pico (ramo descendente)
A16: T_R_m3 | B16: 2436681.6 | C16: volume MEDIDO total (= soma das 92 vazoes horarias x 3600) - usado no fator f do volume restrito
A17: CSS_pico | B17: 2719.1505
A18: chuva_p1_mm | B18: 62.800003 | C18: chuva total no posto DBT5 -> IDW
A19: chuva_p2_mm | B19: 79.000002 | C19: chuva total no posto Campo Limpo Paulista -> IDW
A20: Chuva_evento_mm | B20: 74.039628 | C20: R: lamina do evento (media ponderada dos 2 postos) -> denominador de RI/R no calculo de pr
A21: Duracao_horas | B21: 91 | C21: duracao da janela (h)
A22: Tempo_precipitacao_p1_h | B22: 20
A23: Tempo_precipitacao_p2_h | B23: 23
A24: i60_p1_mm/h | B24: 11.8 | C24: intensidade 60 min no posto DBT5
A25: i60_p2_mm/h | B25: 9.400001 | C25: intensidade 60 min no posto Campo Limpo Paulista (RI usa o MAIOR dos dois)
A26: Intensidade_60min_mm/h | B26: 11.8 | C26: RI: intensidade maxima em 60 min -> numerador de RI/R no calculo de pr
A27: i120_p1_mm/h | B27: 15
A28: i120_p2_mm/h | B28: 17.2
A29: Intensidade_120min_mm | B29: 17.2
A30: IERI_p1 | B30: 0.78021978
A31: IERI_p2 | B31: 0.74725275
A32: Ap1_est1_mm | B32: 11.8
A33: Ap1_est2_mm | B33: 13.599999
A34: Ap1_pond_mm | B34: 13.048847
A35: Ap3_est1_mm | B35: 11.8
A36: Ap3_est2_mm | B36: 13.799999
A37: Ap3_pond_mm | B37: 13.187607
A38: Ap5_est1_mm | B38: 12
... A64: CSS_range | B64: 2594.8671
A65: SYY_t | B65: 1821.7535 | C65: SY OBSERVADO (t) - alvo da calibracao de c
A66: SYYmax_t | B66: 78.12026
...

Sheet Pesos_postos
A1: Peso w1 do posto DBT5 na chuva de bacia (minimos quadrados nos 17 eventos)
A2: Modelo: R_evento = w1*p1 + (1-w1)*p2 => (R-p2) = w1*(p1-p2). Solucao por minimos quadrados pela origem: w1 = SUM[(p1-p2)(R-p2)] / SUM[(p1-p2)^2].
A4: Evento | B4: p1 DBT5 (mm) | C4: p2 CLP (mm) | D4: R_evento (mm) | E4: p1-p2 | F4: R-p2 | G4: R estimado (mm)
A5: 1 | B5: 32.8 | C5: 19.2 | D5: 23.364265 | E5: =B5-C5 -> 13.6 | F5: =D5-C5 -> 4.1642652 | G5: =$B$24*B5+(1-$B$24)*C5 -> 23.379677
A6: 2 | B6: 64 | C6: 54.400002 | D6: 57.339482 | E6: =B6-C6 -> 9.5999984 | F6: =D6-C6 -> 2.9394808 | G6: =$B$24*B6+(1-$B$24)*C6 -> 57.350362
A7: 3 | B7: 50.999999 | C7: 71.8 | D7: 65.431124 | E7: =B7-C7 -> -20.800002 | F7: =D7-C7 -> -6.3688766 | G7: =$B$24*B7+(1-$B$24)*C7 -> 65.407552
A8: 4 | B8: 56.999997 | C8: 27.000002 | D8: 36.185879 | E8: =B8-C8 -> 29.999995 | F8: =D8-C8 -> 9.1858776 | G8: =$B$24*B8+(1-$B$24)*C8 -> 36.219877
A9: 5 | B9: 23.999999 | C9: 77.200003 | D9: 60.910376 | E9: =B9-C9 -> -53.200003 | F9: =D9-C9 -> -16.289626 | G9: =$B$24*B9+(1-$B$24)*C9 -> 60.850087
A10: 6 | B10: 11 | C10: 44.799999 | D10: 34.450576 | E10: =B10-C10 -> -33.799999 | F10: =D10-C10 -> -10.349423 | G10: =$B$24*B10+(1-$B$24)*C10 -> 34.412272
A11: 7 | B11: 29.000001 | C11: 38.4 | D11: 35.521758 | E11: =B11-C11 -> -9.3999998 | F11: =D11-C11 -> -2.878242 | G11: =$B$24*B11+(1-$B$24)*C11 -> 35.511106
A12: 8 | B12: 48.399998 | C12: 97.600002 | D12: 82.535159 | E12: =B12-C12 -> -49.200004 | F12: =D12-C12 -> -15.064843 | G12: =$B$24*B12+(1-$B$24)*C12 -> 82.479403
A13: 9 | B13: 57.000002 | C13: 108.8 | D13: 92.939051 | E13: =B13-C13 -> -51.8 | F13: =D13-C13 -> -15.860951 | G13: =$B$24*B13+(1-$B$24)*C13 -> 92.880348
A14: 10 | B14: 14.399999 | C14: 30.799999 | D14: 25.778385 | E14: =B14-C14 -> -16.4 | F14: =D14-C14 -> -5.0216138 | G14: =$B$24*B14+(1-$B$24)*C14 -> 25.7598
A15: 11 | B15: 62.800003 | C15: 79.000002 | D15: 74.039628 | E15: =B15-C15 -> -16.199999 | F15: =D15-C15 -> -4.9603743 | G15: =$B$24*B15+(1-$B$24)*C15 -> 74.021269
A16: 12 | B16: 0 | C16: 34.200001 | D16: 23.728099 | E16: =B16-C16 -> -34.200001 | F16: =D16-C16 -> -10.471902 | G16: =$B$24*B16+(1-$B$24)*C16 -> 23.689342
... A21: 17 | B21: 67.999999 | C21: 64.600003 | D21: 65.641068 | E21: =B21-C21 -> 3.3999959 | F21: =D21-C21 -> 1.041065 | G21: =$B$24*B21+(1-$B$24)*C21 -> 65.644921
A23: Calculo de w1
A24: w1 (DBT5) | B24: =MIN(MAX(SUMPRODUCT(E5:E21,F5:F21)/SUMSQ(E5:E21),0),1) -> 0.30732921
A25: 1 - w1 (CLP) | B25: =1-B24 -> 0.69267079
A26: Obs.: para o evento 11, w1*62,8 + (1-w1)*79,0 reproduz Chuva_evento_mm = 74,0396 (ver aba Checagem).

Sheet Serie_horaria
A1: Data/hora | B1: P DBT5 (mm/h) | C1: P Campo Limpo (mm/h) | D1: Q medida (m3/s) | E1: CSS (mg/L) | F1: Q base Bt (m3/s) | G1: Volume na hora (m3) = Q*3600 | H1: Carga na hora (t) = Q*CSS*3600/1e6 | I1: Ramo (asc ate o pico, desc depois) | J1: P bacia (mm) = w1*P1+(1-w1)*P2 | K1: P acumulada (mm) | L1: Q SCS acumulado (mm) | M1: Q SCS incremental (mm) | N1: Q SCS incremental (cm) | O1: Escoamento direto medido (m3) = (Q-Bt)*3600 | Q1: Parametros e resultados | R1: Valor | S1: Comentario
A2: 43650.5 | B2: 0 | C2: 3.4000006 | D2: 1.869 | E2: 263.19753 | F2: 0.9447559 | G2: =D2*3600 -> 6728.4 | H2: =D2*E2*3600/1000000 -> 1.7708982 | I2: =IF(A2<=$R$8,"asc","desc") -> asc | J2: =w1_DBT5*B2+(1-w1_DBT5)*C2 -> 2.3550811 | K2: =SUM(J$2:J2) -> 2.3550811 | L2: =IF(K2<=$R$4*$R$5,0,(K2-$R$4*$R$5)^2/(K2+(1-$R$4)*$R$5)) -> 0 | M2: =L2 -> 0 | N2: =M2/10 -> 0 | O2: =(D2-F2)*3600 -> 3327.2788
A3: 43650.542 | B3: 1.4000006 | C3: 0 | D3: 1.819 | E3: 1094.8862 | F3: 0.95008311 | G3: =D3*3600 -> 6548.4 | H3: =D3*E3*3600/1000000 -> 7.169753 | I3: =IF(A3<=$R$8,"asc","desc") -> asc | J3: =w1_DBT5*B3+(1-w1_DBT5)*C3 -> 0.43026108 | K3: =SUM(J$2:J3) -> 2.7853422 | L3: =IF(K3<=$R$4*$R$5,0,(K3-$R$4*$R$5)^2/(K3+(1-$R$4)*$R$5)) -> 0 | M3: =L3-L2 -> 0 | N3: =M3/10 -> 0 | O3: =(D3-F3)*3600 -> 3128.1008 | Q3: w1 (peso DBT5) | R3: =w1_DBT5 -> 0.30732921 | S3: aba Pesos_postos
A4: 43650.583 | B4: 0 | C4: 1 | D4: 2.589 | E4: 1178.4279 | F4: 0.96412801 | G4: =D4*3600 -> 9320.4 | H4: =D4*E4*3600/1000000 -> 10.98342 | I4: =IF(A4<=$R$8,"asc","desc") -> asc | J4: =w1_DBT5*B4+(1-w1_DBT5)*C4 -> 0.69267079 | K4: =SUM(J$2:J4) -> 3.478013 | L4: =IF(K4<=$R$4*$R$5,0,(K4-$R$4*$R$5)^2/(K4+(1-$R$4)*$R$5)) -> 0 | M4: =L4-L3 -> 0 | N4: =M4/10 -> 0 | O4: =(D4-F4)*3600 -> 5849.5392 | Q4: lambda (Ia = lambda*S) | R4: 0.05 | S4: adotado: 0,05 (calibrado; ver notas)
A5: 43650.625 | B5: 3.1999998 | C5: 9.400001 | D5: 2.049 | E5: 1171.4275 | F5: 0.971768 | G5: =D5*3600 -> 7376.4 | H5: =D5*E5*3600/1000000 -> 8.640918 | I5: =IF(A5<=$R$8,"asc","desc") -> asc | J5: =w1_DBT5*B5+(1-w1_DBT5)*C5 -> 7.4945595 | K5: =SUM(J$2:J5) -> 10.972572 | L5: =IF(K5<=$R$4*$R$5,0,(K5-$R$4*$R$5)^2/(K5+(1-$R$4)*$R$5)) -> 0 | M5: =L5-L4 -> 0 | N5: =M5/10 -> 0 | O5: =(D5-F5)*3600 -> 3878.0352 | Q5: S medio da bacia, CN-I (mm) | R5: 255.69405 | S5: media do raster S - Seco recortado pela mascara (script spatialPeakFlowHU_convolucao.py)
A6: 43650.667 | B6: 11.8 | C6: 7.799999 | D6: 2.723 | E6: 1332.1822 | F6: 0.98699004 | G6: =D6*3600 -> 9802.8 | H6: =D6*E6*3600/1000000 -> 13.059115 | I6: =IF(A6<=$R$8,"asc","desc") -> asc | J6: =w1_DBT5*B6+(1-w1_DBT5)*C6 -> 9.0293162 | K6: =SUM(J$2:J6) -> 20.001889 | L6: =IF(K6<=$R$4*$R$5,0,(K6-$R$4*$R$5)^2/(K6+(1-$R$4)*$R$5)) -> 0.19811924 | M6: =L6-L5 -> 0.19811924 | N6: =M6/10 -> 0.019811924 | O6: =(D6-F6)*3600 -> 6249.6358
A7: 43650.708 | B7: 1.7999992 | C7: 1.7999992 | D7: 2.242 | E7: 2485.5793 | F7: 0.99646255 | G7: =D7*3600 -> 8071.2 | H7: =D7*E7*3600/1000000 -> 20.061607 | I7: =IF(A7<=$R$8,"asc","desc") -> asc | J7: =w1_DBT5*B7+(1-w1_DBT5)*C7 -> 1.7999992 | K7: =SUM(J$2:J7) -> 21.801888 | L7: =IF(K7<=$R$4*$R$5,0,(K7-$R$4*$R$5)^2/(K7+(1-$R$4)*$R$5)) -> 0.3071635 | M7: =L7-L6 -> 0.10904426 | N7: =M7/10 -> 0.010904426 | O7: =(D7-F7)*3600 -> 4483.9348 | Q7: Q medida maxima (m3/s) | R7: =MAX($D$2:$D$93) -> 20.95 | S7: igual ao Q_pico da planilha de eventos
A8: 43650.75 | B8: 2.3999996 | C8: 8.799999 | D8: 2.318 | E8: 2719.1505 | F8: 1.006649 | G8: =D8*3600 -> 8344.8 | H8: =D8*E8*3600/1000000 -> 22.690767 | I8: =IF(A8<=$R$8,"asc","desc") -> asc | J8: =w1_DBT5*B8+(1-w1_DBT5)*C8 -> 6.8330922 | K8: =SUM(J$2:J8) -> 28.63498 | L8: =IF(K8<=$R$4*$R$5,0,(K8-$R$4*$R$5)^2/(K8+(1-$R$4)*$R$5)) -> 0.92519441 | M8: =L8-L7 -> 0.61803091 | N8: =M8/10 -> 0.061803091 | O8: =(D8-F8)*3600 -> 4720.8637 | Q8: Data/hora do pico | R8: =INDEX($A$2:$A$93,MATCH(MAX($D$2:$D$93),$D$2:$D$93,0)) -> 43651.792
A9: 43650.792 | B9: 5.200001 | C9: 4 | D9: 6.704 | E9: 2432.3876 | F9: 1.0668225 | G9: =D9*3600 -> 24134.4 | H9: =D9*E9*3600/1000000 -> 58.704216 | I9: =IF(A9<=$R$8,"asc","desc") -> asc | J9: =w1_DBT5*B9+(1-w1_DBT5)*C9 -> 4.3687954 | K9: =SUM(J$2:J9) -> 33.003775 | L9: =IF(K9<=$R$4*$R$5,0,(K9-$R$4*$R$5)^2/(K9+(1-$R$4)*$R$5)) -> 1.4816653 | M9: =L9-L8 -> 0.5564709 | N9: =M9/10 -> 0.05564709 | O9: =(D9-F9)*3600 -> 20293.839 | Q9: Numero de leituras horarias | R9: =COUNT($D$2:$D$93) -> 92 | S9: 91 intervalos de 1 h, 92 pontos
A10: 43650.833 | B10: 7.200001 | C10: 8.400002 | D10: 4.575 | E10: 2035.9014 | F10: 1.1016653 | G10: =D10*3600 -> 16470 | H10: =D10*E10*3600/1000000 -> 33.531296 | I10: =IF(A10<=$R$8,"asc","desc") -> asc | J10: =w1_DBT5*B10+(1-w1_DBT5)*C10 -> 8.0312066 | K10: =SUM(J$2:J10) -> 41.034982 | L10: =IF(K10<=$R$4*$R$5,0,(K10-$R$4*$R$5)^2/(K10+(1-$R$4)*$R$5)) -> 2.8106858 | M10: =L10-L9 -> 1.3290205 | N10: =M10/10 -> 0.13290205 | O10: =(D10-F10)*3600 -> 12504.005 | Q10: Soma da chuva DBT5 (mm) | R10: =SUM($B$2:$B$93) -> 62.800003 | S10: planilha: chuva_p1_mm = 62,800003
A11: 43650.875 | B11: 4 | C11: 2.2000008 | D11: 4.967 | E11: 1725.2415 | F11: 1.14042 | G11: =D11*3600 -> 17881.2 | H11: =D11*E11*3600/1000000 -> 30.849388 | I11: =IF(A11<=$R$8,"asc","desc") -> asc | J11: =w1_DBT5*B11+(1-w1_DBT5)*C11 -> 2.7531931 | K11: =SUM(J$2:J11) -> 43.788175 | L11: =IF(K11<=$R$4*$R$5,0,(K11-$R$4*$R$5)^2/(K11+(1-$R$4)*$R$5)) -> 3.3527158 | M11: =L11-L10 -> 0.54203001 | N11: =M11/10 -> 0.054203001 | O11: =(D11-F11)*3600 -> 13775.688 | Q11: Soma da chuva Campo Limpo (mm) | R11: =SUM($C$2:$C$93) -> 79.000002 | S11: planilha: chuva_p2_mm = 79,000002
A12: 43650.917 | B12: 3.3999977 | C12: 7.799999 | D12: 8.31 | E12: 1649.6816 | F12: 1.2167672 | G12: =D12*3600 -> 29916 | H12: =D12*E12*3600/1000000 -> 49.351876 | I12: =IF(A12<=$R$8,"asc","desc") -> asc | J12: =w1_DBT5*B12+(1-w1_DBT5)*C12 -> 6.4477501 | K12: =SUM(J$2:J12) -> 50.235925 | L12: =IF(K12<=$R$4*$R$5,0,(K12-$R$4*$R$5)^2/(K12+(1-$R$4)*$R$5)) -> 4.7846382 | M12: =L12-L11 -> 1.4319224 | N12: =M12/10 -> 0.14319224 | O12: =(D12-F12)*3600 -> 25535.638 | Q12: Chuva de bacia, soma (mm) = R | R12: =SUM($J$2:$J$93) -> 74.021269 | S12: planilha: Chuva_evento_mm = 74,039628
A13: 43650.958 | B13: 3.6000023 | C13: 0.80000305 | D13: 8.769 | E13: 1537.3774 | F13: 1.2971127 | G13: =D13*3600 -> 31568.4 | H13: =D13*E13*3600/1000000 -> 48.532544 | I13: =IF(A13<=$R$8,"asc","desc") -> asc | J13: =w1_DBT5*B13+(1-w1_DBT5)*C13 -> 1.6605246 | K13: =SUM(J$2:J13) -> 51.89645 | L13: =IF(K13<=$R$4*$R$5,0,(K13-$R$4*$R$5)^2/(K13+(1-$R$4)*$R$5)) -> 5.1889372 | M13: =L13-L12 -> 0.40429899 | N13: =M13/10 -> 0.040429899 | O13: =(D13-F13)*3600 -> 26898.794 | Q13: Volume total medido T_R (m3) = soma(Q)*3600 | R13: =SUM($G$2:$G$93) -> 2436681.6 | S13: planilha: T_R_m3 = 2.436.681,6 (INCLUI vazao de base!)
A14: 43651 | B14: 1.3999977 | C14: 1.5999985 | D14: 10.142 | E14: 1399.5598 | F14: 1.3918425 | G14: =D14*3600 -> 36511.2 | H14: =D14*E14*3600/1000000 -> 51.099609 | I14: =IF(A14<=$R$8,"asc","desc") -> asc | J14: =w1_DBT5*B14+(1-w1_DBT5)*C14 -> 1.5385324 | K14: =SUM(J$2:J14) -> 53.434982 | L14: =IF(K14<=$R$4*$R$5,0,(K14-$R$4*$R$5)^2/(K14+(1-$R$4)*$R$5)) -> 5.5760987 | M14: =L14-L13 -> 0.3871615 | N14: =M14/10 -> 0.03871615 | O14: =(D14-F14)*3600 -> 31500.567 | Q14: Ris_R (m3): ate o pico | R14: =SUMIF($I$2:$I$93,"asc",$G$2:$G$93) -> 1283688 | S14: planilha: Ris_R_m3 = 1.283.688,0
A15: 43651.042 | B15: 2.2000008 | C15: 2.4000015 | D15: 10.68 | E15: 811.70087 | F15: 1.4911729 | G15: =D15*3600 -> 38448 | H15: =D15*E15*3600/1000000 -> 31.208275 | I15: =IF(A15<=$R$8,"asc","desc") -> asc | J15: =w1_DBT5*B15+(1-w1_DBT5)*C15 -> 2.3385354 | K15: =SUM(J$2:J15) -> 55.773518 | L15: =IF(K15<=$R$4*$R$5,0,(K15-$R$4*$R$5)^2/(K15+(1-$R$4)*$R$5)) -> 6.1872924 | M15: =L15-L14 -> 0.61119369 | N15: =M15/10 -> 0.061119369 | O15: =(D15-F15)*3600 -> 33079.778 | Q15: Fall_R (m3): depois do pico | R15: =SUMIF($I$2:$I$93,"desc",$G$2:$G$93) -> 1152993.6 | S15: planilha: Fall_R_m3 = 1.152.993,6
A16: 43651.083 | B16: 1.7999992 | C16: 7.7999954 | D16: 13.691 | E16: 1142.1434 | F16: 1.6233072 | G16: =D16*3600 -> 49287.6 | H16: =D16*E16*3600/1000000 -> 56.293509 | I16: =IF(A16<=$R$8,"asc","desc") -> asc | J16: =w1_DBT5*B16+(1-w1_DBT5)*C16 -> 5.9560213 | K16: =SUM(J$2:J16) -> 61.729539 | L16: =IF(K16<=$R$4*$R$5,0,(K16-$R$4*$R$5)^2/(K16+(1-$R$4)*$R$5)) -> 7.8637269 | M16: =L16-L15 -> 1.6764345 | N16: =M16/10 -> 0.16764345 | O16: =(D16-F16)*3600 -> 43443.694 | Q16: SY observado SYY_t (t) = soma(Q*CSS*3600/1e6) | R16: =SUM($H$2:$H$93) -> 1821.7535 | S16: planilha: SYY_t = 1.821,7535 (carga TOTAL: inclui sedimento da vazao de base)
A17: 43651.125 | B17: 5 | C17: 2.2000046 | D17: 12.783 | E17: 1086.5633 | F17: 1.7428944 | G17: =D17*3600 -> 46018.8 | H17: =D17*E17*3600/1000000 -> 50.002339 | I17: =IF(A17<=$R$8,"asc","desc") -> asc | J17: =w1_DBT5*B17+(1-w1_DBT5)*C17 -> 3.060525 | K17: =SUM(J$2:J17) -> 64.790064 | L17: =IF(K17<=$R$4*$R$5,0,(K17-$R$4*$R$5)^2/(K17+(1-$R$4)*$R$5)) -> 8.7896093 | M17: =L17-L16 -> 0.9258824 | N17: =M17/10 -> 0.09258824 | O17: =(D17-F17)*3600 -> 39744.38 | Q17: SSY_Ris (t): ate o pico | R17: =SUMIF($I$2:$I$93,"asc",$H$2:$H$93) -> 1239.8365 | S17: planilha: SSY_Ris_t = 1.239,8365
A18: 43651.167 | B18: 2 | C18: 4.399994 | D18: 13.215 | E18: 965.18076 | F18: 1.8654631 | G18: =D18*3600 -> 47574 | H18: =D18*E18*3600/1000000 -> 45.91751 | I18: =IF(A18<=$R$8,"asc","desc") -> asc | J18: =w1_DBT5*B18+(1-w1_DBT5)*C18 -> 3.6624057 | K18: =SUM(J$2:J18) -> 68.45247 | L18: =IF(K18<=$R$4*$R$5,0,(K18-$R$4*$R$5)^2/(K18+(1-$R$4)*$R$5)) -> 9.9527306 | M18: =L18-L17 -> 1.1631213 | N18: =M18/10 -> 0.11631213 | O18: =(D18-F18)*3600 -> 40858.333 | Q18: SSY_Fall (t): depois do pico | R18: =SUMIF($I$2:$I$93,"desc",$H$2:$H$93) -> 581.91704 | S18: planilha: SSY_Fall_t = 581,9170
A19: 43651.208 | B19: 1.4000015 | C19: 0.40000153 | D19: 14.092 | E19: 843.58539 | F19: 1.9960527 | G19: =D19*3600 -> 50731.2 | H19: =D19*E19*3600/1000000 -> 42.796099 | I19: =IF(A19<=$R$8,"asc","desc") -> asc | J19: =w1_DBT5*B19+(1-w1_DBT5)*C19 -> 0.70733073 | K19: =SUM(J$2:J19) -> 69.1598 | L19: =IF(K19<=$R$4*$R$5,0,(K19-$R$4*$R$5)^2/(K19+(1-$R$4)*$R$5)) -> 10.184126 | M19: =L19-L18 -> 0.2313958 | N19: =M19/10 -> 0.02313958 | O19: =(D19-F19)*3600 -> 43545.41
A20: 43651.25 | B20: 0.40000153 | C20: 2.4000015 | D20: 16.278 | E20: 931.2993 | F20: 2.1495006 | G20: =D20*3600 -> 58600.8 | H20: =D20*E20*3600/1000000 -> 54.574884 | I20: =IF(A20<=$R$8,"asc","desc") -> asc | J20: =w1_DBT5*B20+(1-w1_DBT5)*C20 -> 1.7853431 | K20: =SUM(J$2:J20) -> 70.945144 | L20: =IF(K20<=$R$4*$R$5,0,(K20-$R$4*$R$5)^2/(K20+(1-$R$4)*$R$5)) -> 10.777723 | M20: =L20-L19 -> 0.59359696 | N20: =M20/10 -> 0.059359696 | O20: =(D20-F20)*3600 -> 50862.598 | Q20: Volume da vazao de base Bt (m3) = soma(Bt)*3600 | R20: =SUM($F$2:$F$93)*3600 -> 957727.06 | S20: Bt = linha de base da serie (separacao feita pelos autores dos dados)
A21: 43651.292 | B21: 3.4000015 | C21: 1.0000015 | D21: 15.276 | E21: 605.94238 | F21: 2.2889774 | G21: =D21*3600 -> 54993.6 | H21: =D21*E21*3600/1000000 -> 33.322953 | I21: =IF(A21<=$R$8,"asc","desc") -> asc | J21: =w1_DBT5*B21+(1-w1_DBT5)*C21 -> 1.7375916 | K21: =SUM(J$2:J21) -> 72.682735 | L21: =IF(K21<=$R$4*$R$5,0,(K21-$R$4*$R$5)^2/(K21+(1-$R$4)*$R$5)) -> 11.368391 | M21: =L21-L20 -> 0.59066796 | N21: =M21/10 -> 0.059066796 | O21: =(D21-F21)*3600 -> 46753.282 | Q21: Escoamento direto medido (m3) = soma(Q-Bt)*3600 | R21: =SUM($O$2:$O$93) -> 1478954.5
A22: 43651.333 | B22: 1 | C22: 0.79999995 | D22: 16.11 | E22: 380.07129 | F22: 2.4357066 | G22: =D22*3600 -> 57996 | H22: =D22*E22*3600/1000000 -> 22.042615 | I22: =IF(A22<=$R$8,"asc","desc") -> asc | J22: =w1_DBT5*B22+(1-w1_DBT5)*C22 -> 0.86146581 | K22: =SUM(J$2:J22) -> 73.544201 | L22: =IF(K22<=$R$4*$R$5,0,(K22-$R$4*$R$5)^2/(K22+(1-$R$4)*$R$5)) -> 11.665904 | M22: =L22-L21 -> 0.29751241 | N22: =M22/10 -> 0.029751241 | O22: =(D22-F22)*3600 -> 49227.456 | Q22: Fracao do T_R que e vazao de base | R22: =R20/R13 -> 0.39304563 | S22: ATENCAO: o T_R_m3 usado como 'volume medido' contem vazao de base
A23: 43651.375 | B23: 0 | C23: 0.20000005 | D23: 15.414 | E23: 597.64484 | F23: 2.572074 | G23: =D23*3600 -> 55490.4 | H23: =D23*E23*3600/1000000 -> 33.163551 | I23: =IF(A23<=$R$8,"asc","desc") -> asc | J23: =w1_DBT5*B23+(1-w1_DBT5)*C23 -> 0.13853419 | K23: =SUM(J$2:J23) -> 73.682735 | L23: =IF(K23<=$R$4*$R$5,0,(K23-$R$4*$R$5)^2/(K23+(1-$R$4)*$R$5)) -> 11.714034 | M23: =L23-L22 -> 0.048130076 | N23: =M23/10 -> 0.0048130076 | O23: =(D23-F23)*3600 -> 46230.934
A24: 43651.417 | B24: 0 | C24: 0 | D24: 15.414 | E24: 636.80661 | F24: 2.706208 | G24: =D24*3600 -> 55490.4 | H24: =D24*E24*3600/1000000 -> 35.336653 | I24: =IF(A24<=$R$8,"asc","desc") -> asc | J24: =w1_DBT5*B24+(1-w1_DBT5)*C24 -> 0 | K24: =SUM(J$2:J24) -> 73.682735 | L24: =IF(K24<=$R$4*$R$5,0,(K24-$R$4*$R$5)^2/(K24+(1-$R$4)*$R$5)) -> 11.714034 | M24: =L24-L23 -> 0 | N24: =M24/10 -> 0 | O24: =(D24-F24)*3600 -> 45748.051 | Q24: Chuva de bacia acumulada final (mm) | R24: =K93 -> 74.021269
A25: 43651.458 | B25: 0 | C25: 0 | D25: 14.919 | E25: 675.36538 | F25: 2.8324849 | G25: =D25*3600 -> 53708.4 | H25: =D25*E25*3600/1000000 -> 36.272794 | I25: =IF(A25<=$R$8,"asc","desc") -> asc | J25: =w1_DBT5*B25+(1-w1_DBT5)*C25 -> 0 | K25: =SUM(J$2:J25) -> 73.682735 | L25: =IF(K25<=$R$4*$R$5,0,(K25-$R$4*$R$5)^2/(K25+(1-$R$4)*$R$5)) -> 11.714034 | M25: =L25-L24 -> 0 | N25: =M25/10 -> 0 | O25: =(D25-F25)*3600 -> 43511.454 | Q25: Escoamento SCS-CN concentrado total (mm) | R25: =L93 -> 11.831981 | S25: usando S medio e P de bacia (visao concentrada)
A26: 43651.5 | B26: 0 | C26: 0 | D26: 14.646 | E26: 645.65181 | F26: 2.9535719 | G26: =D26*3600 -> 52725.6 | H26: =D26*E26*3600/1000000 -> 34.042379 | I26: =IF(A26<=$R$8,"asc","desc") -> asc | J26: =w1_DBT5*B26+(1-w1_DBT5)*C26 -> 0 | K26: =SUM(J$2:J26) -> 73.682735 | L26: =IF(K26<=$R$4*$R$5,0,(K26-$R$4*$R$5)^2/(K26+(1-$R$4)*$R$5)) -> 11.714034 | M26: =L26-L25 -> 0 | N26: =M26/10 -> 0 | O26: =(D26-F26)*3600 -> 42092.741 | Q26: Escoamento SCS-CN concentrado (m3) = mm/1000*138 km2 | R26: =R25/1000*138*1000000 -> 1632813.4 | S26: so para comparar com o espacializado (IDW pixel a pixel)
A27: 43651.542 | B27: 0 | C27: 0 | D27: 14.619 | E27: 700.76185 | F27: 3.0723669 | G27: =D27*3600 -> 52628.4 | H27: =D27*E27*3600/1000000 -> 36.879975 | I27: =IF(A27<=$R$8,"asc","desc") -> asc | J27: =w1_DBT5*B27+(1-w1_DBT5)*C27 -> 0 | K27: =SUM(J$2:J27) -> 73.682735 | L27: =IF(K27<=$R$4*$R$5,0,(K27-$R$4*$R$5)^2/(K27+(1-$R$4)*$R$5)) -> 11.714034 | M27: =L27-L26 -> 0 | N27: =M27/10 -> 0 | O27: =(D27-F27)*3600 -> 41567.879
A28: 43651.583 | B28: 0 | C28: 0 | D28: 15.359 | E28: 753.48492 | F28: 3.1976783 | G28: =D28*3600 -> 55292.4 | H28: =D28*E28*3600/1000000 -> 41.661989 | I28: =IF(A28<=$R$8,"asc","desc") -> asc | J28: =w1_DBT5*B28+(1-w1_DBT5)*C28 -> 0 | K28: =SUM(J$2:J28) -> 73.682735 | L28: =IF(K28<=$R$4*$R$5,0,(K28-$R$4*$R$5)^2/(K28+(1-$R$4)*$R$5)) -> 11.714034 | M28: =L28-L27 -> 0 | N28: =M28/10 -> 0 | O28: =(D28-F28)*3600 -> 43780.758 | Q28: Leitura do aviso:
A29: 43651.625 | B29: 0 | C29: 0 | D29: 16.32 | E29: 741.70609 | F29: 3.3319264 | G29: =D29*3600 -> 58752 | H29: =D29*E29*3600/1000000 -> 43.576716 | I29: =IF(A29<=$R$8,"asc","desc") -> asc | J29: =w1_DBT5*B29+(1-w1_DBT5)*C29 -> 0 | K29: =SUM(J$2:J29) -> 73.682735 | L29: =IF(K29<=$R$4*$R$5,0,(K29-$R$4*$R$5)^2/(K29+(1-$R$4)*$R$5)) -> 11.714034 | M29: =L29-L28 -> 0 | N29: =M29/10 -> 0 | O29: =(D29-F29)*3600 -> 46757.065 | Q29: T_R_m3 (planilha) = soma das 92 vazoes horarias x 3600, ou seja, volume TOTAL escoado no exutorio, que inclui a vazao de base. O SCS-CN calcula apenas o escoamento DIRETO. Para o evento 11: total 2,437 milhoes m3; vazao de base (Bt) ~0,96 milhao m3; direto ~1,479 milhao m3. Ver o impacto no fator f do volume restrito na planilha 02 e no texto da conversa.
A30: 43651.667 | B30: 0 | C30: 0 | D30: 17.948 | E30: 968.2458 | F30: 3.4825919 | G30: =D30*3600 -> 64612.8 | H30: =D30*E30*3600/1000000 -> 62.561072 | I30: =IF(A30<=$R$8,"asc","desc") -> asc | J30: =w1_DBT5*B30+(1-w1_DBT5)*C30 -> 0 | K30: =SUM(J$2:J30) -> 73.682735 | L30: =IF(K30<=$R$4*$R$5,0,(K30-$R$4*$R$5)^2/(K30+(1-$R$4)*$R$5)) -> 11.714034 | M30: =L30-L29 -> 0 | N30: =M30/10 -> 0 | O30: =(D30-F30)*3600 -> 52075.469
A31: 43651.708 | B31: 0 | C31: 0 | D31: 19.416 | E31: 1065.0865 | F31: 3.6475765 | G31: =D31*3600 -> 69897.6 | H31: =D31*E31*3600/1000000 -> 74.446989 | I31: =IF(A31<=$R$8,"asc","desc") -> asc | J31: =w1_DBT5*B31+(1-w1_DBT5)*C31 -> 0 | K31: =SUM(J$2:J31) -> 73.682735 | L31: =IF(K31<=$R$4*$R$5,0,(K31-$R$4*$R$5)^2/(K31+(1-$R$4)*$R$5)) -> 11.714034 | M31: =L31-L30 -> 0 | N31: =M31/10 -> 0 | O31: =(D31-F31)*3600 -> 56766.325
A32: 43651.75 | B32: 0 | C32: 0 | D32: 20.374 | E32: 1065.0865 | F32: 3.8208137 | G32: =D32*3600 -> 73346.4 | H32: =D32*E32*3600/1000000 -> 78.12026 | I32: =IF(A32<=$R$8,"asc","desc") -> asc | J32: =w1_DBT5*B32+(1-w1_DBT5)*C32 -> 0 | K32: =SUM(J$2:J32) -> 73.682735 | L32: =IF(K32<=$R$4*$R$5,0,(K32-$R$4*$R$5)^2/(K32+(1-$R$4)*$R$5)) -> 11.714034 | M32: =L32-L31 -> 0 | N32: =M32/10 -> 0 | O32: =(D32-F32)*3600 -> 59591.471
A33: 43651.792 | B33: 0 | C33: 0 | D33: 20.95 | E33: 943.65551 | F33: 3.9978001 | G33: =D33*3600 -> 75420 | H33: =D33*E33*3600/1000000 -> 71.170498 | I33: =IF(A33<=$R$8,"asc","desc") -> asc | J33: =w1_DBT5*B33+(1-w1_DBT5)*C33 -> 0 | K33: =SUM(J$2:J33) -> 73.682735 | L33: =IF(K33<=$R$4*$R$5,0,(K33-$R$4*$R$5)^2/(K33+(1-$R$4)*$R$5)) -> 11.714034 | M33: =L33-L32 -> 0 | N33: =M33/10 -> 0 | O33: =(D33-F33)*3600 -> 61027.919
A34: 43651.833 | B34: 0 | C34: 0 | D34: 20.495 | E34: 931.2993 | F34: 4.1666851 | G34: =D34*3600 -> 73782 | H34: =D34*E34*3600/1000000 -> 68.713125 | I34: =IF(A34<=$R$8,"asc","desc") -> desc | J34: =w1_DBT5*B34+(1-w1_DBT5)*C34 -> 0 | K34: =SUM(J$2:J34) -> 73.682735 | L34: =IF(K34<=$R$4*$R$5,0,(K34-$R$4*$R$5)^2/(K34+(1-$R$4)*$R$5)) -> 11.714034 | M34: =L34-L33 -> 0 | N34: =M34/10 -> 0 | O34: =(D34-F34)*3600 -> 58781.934
A35: 43651.875 | B35: 0 | C35: 0 | D35: 19.878 | E35: 779.49482 | F35: 4.3257486 | G35: =D35*3600 -> 71560.8 | H35: =D35*E35*3600/1000000 -> 55.781273 | I35: =IF(A35<=$R$8,"asc","desc") -> desc | J35: =w1_DBT5*B35+(1-w1_DBT5)*C35 -> 0 | K35: =SUM(J$2:J35) -> 73.682735 | L35: =IF(K35<=$R$4*$R$5,0,(K35-$R$4*$R$5)^2/(K35+(1-$R$4)*$R$5)) -> 11.714034 | M35: =L35-L34 -> 0 | N35: =M35/10 -> 0 | O35: =(D35-F35)*3600 -> 55988.105
A36: 43651.917 | B36: 0 | C36: 0 | D36: 19.031 | E36: 750.21774 | F36: 4.4725216 | G36: =D36*3600 -> 68511.6 | H36: =D36*E36*3600/1000000 -> 51.398618 | I36: =IF(A36<=$R$8,"asc","desc") -> desc | J36: =w1_DBT5*B36+(1-w1_DBT5)*C36 -> 0 | K36: =SUM(J$2:J36) -> 73.682735 | L36: =IF(K36<=$R$4*$R$5,0,(K36-$R$4*$R$5)^2/(K36+(1-$R$4)*$R$5)) -> 11.714034 | M36: =L36-L35 -> 0 | N36: =M36/10 -> 0 | O36: =(D36-F36)*3600 -> 52410.522
A37: 43651.958 | B37: 0 | C37: 0 | D37: 17.992 | E37: 694.10156 | F37: 4.6050098 | G37: =D37*3600 -> 64771.2 | H37: =D37*E37*3600/1000000 -> 44.957791 | I37: =IF(A37<=$R$8,"asc","desc") -> desc | J37: =w1_DBT5*B37+(1-w1_DBT5)*C37 -> 0 | K37: =SUM(J$2:J37) -> 73.682735 | L37: =IF(K37<=$R$4*$R$5,0,(K37-$R$4*$R$5)^2/(K37+(1-$R$4)*$R$5)) -> 11.714034 | M37: =L37-L36 -> 0 | N37: =M37/10 -> 0 | O37: =(D37-F37)*3600 -> 48193.165
A38: 43652 | B38: 0 | C38: 0 | D38: 16.914 | E38: 714.69651 | F38: 4.7230013 | G38: =D38*3600 -> 60890.4 | H38: =D38*E38*3600/1000000 -> 43.518157 | I38: =IF(A38<=$R$8,"asc","desc") -> desc | J38: =w1_DBT5*B38+(1-w1_DBT5)*C38 -> 0 | K38: =SUM(J$2:J38) -> 73.682735 | L38: =IF(K38<=$R$4*$R$5,0,(K38-$R$4*$R$5)^2/(K38+(1-$R$4)*$R$5)) -> 11.714034 | M38: =L38-L37 -> 0 | N38: =M38/10 -> 0 | O38: =(D38-F38)*3600 -> 43887.595
A39: 43652.042 | B39: 0 | C39: 0 | D39: 15.802 | E39: 667.96865 | F39: 4.8263446 | G39: =D39*3600 -> 56887.2 | H39: =D39*E39*3600/1000000 -> 37.998866 | I39: =IF(A39<=$R$8,"asc","desc") -> desc | J39: =w1_DBT5*B39+(1-w1_DBT5)*C39 -> 0 | K39: =SUM(J$2:J39) -> 73.682735 | L39: =IF(K39<=$R$4*$R$5,0,(K39-$R$4*$R$5)^2/(K39+(1-$R$4)*$R$5)) -> 11.714034 | M39: =L39-L38 -> 0 | N39: =M39/10 -> 0 | O39: =(D39-F39)*3600 -> 39512.36
A40: 43652.083 | B40: 0 | C40: 0 | D40: 14.484 | E40: 637.48811 | F40: 4.912924 | G40: =D40*3600 -> 52142.4 | H40: =D40*E40*3600/1000000 -> 33.24016 | I40: =IF(A40<=$R$8,"asc","desc") -> desc | J40: =w1_DBT5*B40+(1-w1_DBT5)*C40 -> 0 | K40: =SUM(J$2:J40) -> 73.682735 | L40: =IF(K40<=$R$4*$R$5,0,(K40-$R$4*$R$5)^2/(K40+(1-$R$4)*$R$5)) -> 11.714034 | M40: =L40-L39 -> 0 | N40: =M40/10 -> 0 | O40: =(D40-F40)*3600 -> 34455.874
...

Sheet HU
A1: Hidrograma unitario triangular do SCS (D = 1 h)
A3: A, area da bacia (km2) | B3: 138 | C3: area adotada nos scripts (138)
A4: L, comprimento do talvegue (km) | B4: 37.587 | C4: medido no MDE/drenagem
A5: Hm, altitude media (m) | B5: 147.1
A6: Tc Giandotti adotado (h) | B6: 10.652 | C6: valor usado no script (10,652). Formula: Tc=(4*raiz(A)+1,5*L)/(0,8*raiz(Hm)); com A, L e Hm arredondados acima da 10,6536 (celula D6) | D6: =(4*SQRT(B3)+1.5*B4)/(0.8*SQRT(B5)) -> 10.65363
A7: D, duracao unitaria (h) | B7: 1 | C7: passo horario dos dados
A8: Tp = D/2 + 0,6*Tc (h) | B8: =B7/2+0.6*B6 -> 6.8912 | C8: tempo de pico
A9: Tb = 2,67*Tp (h) | B9: =2.67*B8 -> 18.399504 | C9: tempo de base do triangulo SCS
A10: Fator de pico (2,08*0,5377) | B10: =2.08*0.5377 -> 1.118416 | C10: 2,08 e o padrao SCS; 0,5377 e o fator de reducao calibrado nos 17 eventos
A11: qp do HU (m3/s por cm) = fator*A/Tp | B11: =B10*B3/B8 -> 22.396884 | C11: ordenada de pico do HU para 1 cm de chuva efetiva
A12: Numero de ordenadas (h = 0..ceil(Tb)) | B12: =ROUNDUP(B9,0)+1 -> 20
A15: Ordenadas do HU
A16: h (horas) | B16: u(h) (m3/s por cm)
A17: 0 | B17: =IF(A17<=$B$8,$B$11*A17/$B$8,MAX($B$11*($B$9-A17)/($B$9-$B$8),0)) -> 0
A18: 1 | B18: =IF(A18<=$B$8,$B$11*A18/$B$8,MAX($B$11*($B$9-A18)/($B$9-$B$8),0)) -> 3.2500703
A19: 2 | B19: =IF(A19<=$B$8,$B$11*A19/$B$8,MAX($B$11*($B$9-A19)/($B$9-$B$8),0)) -> 6.5001405
A20: 3 | B20: =IF(A20<=$B$8,$B$11*A20/$B$8,MAX($B$11*($B$9-A20)/($B$9-$B$8),0)) -> 9.7502108
A21: 4 | B21: =IF(A21<=$B$8,$B$11*A21/$B$8,MAX($B$11*($B$9-A21)/($B$9-$B$8),0)) -> 13.000281
A22: 5 | B22: =IF(A22<=$B$8,$B$11*A22/$B$8,MAX($B$11*($B$9-A22)/($B$9-$B$8),0)) -> 16.250351
A23: 6 | B23: =IF(A23<=$B$8,$B$11*A23/$B$8,MAX($B$11*($B$9-A23)/($B$9-$B$8),0)) -> 19.500422
A24: 7 | B24: =IF(A24<=$B$8,$B$11*A24/$B$8,MAX($B$11*($B$9-A24)/($B$9-$B$8),0)) -> 22.185143
A25: 8 | B25: =IF(A25<=$B$8,$B$11*A25/$B$8,MAX($B$11*($B$9-A25)/($B$9-$B$8),0)) -> 20.238993
A26: 9 | B26: =IF(A26<=$B$8,$B$11*A26/$B$8,MAX($B$11*($B$9-A26)/($B$9-$B$8),0)) -> 18.292843
A27: 10 | B27: =IF(A27<=$B$8,$B$11*A27/$B$8,MAX($B$11*($B$9-A27)/($B$9-$B$8),0)) -> 16.346693
A28: 11 | B28: =IF(A28<=$B$8,$B$11*A28/$B$8,MAX($B$11*($B$9-A28)/($B$9-$B$8),0)) -> 14.400544
... A36: 19 | B36: =IF(A36<=$B$8,$B$11*A36/$B$8,MAX($B$11*($B$9-A36)/($B$9-$B$8),0)) -> 0
A38: Soma das ordenadas (m3/s*h por cm) - mede quanto do volume unitario o triangulo carrega | B38: =SUM(B17:B36) -> 206.0273
A39: Volume unitario ideal da bacia (m3/s*h por cm) = A*10/3,6 | B39: =B3*10/3.6 -> 383.33333
A40: Fracao do volume unitario retida pelo HU (=~54%: o fator de pico e um fator de escala empirico) | B40: =B38/B39 -> 0.53746253

Sheet Convolucao
A1: Convolucao: hidrograma(k) = soma_j [ chuva efetiva incremental(j) em cm x u(k-j) ]
A2: Linha j = hora da chuva efetiva; coluna k = hora do hidrograma. Cada celula = incremento(j) x u(k-j) quando 0 <= k-j <= 19. A linha 'Q total' soma cada coluna.
A4: k -> | B4: ef (cm)
C5: 0 | D5: 1 | E5: 2 | F5: 3 | G5: 4 | H5: 5 | I5: 6 | J5: 7 | K5: 8 | L5: 9 | M5: 10 | N5: 11 | O5: 12 | P5: 13 | Q5: 14 | R5: 15 | S5: 16 | T5: 17 | U5: 18 | V5: 19 | W5: 20 | X5: 21 | Y5: 22 | Z5: 23 | AA5: 24 | AB5: 25 | AC5: 26 | AD5: 27 | AE5: 28 | AF5: 29 | AG5: 30 | AH5: 31 | AI5: 32 | AJ5: 33 | AK5: 34 | AL5: 35 | AM5: 36 | AN5: 37 | AO5: 38 | AP5: 39 | AQ5: 40 | AR5: 41 | AS5: 42 | AT5: 43 | AU5: 44 | AV5: 45 | AW5: 46 | AX5: 47 | AY5: 48 | AZ5: 49 | BA5: 50 | BB5: 51 | BC5: 52 | BD5: 53 | BE5: 54 | BF5: 55 | BG5: 56 | BH5: 57 | BI5: 58 | BJ5: 59 | BK5: 60 | BL5: 61 | BM5: 62 | BN5: 63 | BO5: 64 | BP5: 65 | BQ5: 66 | BR5: 67 | BS5: 68 | BT5: 69 | BU5: 70 | BV5: 71 | BW5: 72 | BX5: 73 | BY5: 74 | BZ5: 75 | CA5: 76 | CB5: 77 | CC5: 78 | CD5: 79 | CE5: 80 | CF5: 81 | CG5: 82 | CH5: 83 | CI5: 84 | CJ5: 85 | CK5: 86 | CL5: 87 | CM5: 88 | CN5: 89 | CO5: 90 | CP5: 91 | CQ5: 92 | CR5: 93 | CS5: 94 | CT5: 95 | CU5: 96 | CV5: 97 | CW5: 98 | CX5: 99 | CY5: 100 | CZ5: 101 | DA5: 102 | DB5: 103 | DC5: 104 | DD5: 105 | DE5: 106 | DF5: 107 | DG5: 108 | DH5: 109 | DI5: 110
A6: 0 | B6: =Serie_horaria!N2 -> 0 | C6: =IF(AND(C$5-$A6>=0,C$5-$A6<=19),INDEX(HU_ord,C$5-$A6+1)*$B6,0) -> 0 | D6: =IF(AND(D$5-$A6>=0,D$5-$A6<=19),INDEX(HU_ord,D$5-$A6+1)*$B6,0) -> 0 | E6: =IF(AND(E$5-$A6>=0,E$5-$A6<=19),INDEX(HU_ord,E$5-$A6+1)*$B6,0) -> 0 | F6: =IF(AND(F$5-$A6>=0,F$5-$A6<=19),INDEX(HU_ord,F$5-$A6+1)*$B6,0) -> 0 | G6: =IF(AND(G$5-$A6>=0,G$5-$A6<=19),INDEX(HU_ord,G$5-$A6+1)*$B6,0) -> 0 | H6: =IF(AND(H$5-$A6>=0,H$5-$A6<=19),INDEX(HU_ord,H$5-$A6+1)*$B6,0) -> 0 | I6: =IF(AND(I$5-$A6>=0,I$5-$A6<=19),INDEX(HU_ord,I$5-$A6+1)*$B6,0) -> 0 | J6: =IF(AND(J$5-$A6>=0,J$5-$A6<=19),INDEX(HU_ord,J$5-$A6+1)*$B6,0) -> 0 | ... DI6: =IF(AND(DI$5-$A6>=0,DI$5-$A6<=19),INDEX(HU_ord,DI$5-$A6+1)*$B6,0) -> 0
A7: 1 | B7: =Serie_horaria!N3 -> 0 | C7: =IF(AND(C$5-$A7>=0,C$5-$A7<=19),INDEX(HU_ord,C$5-$A7+1)*$B7,0) -> 0 | D7: =IF(AND(D$5-$A7>=0,D$5-$A7<=19),INDEX(HU_ord,D$5-$A7+1)*$B7,0) -> 0 | E7: =IF(AND(E$5-$A7>=0,E$5-$A7<=19),INDEX(HU_ord,E$5-$A7+1)*$B7,0) -> 0 | F7: =IF(AND(F$5-$A7>=0,F$5-$A7<=19),INDEX(HU_ord,F$5-$A7+1)*$B7,0) -> 0 | G7: =IF(AND(G$5-$A7>=0,G$5-$A7<=19),INDEX(HU_ord,G$5-$A7+1)*$B7,0) -> 0 | H7: =IF(AND(H$5-$A7>=0,H$5-$A7<=19),INDEX(HU_ord,H$5-$A7+1)*$B7,0) -> 0 | I7: =IF(AND(I$5-$A7>=0,I$5-$A7<=19),INDEX(HU_ord,I$5-$A7+1)*$B7,0) -> 0 | J7: =IF(AND(J$5-$A7>=0,J$5-$A7<=19),INDEX(HU_ord,J$5-$A7+1)*$B7,0) -> 0 | ... DI7: =IF(AND(DI$5-$A7>=0,DI$5-$A7<=19),INDEX(HU_ord,DI$5-$A7+1)*$B7,0) -> 0
A8: 2 | B8: =Serie_horaria!N4 -> 0 | C8: =IF(AND(C$5-$A8>=0,C$5-$A8<=19),INDEX(HU_ord,C$5-$A8+1)*$B8,0) -> 0 | D8: =IF(AND(D$5-$A8>=0,D$5-$A8<=19),INDEX(HU_ord,D$5-$A8+1)*$B8,0) -> 0 | E8: =IF(AND(E$5-$A8>=0,E$5-$A8<=19),INDEX(HU_ord,E$5-$A8+1)*$B8,0) -> 0 | F8: =IF(AND(F$5-$A8>=0,F$5-$A8<=19),INDEX(HU_ord,F$5-$A8+1)*$B8,0) -> 0 | G8: =IF(AND(G$5-$A8>=0,G$5-$A8<=19),INDEX(HU_ord,G$5-$A8+1)*$B8,0) -> 0 | H8: =IF(AND(H$5-$A8>=0,H$5-$A8<=19),INDEX(HU_ord,H$5-$A8+1)*$B8,0) -> 0 | I8: =IF(AND(I$5-$A8>=0,I$5-$A8<=19),INDEX(HU_ord,I$5-$A8+1)*$B8,0) -> 0 | J8: =IF(AND(J$5-$A8>=0,J$5-$A8<=19),INDEX(HU_ord,J$5-$A8+1)*$B8,0) -> 0 | ... DI8: =IF(AND(DI$5-$A8>=0,DI$5-$A8<=19),INDEX(HU_ord,DI$5-$A8+1)*$B8,0) -> 0
A9: 3 | B9: =Serie_horaria!N5 -> 0 | C9: =IF(AND(C$5-$A9>=0,C$5-$A9<=19),INDEX(HU_ord,C$5-$A9+1)*$B9,0) -> 0 | D9: =IF(AND(D$5-$A9>=0,D$5-$A9<=19),INDEX(HU_ord,D$5-$A9+1)*$B9,0) -> 0 | E9: =IF(AND(E$5-$A9>=0,E$5-$A9<=19),INDEX(HU_ord,E$5-$A9+1)*$B9,0) -> 0 | F9: =IF(AND(F$5-$A9>=0,F$5-$A9<=19),INDEX(HU_ord,F$5-$A9+1)*$B9,0) -> 0 | G9: =IF(AND(G$5-$A9>=0,G$5-$A9<=19),INDEX(HU_ord,G$5-$A9+1)*$B9,0) -> 0 | H9: =IF(AND(H$5-$A9>=0,H$5-$A9<=19),INDEX(HU_ord,H$5-$A9+1)*$B9,0) -> 0 | I9: =IF(AND(I$5-$A9>=0,I$5-$A9<=19),INDEX(HU_ord,I$5-$A9+1)*$B9,0) -> 0 | J9: =IF(AND(J$5-$A9>=0,J$5-$A9<=19),INDEX(HU_ord,J$5-$A9+1)*$B9,0) -> 0 | ... DI9: =IF(AND(DI$5-$A9>=0,DI$5-$A9<=19),INDEX(HU_ord,DI$5-$A9+1)*$B9,0) -> 0
A10: 4 | B10: =Serie_horaria!N6 -> 0.019811924 | C10: =IF(AND(C$5-$A10>=0,C$5-$A10<=19),INDEX(HU_ord,C$5-$A10+1)*$B10,0) -> 0 | D10: =IF(AND(D$5-$A10>=0,D$5-$A10<=19),INDEX(HU_ord,D$5-$A10+1)*$B10,0) -> 0 | E10: =IF(AND(E$5-$A10>=0,E$5-$A10<=19),INDEX(HU_ord,E$5-$A10+1)*$B10,0) -> 0 | F10: =IF(AND(F$5-$A10>=0,F$5-$A10<=19),INDEX(HU_ord,F$5-$A10+1)*$B10,0) -> 0 | G10: =IF(AND(G$5-$A10>=0,G$5-$A10<=19),INDEX(HU_ord,G$5-$A10+1)*$B10,0) -> 0 | H10: =IF(AND(H$5-$A10>=0,H$5-$A10<=19),INDEX(HU_ord,H$5-$A10+1)*$B10,0) -> 0.064390144 | I10: =IF(AND(I$5-$A10>=0,I$5-$A10<=19),INDEX(HU_ord,I$5-$A10+1)*$B10,0) -> 0.12878029 | J10: =IF(AND(J$5-$A10>=0,J$5-$A10<=19),INDEX(HU_ord,J$5-$A10+1)*$B10,0) -> 0.19317043 | ... DI10: =IF(AND(DI$5-$A10>=0,DI$5-$A10<=19),INDEX(HU_ord,DI$5-$A10+1)*$B10,0) -> 0
A11: 5 | B11: =Serie_horaria!N7 -> 0.010904426 | C11: =IF(AND(C$5-$A11>=0,C$5-$A11<=19),INDEX(HU_ord,C$5-$A11+1)*$B11,0) -> 0 | D11: =IF(AND(D$5-$A11>=0,D$5-$A11<=19),INDEX(HU_ord,D$5-$A11+1)*$B11,0) -> 0 | E11: =IF(AND(E$5-$A11>=0,E$5-$A11<=19),INDEX(HU_ord,E$5-$A11+1)*$B11,0) -> 0 | F11: =IF(AND(F$5-$A11>=0,F$5-$A11<=19),INDEX(HU_ord,F$5-$A11+1)*$B11,0) -> 0 | G11: =IF(AND(G$5-$A11>=0,G$5-$A11<=19),INDEX(HU_ord,G$5-$A11+1)*$B11,0) -> 0 | H11: =IF(AND(H$5-$A11>=0,H$5-$A11<=19),INDEX(HU_ord,H$5-$A11+1)*$B11,0) -> 0 | I11: =IF(AND(I$5-$A11>=0,I$5-$A11<=19),INDEX(HU_ord,I$5-$A11+1)*$B11,0) -> 0.03544015 | J11: =IF(AND(J$5-$A11>=0,J$5-$A11<=19),INDEX(HU_ord,J$5-$A11+1)*$B11,0) -> 0.070880301 | ... DI11: =IF(AND(DI$5-$A11>=0,DI$5-$A11<=19),INDEX(HU_ord,DI$5-$A11+1)*$B11,0) -> 0
A12: 6 | B12: =Serie_horaria!N8 -> 0.061803091 | C12: =IF(AND(C$5-$A12>=0,C$5-$A12<=19),INDEX(HU_ord,C$5-$A12+1)*$B12,0) -> 0 | D12: =IF(AND(D$5-$A12>=0,D$5-$A12<=19),INDEX(HU_ord,D$5-$A12+1)*$B12,0) -> 0 | E12: =IF(AND(E$5-$A12>=0,E$5-$A12<=19),INDEX(HU_ord,E$5-$A12+1)*$B12,0) -> 0 | F12: =IF(AND(F$5-$A12>=0,F$5-$A12<=19),INDEX(HU_ord,F$5-$A12+1)*$B12,0) -> 0 | G12: =IF(AND(G$5-$A12>=0,G$5-$A12<=19),INDEX(HU_ord,G$5-$A12+1)*$B12,0) -> 0 | H12: =IF(AND(H$5-$A12>=0,H$5-$A12<=19),INDEX(HU_ord,H$5-$A12+1)*$B12,0) -> 0 | I12: =IF(AND(I$5-$A12>=0,I$5-$A12<=19),INDEX(HU_ord,I$5-$A12+1)*$B12,0) -> 0 | J12: =IF(AND(J$5-$A12>=0,J$5-$A12<=19),INDEX(HU_ord,J$5-$A12+1)*$B12,0) -> 0.20086439 | ... DI12: =IF(AND(DI$5-$A12>=0,DI$5-$A12<=19),INDEX(HU_ord,DI$5-$A12+1)*$B12,0) -> 0
A13: 7 | B13: =Serie_horaria!N9 -> 0.05564709 | C13: =IF(AND(C$5-$A13>=0,C$5-$A13<=19),INDEX(HU_ord,C$5-$A13+1)*$B13,0) -> 0 | D13: =IF(AND(D$5-$A13>=0,D$5-$A13<=19),INDEX(HU_ord,D$5-$A13+1)*$B13,0) -> 0 | E13: =IF(AND(E$5-$A13>=0,E$5-$A13<=19),INDEX(HU_ord,E$5-$A13+1)*$B13,0) -> 0 | F13: =IF(AND(F$5-$A13>=0,F$5-$A13<=19),INDEX(HU_ord,F$5-$A13+1)*$B13,0) -> 0 | G13: =IF(AND(G$5-$A13>=0,G$5-$A13<=19),INDEX(HU_ord,G$5-$A13+1)*$B13,0) -> 0 | H13: =IF(AND(H$5-$A13>=0,H$5-$A13<=19),INDEX(HU_ord,H$5-$A13+1)*$B13,0) -> 0 | I13: =IF(AND(I$5-$A13>=0,I$5-$A13<=19),INDEX(HU_ord,I$5-$A13+1)*$B13,0) -> 0 | J13: =IF(AND(J$5-$A13>=0,J$5-$A13<=19),INDEX(HU_ord,J$5-$A13+1)*$B13,0) -> 0 | ... DI13: =IF(AND(DI$5-$A13>=0,DI$5-$A13<=19),INDEX(HU_ord,DI$5-$A13+1)*$B13,0) -> 0
A14: 8 | B14: =Serie_horaria!N10 -> 0.13290205 | C14: =IF(AND(C$5-$A14>=0,C$5-$A14<=19),INDEX(HU_ord,C$5-$A14+1)*$B14,0) -> 0 | D14: =IF(AND(D$5-$A14>=0,D$5-$A14<=19),INDEX(HU_ord,D$5-$A14+1)*$B14,0) -> 0 | E14: =IF(AND(E$5-$A14>=0,E$5-$A14<=19),INDEX(HU_ord,E$5-$A14+1)*$B14,0) -> 0 | F14: =IF(AND(F$5-$A14>=0,F$5-$A14<=19),INDEX(HU_ord,F$5-$A14+1)*$B14,0) -> 0 | G14: =IF(AND(G$5-$A14>=0,G$5-$A14<=19),INDEX(HU_ord,G$5-$A14+1)*$B14,0) -> 0 | H14: =IF(AND(H$5-$A14>=0,H$5-$A14<=19),INDEX(HU_ord,H$5-$A14+1)*$B14,0) -> 0 | I14: =IF(AND(I$5-$A14>=0,I$5-$A14<=19),INDEX(HU_ord,I$5-$A14+1)*$B14,0) -> 0 | J14: =IF(AND(J$5-$A14>=0,J$5-$A14<=19),INDEX(HU_ord,J$5-$A14+1)*$B14,0) -> 0 | ... DI14: =IF(AND(DI$5-$A14>=0,DI$5-$A14<=19),INDEX(HU_ord,DI$5-$A14+1)*$B14,0) -> 0
A15: 9 | B15: =Serie_horaria!N11 -> 0.054203001 | C15: =IF(AND(C$5-$A15>=0,C$5-$A15<=19),INDEX(HU_ord,C$5-$A15+1)*$B15,0) -> 0 | D15: =IF(AND(D$5-$A15>=0,D$5-$A15<=19),INDEX(HU_ord,D$5-$A15+1)*$B15,0) -> 0 | E15: =IF(AND(E$5-$A15>=0,E$5-$A15<=19),INDEX(HU_ord,E$5-$A15+1)*$B15,0) -> 0 | F15: =IF(AND(F$5-$A15>=0,F$5-$A15<=19),INDEX(HU_ord,F$5-$A15+1)*$B15,0) -> 0 | G15: =IF(AND(G$5-$A15>=0,G$5-$A15<=19),INDEX(HU_ord,G$5-$A15+1)*$B15,0) -> 0 | H15: =IF(AND(H$5-$A15>=0,H$5-$A15<=19),INDEX(HU_ord,H$5-$A15+1)*$B15,0) -> 0 | I15: =IF(AND(I$5-$A15>=0,I$5-$A15<=19),INDEX(HU_ord,I$5-$A15+1)*$B15,0) -> 0 | J15: =IF(AND(J$5-$A15>=0,J$5-$A15<=19),INDEX(HU_ord,J$5-$A15+1)*$B15,0) -> 0 | ... DI15: =IF(AND(DI$5-$A15>=0,DI$5-$A15<=19),INDEX(HU_ord,DI$5-$A15+1)*$B15,0) -> 0
A16: 10 | B16: =Serie_horaria!N12 -> 0.14319224 | C16: =IF(AND(C$5-$A16>=0,C$5-$A16<=19),INDEX(HU_ord,C$5-$A16+1)*$B16,0) -> 0 | D16: =IF(AND(D$5-$A16>=0,D$5-$A16<=19),INDEX(HU_ord,D$5-$A16+1)*$B16,0) -> 0 | E16: =IF(AND(E$5-$A16>=0,E$5-$A16<=19),INDEX(HU_ord,E$5-$A16+1)*$B16,0) -> 0 | F16: =IF(AND(F$5-$A16>=0,F$5-$A16<=19),INDEX(HU_ord,F$5-$A16+1)*$B16,0) -> 0 | G16: =IF(AND(G$5-$A16>=0,G$5-$A16<=19),INDEX(HU_ord,G$5-$A16+1)*$B16,0) -> 0 | H16: =IF(AND(H$5-$A16>=0,H$5-$A16<=19),INDEX(HU_ord,H$5-$A16+1)*$B16,0) -> 0 | I16: =IF(AND(I$5-$A16>=0,I$5-$A16<=19),INDEX(HU_ord,I$5-$A16+1)*$B16,0) -> 0 | J16: =IF(AND(J$5-$A16>=0,J$5-$A16<=19),INDEX(HU_ord,J$5-$A16+1)*$B16,0) -> 0 | ... DI16: =IF(AND(DI$5-$A16>=0,DI$5-$A16<=19),INDEX(HU_ord,DI$5-$A16+1)*$B16,0) -> 0
A17: 11 | B17: =Serie_horaria!N13 -> 0.040429899 | C17: =IF(AND(C$5-$A17>=0,C$5-$A17<=19),INDEX(HU_ord,C$5-$A17+1)*$B17,0) -> 0 | D17: =IF(AND(D$5-$A17>=0,D$5-$A17<=19),INDEX(HU_ord,D$5-$A17+1)*$B17,0) -> 0 | E17: =IF(AND(E$5-$A17>=0,E$5-$A17<=19),INDEX(HU_ord,E$5-$A17+1)*$B17,0) -> 0 | F17: =IF(AND(F$5-$A17>=0,F$5-$A17<=19),INDEX(HU_ord,F$5-$A17+1)*$B17,0) -> 0 | G17: =IF(AND(G$5-$A17>=0,G$5-$A17<=19),INDEX(HU_ord,G$5-$A17+1)*$B17,0) -> 0 | H17: =IF(AND(H$5-$A17>=0,H$5-$A17<=19),INDEX(HU_ord,H$5-$A17+1)*$B17,0) -> 0 | I17: =IF(AND(I$5-$A17>=0,I$5-$A17<=19),INDEX(HU_ord,I$5-$A17+1)*$B17,0) -> 0 | J17: =IF(AND(J$5-$A17>=0,J$5-$A17<=19),INDEX(HU_ord,J$5-$A17+1)*$B17,0) -> 0 | ... DI17: =IF(AND(DI$5-$A17>=0,DI$5-$A17<=19),INDEX(HU_ord,DI$5-$A17+1)*$B17,0) -> 0
... A97: 91 | B97: =Serie_horaria!N93 -> 0 | C97: =IF(AND(C$5-$A97>=0,C$5-$A97<=19),INDEX(HU_ord,C$5-$A97+1)*$B97,0) -> 0 | D97: =IF(AND(D$5-$A97>=0,D$5-$A97<=19),INDEX(HU_ord,D$5-$A97+1)*$B97,0) -> 0 | E97: =IF(AND(E$5-$A97>=0,E$5-$A97<=19),INDEX(HU_ord,E$5-$A97+1)*$B97,0) -> 0 | F97: =IF(AND(F$5-$A97>=0,F$5-$A97<=19),INDEX(HU_ord,F$5-$A97+1)*$B97,0) -> 0 | G97: =IF(AND(G$5-$A97>=0,G$5-$A97<=19),INDEX(HU_ord,G$5-$A97+1)*$B97,0) -> 0 | H97: =IF(AND(H$5-$A97>=0,H$5-$A97<=19),INDEX(HU_ord,H$5-$A97+1)*$B97,0) -> 0 | I97: =IF(AND(I$5-$A97>=0,I$5-$A97<=19),INDEX(HU_ord,I$5-$A97+1)*$B97,0) -> 0 | J97: =IF(AND(J$5-$A97>=0,J$5-$A97<=19),INDEX(HU_ord,J$5-$A97+1)*$B97,0) -> 0 | ... DI97: =IF(AND(DI$5-$A97>=0,DI$5-$A97<=19),INDEX(HU_ord,DI$5-$A97+1)*$B97,0) -> 0
A98: Q total | C98: =SUM(C6:C97) -> 0 | D98: =SUM(D6:D97) -> 0 | E98: =SUM(E6:E97) -> 0 | F98: =SUM(F6:F97) -> 0 | G98: =SUM(G6:G97) -> 0 | H98: =SUM(H6:H97) -> 0.064390144 | I98: =SUM(I6:I97) -> 0.16422044 | J98: =SUM(J6:J97) -> 0.46491512 | ... DI98: =SUM(DI6:DI97) -> 0
A100: Qp calculado (m3/s) = MAX(Q total) | F100: =MAX(C98:DI98) -> 16.505064

Sheet Checagem
A1: Valores da planilha do projeto x recalculados nesta planilha
A3: Grandeza | B3: Planilha do projeto | C3: Recalculado aqui | D3: Diferenca | E3: Dif. %
A4: Chuva DBT5 (mm) | B4: 62.800003 | C4: =Serie_horaria!R10 -> 62.800003 | D4: =C4-B4 -> 7.1054274e-15 | E4: =IF(B4=0,0,D4/B4*100) -> 1.1314374e-14
A5: Chuva Campo Limpo (mm) | B5: 79.000002 | C5: =Serie_horaria!R11 -> 79.000002 | D5: =C5-B5 -> 0 | E5: =IF(B5=0,0,D5/B5*100) -> 0
A6: Chuva de bacia R (mm) | B6: 74.039628 | C6: =Serie_horaria!R12 -> 74.021269 | D6: =C6-B6 -> -0.018358614 | E6: =IF(B6=0,0,D6/B6*100) -> -0.024795659
A7: T_R_m3 (m3) | B7: 2436681.6 | C7: =Serie_horaria!R13 -> 2436681.6 | D7: =C7-B7 -> -4.6566129e-10 | E7: =IF(B7=0,0,D7/B7*100) -> -1.9110469e-14
A8: Ris_R_m3 (m3) | B8: 1283688 | C8: =Serie_horaria!R14 -> 1283688 | D8: =C8-B8 -> 0 | E8: =IF(B8=0,0,D8/B8*100) -> 0
A9: Fall_R_m3 (m3) | B9: 1152993.6 | C9: =Serie_horaria!R15 -> 1152993.6 | D9: =C9-B9 -> 0 | E9: =IF(B9=0,0,D9/B9*100) -> 0
A10: SYY_t (t) | B10: 1821.7535 | C10: =Serie_horaria!R16 -> 1821.7535 | D10: =C10-B10 -> -2.2737368e-13 | E10: =IF(B10=0,0,D10/B10*100) -> -1.2481034e-14
A11: SSY_Ris_t (t) | B11: 1239.8365 | C11: =Serie_horaria!R17 -> 1239.8365 | D11: =C11-B11 -> -2.2737368e-13 | E11: =IF(B11=0,0,D11/B11*100) -> -1.8339005e-14
A12: SSY_Fall_t (t) | B12: 581.91704 | C12: =Serie_horaria!R18 -> 581.91704 | D12: =C12-B12 -> 0 | E12: =IF(B12=0,0,D12/B12*100) -> 0
A13: Q_pico medido (m3/s) | B13: 20.95 | C13: =Serie_horaria!R7 -> 20.95 | D13: =C13-B13 -> 0 | E13: =IF(B13=0,0,D13/B13*100) -> 0
A14: Qp calculado (convolucao HU) x Qp do CSV do projeto (m3/s) | B14: 16.505064 | C14: =Qp_calc -> 16.505064 | D14: =C14-B14 -> 0 | E14: =IF(B14=0,0,D14/B14*100) -> 0
A16: Qp calculado x medido: erro % | B16: =(Qp_calc-20.95)/20.95*100 -> -21.21688
