Workbook
Name A_pixel: Parametros!$B$7
Name c_pura: Parametros!$B$24
Name c_restr: Parametros!$B$25
Name Classes_C: Classes!$A$14:$B$22
Name Classes_K: Classes!$A$5:$B$9
Name coef_W: Parametros!$B$20
Name dx_pix: Parametros!$B$5
Name dy_pix: Parametros!$B$6
Name exp_M: Parametros!$B$21
Name fator_f: Parametros!$B$23
Name fator_P: Parametros!$B$22
Name P_CLP: Parametros!$B$15
Name P_DBT5: Parametros!$B$14
Name p_lambda: Parametros!$B$4
Name R_evento_mm: Parametros!$B$17
Name RI_mmh: Parametros!$B$16
Name SY_obs_t: Parametros!$B$19
Name V_med_m3: Parametros!$B$18
Name X0_canto: Parametros!$B$8
Name x_CLP: Parametros!$B$12
Name x_DBT5: Parametros!$B$10
Name Y0_canto: Parametros!$B$9
Name y_CLP: Parametros!$B$13
Name y_DBT5: Parametros!$B$11

Sheet Roteiro
A1: EVENTO 11 - Planilha 02: modelo pixel a pixel (154.667 pixels)
A3: Como ler: a aba Pixels tem uma linha por pixel; todas as colunas em formula usam as constantes da aba Parametros. Clique em qualquer celula para ver a conta. As abas Resumo, Calibracao_c e Conferencia fecham o modelo.
A5: Col. | B5: Variavel | C5: Formula (em palavras / Excel) | D5: Origem do dado ou funcao no modelo
A6: A | B6: id | C6: contador 1..N | D6: chave p/ achar o pixel no QGIS (camada Pixels_Evento11.shp, campo id)
A7: B,C | B7: lin, col | C7: indices da linha e coluna do pixel na grade 884x365 | D7: posicao no raster
A8: D | B8: X (m) | C8: =X0_canto + (col+0,5)*dx_pix -> 0 | D8: centro do pixel (UTM 23S)
A9: E | B9: Y (m) | C9: =Y0_canto - (lin+0,5)*dy_pix -> 0 | D9: idem
A10: F,G | B10: d2 aos postos (m2) | C10: =(X-x_posto)^2 + (Y-y_posto)^2 -> 0 | D10: distancia ao quadrado ate DBT5 e Campo Limpo
A11: H | B11: P (mm) | C11: =(P_DBT5/d2_DBT5 + P_CLP/d2_CLP) / (1/d2_DBT5 + 1/d2_CLP) -> 0 | D11: IDW potencia 2 com 2 postos. Reproduz o raster do QGIS (Interpolacao IDW, coef. 2) com dif < 1e-5 mm
A12: I | B12: CN (AMC II) | C12: valor do raster CN TCC.tif amostrado no centro do pixel | D12: QGIS/GDAL: Warp (vizinho mais proximo) do raster 973x362 para a grade 884x365. CN-II = mapa uso x grupo hidrologico (origem a confirmar)
A13: J | B13: CN (AMC I, seco) | C13: =4,2*CN_II/(10-0,058*CN_II) -> 0 | D13: conversao CN-II -> CN-I (Hawkins; Chow et al. 1988). Reproduz CN TCC - Seco.tif com dif < 4e-6
A14: K | B14: S (mm) | C14: =25,4*(1000/CN_I - 10) -> 0 | D14: retencao potencial maxima (SCS). Reproduz S - Seco.tif com dif < 2e-5 mm
A15: L | B15: Classe de solo | C15: ponto-em-poligono em Pedologia Alto.shp (campo Subordem) | D15: QGIS: 'Unir atributos por localizacao' (ponto no centro do pixel)
A16: M | B16: K | C16: =PROCV(classe de solo; tabela Classes_K) -> 0 | D16: reproduz K_raster.tif em 100% dos pixels
A17: N | B17: Classe de uso | C17: ponto-em-poligono em Uso Solo Alto.shp (campo CLASSE) | D17: idem
A18: O | B18: C | C18: =PROCV(classe de uso; tabela Classes_C) -> 0 | D18: reproduz C_raster.tif em 100% dos pixels
A19: P | B19: LS | C19: valor do raster LS_raster.tif | D19: Moore et al. (1991), SAGA, MDE
A20: Q | B20: Valido | C20: =SE(M, O e P existem; 1; 0) -> 0 | D20: 1 = pixel entra no calculo de E_unit
A21: R | B21: Q (mm) | C21: =SE(P<=lambda*S; 0; (P-lambda*S)^2/(P+(1-lambda)*S)) -> 0 | D21: escoamento SCS-CN do pixel (previsao pura)
A22: S | B22: pr (m3/s) | C22: =Q/1000*A_pixel*RI/R/3600 -> 0 | D22: vazao de pico local (Hao et al. 2022, Eq. 3)
A23: T | B23: E_unit (t) | C23: =SE(Valido; 11,8*MAX(Q*pr*A_pixel;0)^0,56*K*C*P*LS; "") -> 0 | D23: MUSLE por pixel (Hao et al. 2022, Eq. 1). Sai em toneladas/pixel (nao calibrado)
A24: U | B24: SY (t) | C24: =c_pura*E_unit -> 0 | D24: producao de sedimentos do pixel (previsao pura)
A25: V | B25: Q volume restrito (mm) | C25: =SE(Valido; MIN(fator_f*Q; P); "") -> 0 | D25: Q reescalado para o volume medido, limitado a chuva do pixel
A26: W | B26: pr restrito (m3/s) | C26: =Q_restr/1000*A_pixel*RI/R/3600 -> 0
A27: X | B27: E_unit restrito (t) | C27: =11,8*MAX(Q_restr*pr_restr*A_pixel;0)^0,56*K*C*P*LS -> 0
A28: Y | B28: SY restrito (t) | C28: =c_restr*E_unit_restr -> 0 | D28: producao de sedimentos do pixel (volume restrito)

Sheet Parametros
A1: Parametros do evento 11 (celula amarela = entrada; verde = resultado de outra aba)
A3: Nome (usado nas formulas) | B3: Valor | C3: Unidade | D3: Origem / significado
A4: p_lambda | B4: 0.05 | C4: - | D4: Ia = lambda*S (razao de abstracao inicial). 0,05 em vez do classico 0,2 (calibracao do projeto; Valle Junior et al. 2019; Brandao 2025).
A5: dx_pix | B5: 29.991575 | C5: m | D5: tamanho do pixel em X (grade 884 x 365 do raster CN, SIRGAS 2000 / UTM 23S)
A6: dy_pix | B6: 29.924731 | C6: m | D6: tamanho do pixel em Y
A7: A_pixel | B7: =B5*B6 -> 897.48982 | C7: m2 | D7: area do pixel = dx*dy (897,49 m2; NAO 900)
A8: X0_canto | B8: 318646.35 | C8: m | D8: coordenada X do canto superior esquerdo da grade
A9: Y0_canto | B9: 7435057.6 | C9: m | D9: coordenada Y do canto superior esquerdo da grade
A10: x_DBT5 | B10: 348520.85 | C10: m | D10: posto Desemboque do Tunel 5 (lon -46,4809 / lat -23,2646) reprojetado para UTM 23S (QGIS: Reprojetar camada, EPSG:4326 -> 31983)
A11: y_DBT5 | B11: 7426415.3 | C11: m | D11: idem
A12: x_CLP | B12: 319862.37 | C12: m | D12: posto Rio Jundiai em Campo Limpo Paulista (lon -46,760284 / lat -23,208778) reprojetado
A13: y_CLP | B13: 7432277.5 | C13: m | D13: idem
A14: P_DBT5 | B14: 62.800003 | C14: mm | D14: chuva total do evento no posto DBT5 (planilha de eventos: chuva_p1_mm)
A15: P_CLP | B15: 79.000002 | C15: mm | D15: chuva total do evento no posto Campo Limpo (chuva_p2_mm)
A16: RI_mmh | B16: 11.8 | C16: mm/h | D16: intensidade maxima de 60 min do evento = MAIOR entre os 2 postos (11,8 no DBT5; 9,4 no CLP)
A17: R_evento_mm | B17: 74.039628 | C17: mm | D17: lamina de chuva do evento = 0,3068*62,8 + 0,6932*79,0 (aba Pesos_postos da planilha 01)
A18: V_med_m3 | B18: 2436681.6 | C18: m3 | D18: volume medido T_R_m3 (planilha de eventos) = soma das 92 vazoes horarias x 3600 (inclui vazao de base)
A19: SY_obs_t | B19: 1821.7535 | C19: t | D19: SY observado do evento (SYY_t) = soma(Q*CSS*3600/1e6)
... A22: fator_P | B22: 1 | C22: - | D22: pratica conservacionista: P = 1 (sem praticas) na bacia toda
A23: fator_f | B23: =Resumo!B13 -> 1.2249226 | C23: - | D23: f = V_med / V_calc (aba Resumo). Reescala Q para o volume medido (variante 'volume restrito')
A24: c_pura | B24: =Calibracao_c!B22 -> 0.10670576 | C24: - | D24: c da previsao pura (aba Calibracao_c): SY = c * E_unit
A25: c_restr | B25: =Calibracao_c!L22 -> 0.13836172 | C25: - | D25: c do volume restrito (aba Calibracao_c)

Sheet Classes
A1: Tabelas de classe -> fator (K e C) e origem do LS
A3: K - erodibilidade (t.h/MJ/mm). Origem: Pedologia Alto.shp, campo Valor (Plano de Bacias, Consorcio Profill-Rhama 2020; valores por classe da IC)
A4: Classe de solo (campo Subordem) | B4: K | C4: Pixels (COUNTIF) | D4: Observacao
A5: Afloramento Rochoso | B5: 0.0087 | C5: =COUNTIF(Pixels!$L$2:$L$301,A5) -> 0
A6: Argissolos Vermelho-Amarelos | B6: 0.0351 | C6: =COUNTIF(Pixels!$L$2:$L$301,A6) -> 0
A7: Cambissolos Háplicos | B7: 0.0475 | C7: =COUNTIF(Pixels!$L$2:$L$301,A7) -> 174
A8: Neossolos Litólicos | B8: 0.0463 | C8: =COUNTIF(Pixels!$L$2:$L$301,A8) -> 0
A9: Área Urbana | B9: 0 | C9: =COUNTIF(Pixels!$L$2:$L$301,A9) -> 101 | D9: K = 0: area urbana nao produz erosao no modelo (e tambem zera qualquer pixel sobreposto)
A12: C - uso e manejo (-). Origem: Uso Solo Alto.shp, campo Valor (Plano de Bacias 2020; valores da IC)
A13: Classe de uso (campo CLASSE) | B13: C | C13: Pixels (COUNTIF) | D13: Observacao
A14: Afloramento Rochoso | B14: 1 | C14: =COUNTIF(Pixels!$N$2:$N$301,A14) -> 0
A15: Campo | B15: 0.05 | C15: =COUNTIF(Pixels!$N$2:$N$301,A15) -> 75
A16: Corpos D'Água | B16: 0 | C16: =COUNTIF(Pixels!$N$2:$N$301,A16) -> 0 | D16: C = 0: sem erosao (urbano / agua)
A17: Lavoura Temporária | B17: 0.2116 | C17: =COUNTIF(Pixels!$N$2:$N$301,A17) -> 0
A18: Mata Nativa | B18: 0.015 | C18: =COUNTIF(Pixels!$N$2:$N$301,A18) -> 96
A19: Mineração | B19: 1 | C19: =COUNTIF(Pixels!$N$2:$N$301,A19) -> 0
A20: Silvicultura | B20: 0.121 | C20: =COUNTIF(Pixels!$N$2:$N$301,A20) -> 3
A21: Solo exposto | B21: 1 | C21: =COUNTIF(Pixels!$N$2:$N$301,A21) -> 0
A22: Área Urbanizada | B22: 0 | C22: =COUNTIF(Pixels!$N$2:$N$301,A22) -> 101 | D22: C = 0: sem erosao (urbano / agua)
A24: LS - fator topografico
A25: Nao e recalculado nesta planilha: vem de LS_raster.tif (metodo de Moore et al. 1991 no SAGA a partir do MDE, segundo a IC). A coluna LS da aba Pixels e o valor do raster amostrado no centro do pixel.
A26: Pixels sem classe de solo/uso/LS (656): coluna 'Valido'=0 -> sem E_unit (so entram no volume 'todos os pixels').

Sheet Pixels
A1: id | B1: lin | C1: col | D1: X (m) | E1: Y (m) | F1: d2 ao DBT5 (m2) | G1: d2 ao Campo Limpo (m2) | H1: P (mm) | I1: CN AMC II | J1: CN AMC I | K1: S (mm) | L1: Classe de solo | M1: K | N1: Classe de uso | O1: C | P1: LS | Q1: Valido | R1: Q (mm) | S1: pr (m3/s) | T1: E_unit (t) | U1: SY previsao pura (t) | V1: Q restrito (mm) | W1: pr restrito (m3/s) | X1: E_unit restrito (t) | Y1: SY restrito (t)
A2: 1 | B2: 8 | C2: 140 | D2: =X0_canto+(C2+0.5)*dx_pix -> 322860.16 | E2: =Y0_canto-(B2+0.5)*dy_pix -> 7434803.2 | F2: =(D2-x_DBT5)^2+(E2-y_DBT5)^2 -> 7.2882864e+08 | G2: =(D2-x_CLP)^2+(E2-y_CLP)^2 -> 15365839 | H2: =(P_DBT5/F2+P_CLP/G2)/(1/F2+1/G2) -> 78.665511 | I2: 65 | J2: =4.2*I2/(10-0.058*I2) -> 43.820225 | K2: =25.4*(1000/J2-10) -> 325.64103 | L2: Cambissolos Háplicos | M2: =IFERROR(VLOOKUP(L2,Classes_K,2,FALSE),"") -> 0.047499999 | N2: Mata Nativa | O2: =IFERROR(VLOOKUP(N2,Classes_C,2,FALSE),"") -> 0.015 | P2: 0.35805494 | Q2: =IF(COUNT(M2,O2,P2)=3,1,0) -> 1 | R2: =IF(H2<=p_lambda*K2,0,(H2-p_lambda*K2)^2/(H2+(1-p_lambda)*K2)) -> 10.029511 | S2: =R2/1000*A_pixel*RI_mmh/R_evento_mm/3600 -> 0.00039849657 | T2: =IF(Q2=1,coef_W*MAX(R2*S2*A_pixel,0)^exp_M*M2*O2*fator_P*P2,"") -> 0.0061555591 | U2: =IF(Q2=1,c_pura*T2,"") -> 0.00065683359 | V2: =IF(Q2=1,MIN(fator_f*R2,H2),"") -> 12.285375 | W2: =IF(Q2=1,V2/1000*A_pixel*RI_mmh/R_evento_mm/3600,"") -> 0.00048812745 | X2: =IF(Q2=1,coef_W*MAX(V2*W2*A_pixel,0)^exp_M*M2*O2*fator_P*P2,"") -> 0.0077259018 | Y2: =IF(Q2=1,c_restr*X2,"") -> 0.0010689691
A3: 2 | B3: 8 | C3: 141 | D3: =X0_canto+(C3+0.5)*dx_pix -> 322890.15 | E3: =Y0_canto-(B3+0.5)*dy_pix -> 7434803.2 | F3: =(D3-x_DBT5)^2+(E3-y_DBT5)^2 -> 7.2729033e+08 | G3: =(D3-x_CLP)^2+(E3-y_CLP)^2 -> 15546556 | H3: =(P_DBT5/F3+P_CLP/G3)/(1/F3+1/G3) -> 78.660958 | I3: 65 | J3: =4.2*I3/(10-0.058*I3) -> 43.820225 | K3: =25.4*(1000/J3-10) -> 325.64103 | L3: Cambissolos Háplicos | M3: =IFERROR(VLOOKUP(L3,Classes_K,2,FALSE),"") -> 0.047499999 | N3: Mata Nativa | O3: =IFERROR(VLOOKUP(N3,Classes_C,2,FALSE),"") -> 0.015 | P3: 0.41597456 | Q3: =IF(COUNT(M3,O3,P3)=3,1,0) -> 1 | R3: =IF(H3<=p_lambda*K3,0,(H3-p_lambda*K3)^2/(H3+(1-p_lambda)*K3)) -> 10.028165 | S3: =R3/1000*A_pixel*RI_mmh/R_evento_mm/3600 -> 0.00039844309 | T3: =IF(Q3=1,coef_W*MAX(R3*S3*A_pixel,0)^exp_M*M3*O3*fator_P*P3,"") -> 0.0071502187 | U3: =IF(Q3=1,c_pura*T3,"") -> 0.00076296949 | V3: =IF(Q3=1,MIN(fator_f*R3,H3),"") -> 12.283726 | W3: =IF(Q3=1,V3/1000*A_pixel*RI_mmh/R_evento_mm/3600,"") -> 0.00048806193 | X3: =IF(Q3=1,coef_W*MAX(V3*W3*A_pixel,0)^exp_M*M3*O3*fator_P*P3,"") -> 0.0089743086 | Y3: =IF(Q3=1,c_restr*X3,"") -> 0.0012417008
A4: 3 | B4: 8 | C4: 142 | D4: =X0_canto+(C4+0.5)*dx_pix -> 322920.15 | E4: =Y0_canto-(B4+0.5)*dy_pix -> 7434803.2 | F4: =(D4-x_DBT5)^2+(E4-y_DBT5)^2 -> 7.2575382e+08 | G4: =(D4-x_CLP)^2+(E4-y_CLP)^2 -> 15729071 | H4: =(P_DBT5/F4+P_CLP/G4)/(1/F4+1/G4) -> 78.656352 | I4: 77 | J4: =4.2*I4/(10-0.058*I4) -> 58.438742 | K4: =25.4*(1000/J4-10) -> 180.64317 | M4: =IFERROR(VLOOKUP(L4,Classes_K,2,FALSE),"") | O4: =IFERROR(VLOOKUP(N4,Classes_C,2,FALSE),"") | Q4: =IF(COUNT(M4,O4,P4)=3,1,0) -> 0 | R4: =IF(H4<=p_lambda*K4,0,(H4-p_lambda*K4)^2/(H4+(1-p_lambda)*K4)) -> 19.369399 | S4: =R4/1000*A_pixel*RI_mmh/R_evento_mm/3600 -> 0.00076959272 | T4: =IF(Q4=1,coef_W*MAX(R4*S4*A_pixel,0)^exp_M*M4*O4*fator_P*P4,"") | U4: =IF(Q4=1,c_pura*T4,"") | V4: =IF(Q4=1,MIN(fator_f*R4,H4),"") | W4: =IF(Q4=1,V4/1000*A_pixel*RI_mmh/R_evento_mm/3600,"") | X4: =IF(Q4=1,coef_W*MAX(V4*W4*A_pixel,0)^exp_M*M4*O4*fator_P*P4,"") | Y4: =IF(Q4=1,c_restr*X4,"")
A5: 4 | B5: 9 | C5: 139 | D5: =X0_canto+(C5+0.5)*dx_pix -> 322830.17 | E5: =Y0_canto-(B5+0.5)*dy_pix -> 7434773.3 | F5: =(D5-x_DBT5)^2+(E5-y_DBT5)^2 -> 7.2986763e+08 | G5: =(D5-x_CLP)^2+(E5-y_CLP)^2 -> 15036656 | H5: =(P_DBT5/F5+P_CLP/G5)/(1/F5+1/G5) -> 78.672988 | I5: 77 | J5: =4.2*I5/(10-0.058*I5) -> 58.438742 | K5: =25.4*(1000/J5-10) -> 180.64317 | L5: Cambissolos Háplicos | M5: =IFERROR(VLOOKUP(L5,Classes_K,2,FALSE),"") -> 0.047499999 | N5: Mata Nativa | O5: =IFERROR(VLOOKUP(N5,Classes_C,2,FALSE),"") -> 0.015 | P5: 0.43113601 | Q5: =IF(COUNT(M5,O5,P5)=3,1,0) -> 1 | R5: =IF(H5<=p_lambda*K5,0,(H5-p_lambda*K5)^2/(H5+(1-p_lambda)*K5)) -> 19.377368 | S5: =R5/1000*A_pixel*RI_mmh/R_evento_mm/3600 -> 0.00076990937 | T5: =IF(Q5=1,coef_W*MAX(R5*S5*A_pixel,0)^exp_M*M5*O5*fator_P*P5,"") -> 0.015497761 | U5: =IF(Q5=1,c_pura*T5,"") -> 0.0016537003 | V5: =IF(Q5=1,MIN(fator_f*R5,H5),"") -> 23.735776 | W5: =IF(Q5=1,V5/1000*A_pixel*RI_mmh/R_evento_mm/3600,"") -> 0.00094307937 | X5: =IF(Q5=1,coef_W*MAX(V5*W5*A_pixel,0)^exp_M*M5*O5*fator_P*P5,"") -> 0.01945139 | Y5: =IF(Q5=1,c_restr*X5,"") -> 0.0026913278
A6: 5 | B6: 9 | C6: 140 | D6: =X0_canto+(C6+0.5)*dx_pix -> 322860.16 | E6: =Y0_canto-(B6+0.5)*dy_pix -> 7434773.3 | F6: =(D6-x_DBT5)^2+(E6-y_DBT5)^2 -> 7.2832752e+08 | G6: =(D6-x_CLP)^2+(E6-y_CLP)^2 -> 15215574 | H6: =(P_DBT5/F6+P_CLP/G6)/(1/F6+1/G6) -> 78.668492 | I6: 77 | J6: =4.2*I6/(10-0.058*I6) -> 58.438742 | K6: =25.4*(1000/J6-10) -> 180.64317 | L6: Cambissolos Háplicos | M6: =IFERROR(VLOOKUP(L6,Classes_K,2,FALSE),"") -> 0.047499999 | N6: Mata Nativa | O6: =IFERROR(VLOOKUP(N6,Classes_C,2,FALSE),"") -> 0.015 | P6: 0.34137058 | Q6: =IF(COUNT(M6,O6,P6)=3,1,0) -> 1 | R6: =IF(H6<=p_lambda*K6,0,(H6-p_lambda*K6)^2/(H6+(1-p_lambda)*K6)) -> 19.375214 | S6: =R6/1000*A_pixel*RI_mmh/R_evento_mm/3600 -> 0.00076982378 | T6: =IF(Q6=1,coef_W*MAX(R6*S6*A_pixel,0)^exp_M*M6*O6*fator_P*P6,"") -> 0.012269495 | U6: =IF(Q6=1,c_pura*T6,"") -> 0.0013092257 | V6: =IF(Q6=1,MIN(fator_f*R6,H6),"") -> 23.733137 | W6: =IF(Q6=1,V6/1000*A_pixel*RI_mmh/R_evento_mm/3600,"") -> 0.00094297453 | X6: =IF(Q6=1,coef_W*MAX(V6*W6*A_pixel,0)^exp_M*M6*O6*fator_P*P6,"") -> 0.015399562 | Y6: =IF(Q6=1,c_restr*X6,"") -> 0.0021307098
A7: 6 | B7: 9 | C7: 141 | D7: =X0_canto+(C7+0.5)*dx_pix -> 322890.15 | E7: =Y0_canto-(B7+0.5)*dy_pix -> 7434773.3 | F7: =(D7-x_DBT5)^2+(E7-y_DBT5)^2 -> 7.2678921e+08 | G7: =(D7-x_CLP)^2+(E7-y_CLP)^2 -> 15396290 | H7: =(P_DBT5/F7+P_CLP/G7)/(1/F7+1/G7) -> 78.663941 | I7: 77 | J7: =4.2*I7/(10-0.058*I7) -> 58.438742 | K7: =25.4*(1000/J7-10) -> 180.64317 | L7: Cambissolos Háplicos | M7: =IFERROR(VLOOKUP(L7,Classes_K,2,FALSE),"") -> 0.047499999 | N7: Mata Nativa | O7: =IFERROR(VLOOKUP(N7,Classes_C,2,FALSE),"") -> 0.015 | P7: 0.3539305 | Q7: =IF(COUNT(M7,O7,P7)=3,1,0) -> 1 | R7: =IF(H7<=p_lambda*K7,0,(H7-p_lambda*K7)^2/(H7+(1-p_lambda)*K7)) -> 19.373034 | S7: =R7/1000*A_pixel*RI_mmh/R_evento_mm/3600 -> 0.00076973716 | T7: =IF(Q7=1,coef_W*MAX(R7*S7*A_pixel,0)^exp_M*M7*O7*fator_P*P7,"") -> 0.012719319 | U7: =IF(Q7=1,c_pura*T7,"") -> 0.0013572245 | V7: =IF(Q7=1,MIN(fator_f*R7,H7),"") -> 23.730467 | W7: =IF(Q7=1,V7/1000*A_pixel*RI_mmh/R_evento_mm/3600,"") -> 0.00094286842 | X7: =IF(Q7=1,coef_W*MAX(V7*W7*A_pixel,0)^exp_M*M7*O7*fator_P*P7,"") -> 0.01596414 | Y7: =IF(Q7=1,c_restr*X7,"") -> 0.0022088258
A8: 7 | B8: 9 | C8: 142 | D8: =X0_canto+(C8+0.5)*dx_pix -> 322920.15 | E8: =Y0_canto-(B8+0.5)*dy_pix -> 7434773.3 | F8: =(D8-x_DBT5)^2+(E8-y_DBT5)^2 -> 7.252527e+08 | G8: =(D8-x_CLP)^2+(E8-y_CLP)^2 -> 15578806 | H8: =(P_DBT5/F8+P_CLP/G8)/(1/F8+1/G8) -> 78.659335 | I8: 77 | J8: =4.2*I8/(10-0.058*I8) -> 58.438742 | K8: =25.4*(1000/J8-10) -> 180.64317 | L8: Cambissolos Háplicos | M8: =IFERROR(VLOOKUP(L8,Classes_K,2,FALSE),"") -> 0.047499999 | N8: Mata Nativa | O8: =IFERROR(VLOOKUP(N8,Classes_C,2,FALSE),"") -> 0.015 | P8: 0.33788386 | Q8: =IF(COUNT(M8,O8,P8)=3,1,0) -> 1 | R8: =IF(H8<=p_lambda*K8,0,(H8-p_lambda*K8)^2/(H8+(1-p_lambda)*K8)) -> 19.370828 | S8: =R8/1000*A_pixel*RI_mmh/R_evento_mm/3600 -> 0.0007696495 | T8: =IF(Q8=1,coef_W*MAX(R8*S8*A_pixel,0)^exp_M*M8*O8*fator_P*P8,"") -> 0.012141096 | U8: =IF(Q8=1,c_pura*T8,"") -> 0.0012955249 | V8: =IF(Q8=1,MIN(fator_f*R8,H8),"") -> 23.727765 | W8: =IF(Q8=1,V8/1000*A_pixel*RI_mmh/R_evento_mm/3600,"") -> 0.00094276106 | X8: =IF(Q8=1,coef_W*MAX(V8*W8*A_pixel,0)^exp_M*M8*O8*fator_P*P8,"") -> 0.015238407 | Y8: =IF(Q8=1,c_restr*X8,"") -> 0.0021084123
A9: 8 | B9: 9 | C9: 143 | D9: =X0_canto+(C9+0.5)*dx_pix -> 322950.14 | E9: =Y0_canto-(B9+0.5)*dy_pix -> 7434773.3 | F9: =(D9-x_DBT5)^2+(E9-y_DBT5)^2 -> 7.2371799e+08 | G9: =(D9-x_CLP)^2+(E9-y_CLP)^2 -> 15763120 | H9: =(P_DBT5/F9+P_CLP/G9)/(1/F9+1/G9) -> 78.654675 | I9: 77 | J9: =4.2*I9/(10-0.058*I9) -> 58.438742 | K9: =25.4*(1000/J9-10) -> 180.64317 | L9: Cambissolos Háplicos | M9: =IFERROR(VLOOKUP(L9,Classes_K,2,FALSE),"") -> 0.047499999 | N9: Campo | O9: =IFERROR(VLOOKUP(N9,Classes_C,2,FALSE),"") -> 0.050000001 | P9: 0.35815999 | Q9: =IF(COUNT(M9,O9,P9)=3,1,0) -> 1 | R9: =IF(H9<=p_lambda*K9,0,(H9-p_lambda*K9)^2/(H9+(1-p_lambda)*K9)) -> 19.368596 | S9: =R9/1000*A_pixel*RI_mmh/R_evento_mm/3600 -> 0.00076956082 | T9: =IF(Q9=1,coef_W*MAX(R9*S9*A_pixel,0)^exp_M*M9*O9*fator_P*P9,"") -> 0.042893376 | U9: =IF(Q9=1,c_pura*T9,"") -> 0.0045769702 | V9: =IF(Q9=1,MIN(fator_f*R9,H9),"") -> 23.72503 | W9: =IF(Q9=1,V9/1000*A_pixel*RI_mmh/R_evento_mm/3600,"") -> 0.00094265242 | X9: =IF(Q9=1,coef_W*MAX(V9*W9*A_pixel,0)^exp_M*M9*O9*fator_P*P9,"") -> 0.053835892 | Y9: =IF(Q9=1,c_restr*X9,"") -> 0.0074488266
A10: 9 | B10: 10 | C10: 134 | D10: =X0_canto+(C10+0.5)*dx_pix -> 322680.21 | E10: =Y0_canto-(B10+0.5)*dy_pix -> 7434743.4 | F10: =(D10-x_DBT5)^2+(E10-y_DBT5)^2 -> 7.3709583e+08 | G10: =(D10-x_CLP)^2+(E10-y_CLP)^2 -> 14020579 | H10: =(P_DBT5/F10+P_CLP/G10)/(1/F10+1/G10) -> 78.697608 | I10: 81 | J10: =4.2*I10/(10-0.058*I10) -> 64.164466 | K10: =25.4*(1000/J10-10) -> 141.85773 | M10: =IFERROR(VLOOKUP(L10,Classes_K,2,FALSE),"") | O10: =IFERROR(VLOOKUP(N10,Classes_C,2,FALSE),"") | Q10: =IF(COUNT(M10,O10,P10)=3,1,0) -> 0 | R10: =IF(H10<=p_lambda*K10,0,(H10-p_lambda*K10)^2/(H10+(1-p_lambda)*K10)) -> 24.019382 | S10: =R10/1000*A_pixel*RI_mmh/R_evento_mm/3600 -> 0.0009543477 | T10: =IF(Q10=1,coef_W*MAX(R10*S10*A_pixel,0)^exp_M*M10*O10*fator_P*P10,"") | U10: =IF(Q10=1,c_pura*T10,"") | V10: =IF(Q10=1,MIN(fator_f*R10,H10),"") | W10: =IF(Q10=1,V10/1000*A_pixel*RI_mmh/R_evento_mm/3600,"") | X10: =IF(Q10=1,coef_W*MAX(V10*W10*A_pixel,0)^exp_M*M10*O10*fator_P*P10,"") | Y10: =IF(Q10=1,c_restr*X10,"")
A11: 10 | B11: 10 | C11: 135 | D11: =X0_canto+(C11+0.5)*dx_pix -> 322710.2 | E11: =Y0_canto-(B11+0.5)*dy_pix -> 7434743.4 | F11: =(D11-x_DBT5)^2+(E11-y_DBT5)^2 -> 7.3554672e+08 | G11: =(D11-x_CLP)^2+(E11-y_CLP)^2 -> 14190502 | H11: =(P_DBT5/F11+P_CLP/G11)/(1/F11+1/G11) -> 78.69338 | I11: 77 | J11: =4.2*I11/(10-0.058*I11) -> 58.438742 | K11: =25.4*(1000/J11-10) -> 180.64317 | M11: =IFERROR(VLOOKUP(L11,Classes_K,2,FALSE),"") | O11: =IFERROR(VLOOKUP(N11,Classes_C,2,FALSE),"") | P11: 0.32434723 | Q11: =IF(COUNT(M11,O11,P11)=3,1,0) -> 0 | R11: =IF(H11<=p_lambda*K11,0,(H11-p_lambda*K11)^2/(H11+(1-p_lambda)*K11)) -> 19.387138 | S11: =R11/1000*A_pixel*RI_mmh/R_evento_mm/3600 -> 0.00077029755 | T11: =IF(Q11=1,coef_W*MAX(R11*S11*A_pixel,0)^exp_M*M11*O11*fator_P*P11,"") | U11: =IF(Q11=1,c_pura*T11,"") | V11: =IF(Q11=1,MIN(fator_f*R11,H11),"") | W11: =IF(Q11=1,V11/1000*A_pixel*RI_mmh/R_evento_mm/3600,"") | X11: =IF(Q11=1,coef_W*MAX(V11*W11*A_pixel,0)^exp_M*M11*O11*fator_P*P11,"") | Y11: =IF(Q11=1,c_restr*X11,"")
A12: 11 | B12: 10 | C12: 136 | D12: =X0_canto+(C12+0.5)*dx_pix -> 322740.2 | E12: =Y0_canto-(B12+0.5)*dy_pix -> 7434743.4 | F12: =(D12-x_DBT5)^2+(E12-y_DBT5)^2 -> 7.3399942e+08 | G12: =(D12-x_CLP)^2+(E12-y_CLP)^2 -> 14362223 | H12: =(P_DBT5/F12+P_CLP/G12)/(1/F12+1/G12) -> 78.689099 | I12: 77 | J12: =4.2*I12/(10-0.058*I12) -> 58.438742 | K12: =25.4*(1000/J12-10) -> 180.64317 | M12: =IFERROR(VLOOKUP(L12,Classes_K,2,FALSE),"") | O12: =IFERROR(VLOOKUP(N12,Classes_C,2,FALSE),"") | P12: 0.33123329 | Q12: =IF(COUNT(M12,O12,P12)=3,1,0) -> 0 | R12: =IF(H12<=p_lambda*K12,0,(H12-p_lambda*K12)^2/(H12+(1-p_lambda)*K12)) -> 19.385087 | S12: =R12/1000*A_pixel*RI_mmh/R_evento_mm/3600 -> 0.00077021605 | T12: =IF(Q12=1,coef_W*MAX(R12*S12*A_pixel,0)^exp_M*M12*O12*fator_P*P12,"") | U12: =IF(Q12=1,c_pura*T12,"") | V12: =IF(Q12=1,MIN(fator_f*R12,H12),"") | W12: =IF(Q12=1,V12/1000*A_pixel*RI_mmh/R_evento_mm/3600,"") | X12: =IF(Q12=1,coef_W*MAX(V12*W12*A_pixel,0)^exp_M*M12*O12*fator_P*P12,"") | Y12: =IF(Q12=1,c_restr*X12,"")
A13: 12 | B13: 10 | C13: 137 | D13: =X0_canto+(C13+0.5)*dx_pix -> 322770.19 | E13: =Y0_canto-(B13+0.5)*dy_pix -> 7434743.4 | F13: =(D13-x_DBT5)^2+(E13-y_DBT5)^2 -> 7.3245391e+08 | G13: =(D13-x_CLP)^2+(E13-y_CLP)^2 -> 14535744 | H13: =(P_DBT5/F13+P_CLP/G13)/(1/F13+1/G13) -> 78.684765 | I13: 77 | J13: =4.2*I13/(10-0.058*I13) -> 58.438742 | K13: =25.4*(1000/J13-10) -> 180.64317 | L13: Área Urbana | M13: =IFERROR(VLOOKUP(L13,Classes_K,2,FALSE),"") -> 0 | N13: Campo | O13: =IFERROR(VLOOKUP(N13,Classes_C,2,FALSE),"") -> 0.050000001 | P13: 0.36485711 | Q13: =IF(COUNT(M13,O13,P13)=3,1,0) -> 1 | R13: =IF(H13<=p_lambda*K13,0,(H13-p_lambda*K13)^2/(H13+(1-p_lambda)*K13)) -> 19.38301 | S13: =R13/1000*A_pixel*RI_mmh/R_evento_mm/3600 -> 0.00077013354 | T13: =IF(Q13=1,coef_W*MAX(R13*S13*A_pixel,0)^exp_M*M13*O13*fator_P*P13,"") -> 0 | U13: =IF(Q13=1,c_pura*T13,"") -> 0 | V13: =IF(Q13=1,MIN(fator_f*R13,H13),"") -> 23.742687 | W13: =IF(Q13=1,V13/1000*A_pixel*RI_mmh/R_evento_mm/3600,"") -> 0.00094335396 | X13: =IF(Q13=1,coef_W*MAX(V13*W13*A_pixel,0)^exp_M*M13*O13*fator_P*P13,"") -> 0 | Y13: =IF(Q13=1,c_restr*X13,"") -> 0
A14: 13 | B14: 10 | C14: 138 | D14: =X0_canto+(C14+0.5)*dx_pix -> 322800.18 | E14: =Y0_canto-(B14+0.5)*dy_pix -> 7434743.4 | F14: =(D14-x_DBT5)^2+(E14-y_DBT5)^2 -> 7.3091021e+08 | G14: =(D14-x_CLP)^2+(E14-y_CLP)^2 -> 14711063 | H14: =(P_DBT5/F14+P_CLP/G14)/(1/F14+1/G14) -> 78.680377 | I14: 77 | J14: =4.2*I14/(10-0.058*I14) -> 58.438742 | K14: =25.4*(1000/J14-10) -> 180.64317 | L14: Área Urbana | M14: =IFERROR(VLOOKUP(L14,Classes_K,2,FALSE),"") -> 0 | N14: Mata Nativa | O14: =IFERROR(VLOOKUP(N14,Classes_C,2,FALSE),"") -> 0.015 | P14: 0.47237235 | Q14: =IF(COUNT(M14,O14,P14)=3,1,0) -> 1 | R14: =IF(H14<=p_lambda*K14,0,(H14-p_lambda*K14)^2/(H14+(1-p_lambda)*K14)) -> 19.380908 | S14: =R14/1000*A_pixel*RI_mmh/R_evento_mm/3600 -> 0.00077005002 | T14: =IF(Q14=1,coef_W*MAX(R14*S14*A_pixel,0)^exp_M*M14*O14*fator_P*P14,"") -> 0 | U14: =IF(Q14=1,c_pura*T14,"") -> 0 | V14: =IF(Q14=1,MIN(fator_f*R14,H14),"") -> 23.740112 | W14: =IF(Q14=1,V14/1000*A_pixel*RI_mmh/R_evento_mm/3600,"") -> 0.00094325165 | X14: =IF(Q14=1,coef_W*MAX(V14*W14*A_pixel,0)^exp_M*M14*O14*fator_P*P14,"") -> 0 | Y14: =IF(Q14=1,c_restr*X14,"") -> 0
A15: 14 | B15: 10 | C15: 139 | D15: =X0_canto+(C15+0.5)*dx_pix -> 322830.17 | E15: =Y0_canto-(B15+0.5)*dy_pix -> 7434743.4 | F15: =(D15-x_DBT5)^2+(E15-y_DBT5)^2 -> 7.293683e+08 | G15: =(D15-x_CLP)^2+(E15-y_CLP)^2 -> 14888182 | H15: =(P_DBT5/F15+P_CLP/G15)/(1/F15+1/G15) -> 78.675936 | I15: 77 | J15: =4.2*I15/(10-0.058*I15) -> 58.438742 | K15: =25.4*(1000/J15-10) -> 180.64317 | L15: Cambissolos Háplicos | M15: =IFERROR(VLOOKUP(L15,Classes_K,2,FALSE),"") -> 0.047499999 | N15: Mata Nativa | O15: =IFERROR(VLOOKUP(N15,Classes_C,2,FALSE),"") -> 0.015 | P15: 0.46432543 | Q15: =IF(COUNT(M15,O15,P15)=3,1,0) -> 1 | R15: =IF(H15<=p_lambda*K15,0,(H15-p_lambda*K15)^2/(H15+(1-p_lambda)*K15)) -> 19.37878 | S15: =R15/1000*A_pixel*RI_mmh/R_evento_mm/3600 -> 0.00076996547 | T15: =IF(Q15=1,coef_W*MAX(R15*S15*A_pixel,0)^exp_M*M15*O15*fator_P*P15,"") -> 0.016692161 | U15: =IF(Q15=1,c_pura*T15,"") -> 0.0017811497 | V15: =IF(Q15=1,MIN(fator_f*R15,H15),"") -> 23.737506 | W15: =IF(Q15=1,V15/1000*A_pixel*RI_mmh/R_evento_mm/3600,"") -> 0.00094314809 | X15: =IF(Q15=1,coef_W*MAX(V15*W15*A_pixel,0)^exp_M*M15*O15*fator_P*P15,"") -> 0.020950493 | Y15: =IF(Q15=1,c_restr*X15,"") -> 0.0028987463
A16: 15 | B16: 10 | C16: 140 | D16: =X0_canto+(C16+0.5)*dx_pix -> 322860.16 | E16: =Y0_canto-(B16+0.5)*dy_pix -> 7434743.4 | F16: =(D16-x_DBT5)^2+(E16-y_DBT5)^2 -> 7.2782819e+08 | G16: =(D16-x_CLP)^2+(E16-y_CLP)^2 -> 15067099 | H16: =(P_DBT5/F16+P_CLP/G16)/(1/F16+1/G16) -> 78.67144 | I16: 77 | J16: =4.2*I16/(10-0.058*I16) -> 58.438742 | K16: =25.4*(1000/J16-10) -> 180.64317 | L16: Cambissolos Háplicos | M16: =IFERROR(VLOOKUP(L16,Classes_K,2,FALSE),"") -> 0.047499999 | N16: Mata Nativa | O16: =IFERROR(VLOOKUP(N16,Classes_C,2,FALSE),"") -> 0.015 | P16: 0.34231412 | Q16: =IF(COUNT(M16,O16,P16)=3,1,0) -> 1 | R16: =IF(H16<=p_lambda*K16,0,(H16-p_lambda*K16)^2/(H16+(1-p_lambda)*K16)) -> 19.376627 | S16: =R16/1000*A_pixel*RI_mmh/R_evento_mm/3600 -> 0.0007698799 | T16: =IF(Q16=1,coef_W*MAX(R16*S16*A_pixel,0)^exp_M*M16*O16*fator_P*P16,"") -> 0.012304412 | U16: =IF(Q16=1,c_pura*T16,"") -> 0.0013129516 | V16: =IF(Q16=1,MIN(fator_f*R16,H16),"") -> 23.734868 | W16: =IF(Q16=1,V16/1000*A_pixel*RI_mmh/R_evento_mm/3600,"") -> 0.00094304328 | X16: =IF(Q16=1,coef_W*MAX(V16*W16*A_pixel,0)^exp_M*M16*O16*fator_P*P16,"") -> 0.015443387 | Y16: =IF(Q16=1,c_restr*X16,"") -> 0.0021367735
A17: 16 | B17: 10 | C17: 141 | D17: =X0_canto+(C17+0.5)*dx_pix -> 322890.15 | E17: =Y0_canto-(B17+0.5)*dy_pix -> 7434743.4 | F17: =(D17-x_DBT5)^2+(E17-y_DBT5)^2 -> 7.2628988e+08 | G17: =(D17-x_CLP)^2+(E17-y_CLP)^2 -> 15247816 | H17: =(P_DBT5/F17+P_CLP/G17)/(1/F17+1/G17) -> 78.666891 | I17: 77 | J17: =4.2*I17/(10-0.058*I17) -> 58.438742 | K17: =25.4*(1000/J17-10) -> 180.64317 | L17: Cambissolos Háplicos | M17: =IFERROR(VLOOKUP(L17,Classes_K,2,FALSE),"") -> 0.047499999 | N17: Mata Nativa | O17: =IFERROR(VLOOKUP(N17,Classes_C,2,FALSE),"") -> 0.015 | P17: 0.3249647 | Q17: =IF(COUNT(M17,O17,P17)=3,1,0) -> 1 | R17: =IF(H17<=p_lambda*K17,0,(H17-p_lambda*K17)^2/(H17+(1-p_lambda)*K17)) -> 19.374447 | S17: =R17/1000*A_pixel*RI_mmh/R_evento_mm/3600 -> 0.00076979331 | T17: =IF(Q17=1,coef_W*MAX(R17*S17*A_pixel,0)^exp_M*M17*O17*fator_P*P17,"") -> 0.011679319 | U17: =IF(Q17=1,c_pura*T17,"") -> 0.0012462506 | V17: =IF(Q17=1,MIN(fator_f*R17,H17),"") -> 23.732198 | W17: =IF(Q17=1,V17/1000*A_pixel*RI_mmh/R_evento_mm/3600,"") -> 0.0009429372 | X17: =IF(Q17=1,coef_W*MAX(V17*W17*A_pixel,0)^exp_M*M17*O17*fator_P*P17,"") -> 0.014658826 | Y17: =IF(Q17=1,c_restr*X17,"") -> 0.0020282204
A18: 17 | B18: 10 | C18: 142 | D18: =X0_canto+(C18+0.5)*dx_pix -> 322920.15 | E18: =Y0_canto-(B18+0.5)*dy_pix -> 7434743.4 | F18: =(D18-x_DBT5)^2+(E18-y_DBT5)^2 -> 7.2475337e+08 | G18: =(D18-x_CLP)^2+(E18-y_CLP)^2 -> 15430331 | H18: =(P_DBT5/F18+P_CLP/G18)/(1/F18+1/G18) -> 78.662287 | I18: 77 | J18: =4.2*I18/(10-0.058*I18) -> 58.438742 | K18: =25.4*(1000/J18-10) -> 180.64317 | L18: Cambissolos Háplicos | M18: =IFERROR(VLOOKUP(L18,Classes_K,2,FALSE),"") -> 0.047499999 | N18: Mata Nativa | O18: =IFERROR(VLOOKUP(N18,Classes_C,2,FALSE),"") -> 0.015 | P18: 0.32206097 | Q18: =IF(COUNT(M18,O18,P18)=3,1,0) -> 1 | R18: =IF(H18<=p_lambda*K18,0,(H18-p_lambda*K18)^2/(H18+(1-p_lambda)*K18)) -> 19.372242 | S18: =R18/1000*A_pixel*RI_mmh/R_evento_mm/3600 -> 0.00076970568 | T18: =IF(Q18=1,coef_W*MAX(R18*S18*A_pixel,0)^exp_M*M18*O18*fator_P*P18,"") -> 0.011573482 | U18: =IF(Q18=1,c_pura*T18,"") -> 0.0012349572 | V18: =IF(Q18=1,MIN(fator_f*R18,H18),"") -> 23.729496 | W18: =IF(Q18=1,V18/1000*A_pixel*RI_mmh/R_evento_mm/3600,"") -> 0.00094282986 | X18: =IF(Q18=1,coef_W*MAX(V18*W18*A_pixel,0)^exp_M*M18*O18*fator_P*P18,"") -> 0.01452599 | Y18: =IF(Q18=1,c_restr*X18,"") -> 0.0020098409
A19: 18 | B19: 10 | C19: 143 | D19: =X0_canto+(C19+0.5)*dx_pix -> 322950.14 | E19: =Y0_canto-(B19+0.5)*dy_pix -> 7434743.4 | F19: =(D19-x_DBT5)^2+(E19-y_DBT5)^2 -> 7.2321866e+08 | G19: =(D19-x_CLP)^2+(E19-y_CLP)^2 -> 15614646 | H19: =(P_DBT5/F19+P_CLP/G19)/(1/F19+1/G19) -> 78.657628 | I19: 77 | J19: =4.2*I19/(10-0.058*I19) -> 58.438742 | K19: =25.4*(1000/J19-10) -> 180.64317 | L19: Cambissolos Háplicos | M19: =IFERROR(VLOOKUP(L19,Classes_K,2,FALSE),"") -> 0.047499999 | N19: Mata Nativa | O19: =IFERROR(VLOOKUP(N19,Classes_C,2,FALSE),"") -> 0.015 | P19: 0.33229592 | Q19: =IF(COUNT(M19,O19,P19)=3,1,0) -> 1 | R19: =IF(H19<=p_lambda*K19,0,(H19-p_lambda*K19)^2/(H19+(1-p_lambda)*K19)) -> 19.37001 | S19: =R19/1000*A_pixel*RI_mmh/R_evento_mm/3600 -> 0.00076961701 | T19: =IF(Q19=1,coef_W*MAX(R19*S19*A_pixel,0)^exp_M*M19*O19*fator_P*P19,"") -> 0.011939742 | U19: =IF(Q19=1,c_pura*T19,"") -> 0.0012740392 | V19: =IF(Q19=1,MIN(fator_f*R19,H19),"") -> 23.726763 | W19: =IF(Q19=1,V19/1000*A_pixel*RI_mmh/R_evento_mm/3600,"") -> 0.00094272126 | X19: =IF(Q19=1,coef_W*MAX(V19*W19*A_pixel,0)^exp_M*M19*O19*fator_P*P19,"") -> 0.014985686 | Y19: =IF(Q19=1,c_restr*X19,"") -> 0.0020734452
A20: 19 | B20: 10 | C20: 144 | D20: =X0_canto+(C20+0.5)*dx_pix -> 322980.13 | E20: =Y0_canto-(B20+0.5)*dy_pix -> 7434743.4 | F20: =(D20-x_DBT5)^2+(E20-y_DBT5)^2 -> 7.2168575e+08 | G20: =(D20-x_CLP)^2+(E20-y_CLP)^2 -> 15800759 | H20: =(P_DBT5/F20+P_CLP/G20)/(1/F20+1/G20) -> 78.652915 | I20: 77 | J20: =4.2*I20/(10-0.058*I20) -> 58.438742 | K20: =25.4*(1000/J20-10) -> 180.64317 | L20: Cambissolos Háplicos | M20: =IFERROR(VLOOKUP(L20,Classes_K,2,FALSE),"") -> 0.047499999 | N20: Campo | O20: =IFERROR(VLOOKUP(N20,Classes_C,2,FALSE),"") -> 0.050000001 | P20: 0.32118469 | Q20: =IF(COUNT(M20,O20,P20)=3,1,0) -> 1 | R20: =IF(H20<=p_lambda*K20,0,(H20-p_lambda*K20)^2/(H20+(1-p_lambda)*K20)) -> 19.367752 | S20: =R20/1000*A_pixel*RI_mmh/R_evento_mm/3600 -> 0.00076952731 | T20: =IF(Q20=1,coef_W*MAX(R20*S20*A_pixel,0)^exp_M*M20*O20*fator_P*P20,"") -> 0.038463325 | U20: =IF(Q20=1,c_pura*T20,"") -> 0.0041042582 | V20: =IF(Q20=1,MIN(fator_f*R20,H20),"") -> 23.723997 | W20: =IF(Q20=1,V20/1000*A_pixel*RI_mmh/R_evento_mm/3600,"") -> 0.00094261137 | X20: =IF(Q20=1,coef_W*MAX(V20*W20*A_pixel,0)^exp_M*M20*O20*fator_P*P20,"") -> 0.048275692 | Y20: =IF(Q20=1,c_restr*X20,"") -> 0.0066795078
A21: 20 | B21: 10 | C21: 156 | D21: =X0_canto+(C21+0.5)*dx_pix -> 323340.03 | E21: =Y0_canto-(B21+0.5)*dy_pix -> 7434743.4 | F21: =(D21-x_DBT5)^2+(E21-y_DBT5)^2 -> 7.0343112e+08 | G21: =(D21-x_CLP)^2+(E21-y_CLP)^2 -> 18174442 | H21: =(P_DBT5/F21+P_CLP/G21)/(1/F21+1/G21) -> 78.591987 | I21: 77 | J21: =4.2*I21/(10-0.058*I21) -> 58.438742 | K21: =25.4*(1000/J21-10) -> 180.64317 | L21: Área Urbana | M21: =IFERROR(VLOOKUP(L21,Classes_K,2,FALSE),"") -> 0 | N21: Área Urbanizada | O21: =IFERROR(VLOOKUP(N21,Classes_C,2,FALSE),"") -> 0 | P21: 0.36102194 | Q21: =IF(COUNT(M21,O21,P21)=3,1,0) -> 1 | R21: =IF(H21<=p_lambda*K21,0,(H21-p_lambda*K21)^2/(H21+(1-p_lambda)*K21)) -> 19.338576 | S21: =R21/1000*A_pixel*RI_mmh/R_evento_mm/3600 -> 0.00076836807 | T21: =IF(Q21=1,coef_W*MAX(R21*S21*A_pixel,0)^exp_M*M21*O21*fator_P*P21,"") -> 0 | U21: =IF(Q21=1,c_pura*T21,"") -> 0 | V21: =IF(Q21=1,MIN(fator_f*R21,H21),"") -> 23.688259 | W21: =IF(Q21=1,V21/1000*A_pixel*RI_mmh/R_evento_mm/3600,"") -> 0.0009411914 | X21: =IF(Q21=1,coef_W*MAX(V21*W21*A_pixel,0)^exp_M*M21*O21*fator_P*P21,"") -> 0 | Y21: =IF(Q21=1,c_restr*X21,"") -> 0
A22: 21 | B22: 10 | C22: 157 | D22: =X0_canto+(C22+0.5)*dx_pix -> 323370.02 | E22: =Y0_canto-(B22+0.5)*dy_pix -> 7434743.4 | F22: =(D22-x_DBT5)^2+(E22-y_DBT5)^2 -> 7.0192159e+08 | G22: =(D22-x_CLP)^2+(E22-y_CLP)^2 -> 18383942 | H22: =(P_DBT5/F22+P_CLP/G22)/(1/F22+1/G22) -> 78.586539 | I22: 77 | J22: =4.2*I22/(10-0.058*I22) -> 58.438742 | K22: =25.4*(1000/J22-10) -> 180.64317 | L22: Área Urbana | M22: =IFERROR(VLOOKUP(L22,Classes_K,2,FALSE),"") -> 0 | N22: Área Urbanizada | O22: =IFERROR(VLOOKUP(N22,Classes_C,2,FALSE),"") -> 0 | P22: 0.28450853 | Q22: =IF(COUNT(M22,O22,P22)=3,1,0) -> 1 | R22: =IF(H22<=p_lambda*K22,0,(H22-p_lambda*K22)^2/(H22+(1-p_lambda)*K22)) -> 19.335968 | S22: =R22/1000*A_pixel*RI_mmh/R_evento_mm/3600 -> 0.00076826445 | T22: =IF(Q22=1,coef_W*MAX(R22*S22*A_pixel,0)^exp_M*M22*O22*fator_P*P22,"") -> 0 | U22: =IF(Q22=1,c_pura*T22,"") -> 0 | V22: =IF(Q22=1,MIN(fator_f*R22,H22),"") -> 23.685064 | W22: =IF(Q22=1,V22/1000*A_pixel*RI_mmh/R_evento_mm/3600,"") -> 0.00094106447 | X22: =IF(Q22=1,coef_W*MAX(V22*W22*A_pixel,0)^exp_M*M22*O22*fator_P*P22,"") -> 0 | Y22: =IF(Q22=1,c_restr*X22,"") -> 0
A23: 22 | B23: 11 | C23: 125 | D23: =X0_canto+(C23+0.5)*dx_pix -> 322410.29 | E23: =Y0_canto-(B23+0.5)*dy_pix -> 7434713.5 | F23: =(D23-x_DBT5)^2+(E23-y_DBT5)^2 -> 7.5062117e+08 | G23: =(D23-x_CLP)^2+(E23-y_CLP)^2 -> 12425547 | H23: =(P_DBT5/F23+P_CLP/G23)/(1/F23+1/G23) -> 78.736199 | I23: 77 | J23: =4.2*I23/(10-0.058*I23) -> 58.438742 | K23: =25.4*(1000/J23-10) -> 180.64317 | L23: Área Urbana | M23: =IFERROR(VLOOKUP(L23,Classes_K,2,FALSE),"") -> 0 | N23: Área Urbanizada | O23: =IFERROR(VLOOKUP(N23,Classes_C,2,FALSE),"") -> 0 | P23: 0.26990336 | Q23: =IF(COUNT(M23,O23,P23)=3,1,0) -> 1 | R23: =IF(H23<=p_lambda*K23,0,(H23-p_lambda*K23)^2/(H23+(1-p_lambda)*K23)) -> 19.407659 | S23: =R23/1000*A_pixel*RI_mmh/R_evento_mm/3600 -> 0.0007711129 | T23: =IF(Q23=1,coef_W*MAX(R23*S23*A_pixel,0)^exp_M*M23*O23*fator_P*P23,"") -> 0 | U23: =IF(Q23=1,c_pura*T23,"") -> 0 | V23: =IF(Q23=1,MIN(fator_f*R23,H23),"") -> 23.77288 | W23: =IF(Q23=1,V23/1000*A_pixel*RI_mmh/R_evento_mm/3600,"") -> 0.00094455361 | X23: =IF(Q23=1,coef_W*MAX(V23*W23*A_pixel,0)^exp_M*M23*O23*fator_P*P23,"") -> 0 | Y23: =IF(Q23=1,c_restr*X23,"") -> 0
A24: 23 | B24: 11 | C24: 126 | D24: =X0_canto+(C24+0.5)*dx_pix -> 322440.28 | E24: =Y0_canto-(B24+0.5)*dy_pix -> 7434713.5 | F24: =(D24-x_DBT5)^2+(E24-y_DBT5)^2 -> 7.4905588e+08 | G24: =(D24-x_CLP)^2+(E24-y_CLP)^2 -> 12579279 | H24: =(P_DBT5/F24+P_CLP/G24)/(1/F24+1/G24) -> 78.73244 | I24: 77 | J24: =4.2*I24/(10-0.058*I24) -> 58.438742 | K24: =25.4*(1000/J24-10) -> 180.64317 | L24: Área Urbana | M24: =IFERROR(VLOOKUP(L24,Classes_K,2,FALSE),"") -> 0 | N24: Área Urbanizada | O24: =IFERROR(VLOOKUP(N24,Classes_C,2,FALSE),"") -> 0 | P24: 0.35914347 | Q24: =IF(COUNT(M24,O24,P24)=3,1,0) -> 1 | R24: =IF(H24<=p_lambda*K24,0,(H24-p_lambda*K24)^2/(H24+(1-p_lambda)*K24)) -> 19.405858 | S24: =R24/1000*A_pixel*RI_mmh/R_evento_mm/3600 -> 0.00077104132 | T24: =IF(Q24=1,coef_W*MAX(R24*S24*A_pixel,0)^exp_M*M24*O24*fator_P*P24,"") -> 0 | U24: =IF(Q24=1,c_pura*T24,"") -> 0 | V24: =IF(Q24=1,MIN(fator_f*R24,H24),"") -> 23.770673 | W24: =IF(Q24=1,V24/1000*A_pixel*RI_mmh/R_evento_mm/3600,"") -> 0.00094446592 | X24: =IF(Q24=1,coef_W*MAX(V24*W24*A_pixel,0)^exp_M*M24*O24*fator_P*P24,"") -> 0 | Y24: =IF(Q24=1,c_restr*X24,"") -> 0
... A26: 25 | B26: 11 | C26: 128 | D26: =X0_canto+(C26+0.5)*dx_pix -> 322500.26 | E26: =Y0_canto-(B26+0.5)*dy_pix -> 7434713.5 | F26: =(D26-x_DBT5)^2+(E26-y_DBT5)^2 -> 7.4593069e+08 | G26: =(D26-x_CLP)^2+(E26-y_CLP)^2 -> 12892139 | H26: =(P_DBT5/F26+P_CLP/G26)/(1/F26+1/G26) -> 78.72477 | I26: 81 | J26: =4.2*I26/(10-0.058*I26) -> 64.164466 | K26: =25.4*(1000/J26-10) -> 141.85773 | L26: Área Urbana | M26: =IFERROR(VLOOKUP(L26,Classes_K,2,FALSE),"") -> 0 | N26: Área Urbanizada | O26: =IFERROR(VLOOKUP(N26,Classes_C,2,FALSE),"") -> 0 | P26: 0.25394103 | Q26: =IF(COUNT(M26,O26,P26)=3,1,0) -> 1 | R26: =IF(H26<=p_lambda*K26,0,(H26-p_lambda*K26)^2/(H26+(1-p_lambda)*K26)) -> 24.034549 | S26: =R26/1000*A_pixel*RI_mmh/R_evento_mm/3600 -> 0.00095495035 | T26: =IF(Q26=1,coef_W*MAX(R26*S26*A_pixel,0)^exp_M*M26*O26*fator_P*P26,"") -> 0 | U26: =IF(Q26=1,c_pura*T26,"") -> 0 | V26: =IF(Q26=1,MIN(fator_f*R26,H26),"") -> 29.440462 | W26: =IF(Q26=1,V26/1000*A_pixel*RI_mmh/R_evento_mm/3600,"") -> 0.0011697402 | X26: =IF(Q26=1,coef_W*MAX(V26*W26*A_pixel,0)^exp_M*M26*O26*fator_P*P26,"") -> 0 | Y26: =IF(Q26=1,c_restr*X26,"") -> 0
A27: 26 | B27: 11 | C27: 134 | D27: =X0_canto+(C27+0.5)*dx_pix -> 322680.21 | E27: =Y0_canto-(B27+0.5)*dy_pix -> 7434713.5 | F27: =(D27-x_DBT5)^2+(E27-y_DBT5)^2 -> 7.3659829e+08 | G27: =(D27-x_CLP)^2+(E27-y_CLP)^2 -> 13873896 | H27: =(P_DBT5/F27+P_CLP/G27)/(1/F27+1/G27) -> 78.700514 | I27: 81 | J27: =4.2*I27/(10-0.058*I27) -> 64.164466 | K27: =25.4*(1000/J27-10) -> 141.85773 | L27: Área Urbana | M27: =IFERROR(VLOOKUP(L27,Classes_K,2,FALSE),"") -> 0 | N27: Campo | O27: =IFERROR(VLOOKUP(N27,Classes_C,2,FALSE),"") -> 0.050000001 | Q27: =IF(COUNT(M27,O27,P27)=3,1,0) -> 0 | R27: =IF(H27<=p_lambda*K27,0,(H27-p_lambda*K27)^2/(H27+(1-p_lambda)*K27)) -> 24.021005 | S27: =R27/1000*A_pixel*RI_mmh/R_evento_mm/3600 -> 0.00095441219 | T27: =IF(Q27=1,coef_W*MAX(R27*S27*A_pixel,0)^exp_M*M27*O27*fator_P*P27,"") | U27: =IF(Q27=1,c_pura*T27,"") | V27: =IF(Q27=1,MIN(fator_f*R27,H27),"") | W27: =IF(Q27=1,V27/1000*A_pixel*RI_mmh/R_evento_mm/3600,"") | X27: =IF(Q27=1,coef_W*MAX(V27*W27*A_pixel,0)^exp_M*M27*O27*fator_P*P27,"") | Y27: =IF(Q27=1,c_restr*X27,"")
A28: 27 | B28: 11 | C28: 135 | D28: =X0_canto+(C28+0.5)*dx_pix -> 322710.2 | E28: =Y0_canto-(B28+0.5)*dy_pix -> 7434713.5 | F28: =(D28-x_DBT5)^2+(E28-y_DBT5)^2 -> 7.3504919e+08 | G28: =(D28-x_CLP)^2+(E28-y_CLP)^2 -> 14043818 | H28: =(P_DBT5/F28+P_CLP/G28)/(1/F28+1/G28) -> 78.696288 | I28: 77 | J28: =4.2*I28/(10-0.058*I28) -> 58.438742 | K28: =25.4*(1000/J28-10) -> 180.64317 | L28: Área Urbana | M28: =IFERROR(VLOOKUP(L28,Classes_K,2,FALSE),"") -> 0 | N28: Campo | O28: =IFERROR(VLOOKUP(N28,Classes_C,2,FALSE),"") -> 0.050000001 | P28: 0.32020169 | Q28: =IF(COUNT(M28,O28,P28)=3,1,0) -> 1 | R28: =IF(H28<=p_lambda*K28,0,(H28-p_lambda*K28)^2/(H28+(1-p_lambda)*K28)) -> 19.388532 | S28: =R28/1000*A_pixel*RI_mmh/R_evento_mm/3600 -> 0.00077035292 | T28: =IF(Q28=1,coef_W*MAX(R28*S28*A_pixel,0)^exp_M*M28*O28*fator_P*P28,"") -> 0 | U28: =IF(Q28=1,c_pura*T28,"") -> 0 | V28: =IF(Q28=1,MIN(fator_f*R28,H28),"") -> 23.74945 | W28: =IF(Q28=1,V28/1000*A_pixel*RI_mmh/R_evento_mm/3600,"") -> 0.00094362269 | X28: =IF(Q28=1,coef_W*MAX(V28*W28*A_pixel,0)^exp_M*M28*O28*fator_P*P28,"") -> 0 | Y28: =IF(Q28=1,c_restr*X28,"") -> 0
A29: 28 | B29: 11 | C29: 136 | D29: =X0_canto+(C29+0.5)*dx_pix -> 322740.2 | E29: =Y0_canto-(B29+0.5)*dy_pix -> 7434713.5 | F29: =(D29-x_DBT5)^2+(E29-y_DBT5)^2 -> 7.3350188e+08 | G29: =(D29-x_CLP)^2+(E29-y_CLP)^2 -> 14215540 | H29: =(P_DBT5/F29+P_CLP/G29)/(1/F29+1/G29) -> 78.692009 | I29: 77 | J29: =4.2*I29/(10-0.058*I29) -> 58.438742 | K29: =25.4*(1000/J29-10) -> 180.64317 | L29: Área Urbana | M29: =IFERROR(VLOOKUP(L29,Classes_K,2,FALSE),"") -> 0 | N29: Campo | O29: =IFERROR(VLOOKUP(N29,Classes_C,2,FALSE),"") -> 0.050000001 | P29: 0.35576004 | Q29: =IF(COUNT(M29,O29,P29)=3,1,0) -> 1 | R29: =IF(H29<=p_lambda*K29,0,(H29-p_lambda*K29)^2/(H29+(1-p_lambda)*K29)) -> 19.386481 | S29: =R29/1000*A_pixel*RI_mmh/R_evento_mm/3600 -> 0.00077027145 | T29: =IF(Q29=1,coef_W*MAX(R29*S29*A_pixel,0)^exp_M*M29*O29*fator_P*P29,"") -> 0 | U29: =IF(Q29=1,c_pura*T29,"") -> 0 | V29: =IF(Q29=1,MIN(fator_f*R29,H29),"") -> 23.746939 | W29: =IF(Q29=1,V29/1000*A_pixel*RI_mmh/R_evento_mm/3600,"") -> 0.0009435229 | X29: =IF(Q29=1,coef_W*MAX(V29*W29*A_pixel,0)^exp_M*M29*O29*fator_P*P29,"") -> 0 | Y29: =IF(Q29=1,c_restr*X29,"") -> 0
A30: 29 | B30: 11 | C30: 137 | D30: =X0_canto+(C30+0.5)*dx_pix -> 322770.19 | E30: =Y0_canto-(B30+0.5)*dy_pix -> 7434713.5 | F30: =(D30-x_DBT5)^2+(E30-y_DBT5)^2 -> 7.3195638e+08 | G30: =(D30-x_CLP)^2+(E30-y_CLP)^2 -> 14389060 | H30: =(P_DBT5/F30+P_CLP/G30)/(1/F30+1/G30) -> 78.687676 | I30: 77 | J30: =4.2*I30/(10-0.058*I30) -> 58.438742 | K30: =25.4*(1000/J30-10) -> 180.64317 | L30: Área Urbana | M30: =IFERROR(VLOOKUP(L30,Classes_K,2,FALSE),"") -> 0 | N30: Campo | O30: =IFERROR(VLOOKUP(N30,Classes_C,2,FALSE),"") -> 0.050000001 | P30: 0.41192672 | Q30: =IF(COUNT(M30,O30,P30)=3,1,0) -> 1 | R30: =IF(H30<=p_lambda*K30,0,(H30-p_lambda*K30)^2/(H30+(1-p_lambda)*K30)) -> 19.384406 | S30: =R30/1000*A_pixel*RI_mmh/R_evento_mm/3600 -> 0.00077018897 | T30: =IF(Q30=1,coef_W*MAX(R30*S30*A_pixel,0)^exp_M*M30*O30*fator_P*P30,"") -> 0 | U30: =IF(Q30=1,c_pura*T30,"") -> 0 | V30: =IF(Q30=1,MIN(fator_f*R30,H30),"") -> 23.744396 | W30: =IF(Q30=1,V30/1000*A_pixel*RI_mmh/R_evento_mm/3600,"") -> 0.00094342186 | X30: =IF(Q30=1,coef_W*MAX(V30*W30*A_pixel,0)^exp_M*M30*O30*fator_P*P30,"") -> 0 | Y30: =IF(Q30=1,c_restr*X30,"") -> 0
A31: 30 | B31: 11 | C31: 138 | D31: =X0_canto+(C31+0.5)*dx_pix -> 322800.18 | E31: =Y0_canto-(B31+0.5)*dy_pix -> 7434713.5 | F31: =(D31-x_DBT5)^2+(E31-y_DBT5)^2 -> 7.3041267e+08 | G31: =(D31-x_CLP)^2+(E31-y_CLP)^2 -> 14564380 | H31: =(P_DBT5/F31+P_CLP/G31)/(1/F31+1/G31) -> 78.68329 | I31: 77 | J31: =4.2*I31/(10-0.058*I31) -> 58.438742 | K31: =25.4*(1000/J31-10) -> 180.64317 | L31: Área Urbana | M31: =IFERROR(VLOOKUP(L31,Classes_K,2,FALSE),"") -> 0 | N31: Campo | O31: =IFERROR(VLOOKUP(N31,Classes_C,2,FALSE),"") -> 0.050000001 | P31: 0.4871875 | Q31: =IF(COUNT(M31,O31,P31)=3,1,0) -> 1 | R31: =IF(H31<=p_lambda*K31,0,(H31-p_lambda*K31)^2/(H31+(1-p_lambda)*K31)) -> 19.382304 | S31: =R31/1000*A_pixel*RI_mmh/R_evento_mm/3600 -> 0.00077010547 | T31: =IF(Q31=1,coef_W*MAX(R31*S31*A_pixel,0)^exp_M*M31*O31*fator_P*P31,"") -> 0 | U31: =IF(Q31=1,c_pura*T31,"") -> 0 | V31: =IF(Q31=1,MIN(fator_f*R31,H31),"") -> 23.741822 | W31: =IF(Q31=1,V31/1000*A_pixel*RI_mmh/R_evento_mm/3600,"") -> 0.00094331958 | X31: =IF(Q31=1,coef_W*MAX(V31*W31*A_pixel,0)^exp_M*M31*O31*fator_P*P31,"") -> 0 | Y31: =IF(Q31=1,c_restr*X31,"") -> 0
A32: 31 | B32: 11 | C32: 139 | D32: =X0_canto+(C32+0.5)*dx_pix -> 322830.17 | E32: =Y0_canto-(B32+0.5)*dy_pix -> 7434713.5 | F32: =(D32-x_DBT5)^2+(E32-y_DBT5)^2 -> 7.2887076e+08 | G32: =(D32-x_CLP)^2+(E32-y_CLP)^2 -> 14741498 | H32: =(P_DBT5/F32+P_CLP/G32)/(1/F32+1/G32) -> 78.67885 | I32: 77 | J32: =4.2*I32/(10-0.058*I32) -> 58.438742 | K32: =25.4*(1000/J32-10) -> 180.64317 | L32: Cambissolos Háplicos | M32: =IFERROR(VLOOKUP(L32,Classes_K,2,FALSE),"") -> 0.047499999 | N32: Mata Nativa | O32: =IFERROR(VLOOKUP(N32,Classes_C,2,FALSE),"") -> 0.015 | P32: 0.53984368 | Q32: =IF(COUNT(M32,O32,P32)=3,1,0) -> 1 | R32: =IF(H32<=p_lambda*K32,0,(H32-p_lambda*K32)^2/(H32+(1-p_lambda)*K32)) -> 19.380177 | S32: =R32/1000*A_pixel*RI_mmh/R_evento_mm/3600 -> 0.00077002096 | T32: =IF(Q32=1,coef_W*MAX(R32*S32*A_pixel,0)^exp_M*M32*O32*fator_P*P32,"") -> 0.019408554 | U32: =IF(Q32=1,c_pura*T32,"") -> 0.0020710044 | V32: =IF(Q32=1,MIN(fator_f*R32,H32),"") -> 23.739216 | W32: =IF(Q32=1,V32/1000*A_pixel*RI_mmh/R_evento_mm/3600,"") -> 0.00094321606 | X32: =IF(Q32=1,coef_W*MAX(V32*W32*A_pixel,0)^exp_M*M32*O32*fator_P*P32,"") -> 0.024359864 | Y32: =IF(Q32=1,c_restr*X32,"") -> 0.0033704726
A33: 32 | B33: 11 | C33: 140 | D33: =X0_canto+(C33+0.5)*dx_pix -> 322860.16 | E33: =Y0_canto-(B33+0.5)*dy_pix -> 7434713.5 | F33: =(D33-x_DBT5)^2+(E33-y_DBT5)^2 -> 7.2733065e+08 | G33: =(D33-x_CLP)^2+(E33-y_CLP)^2 -> 14920416 | H33: =(P_DBT5/F33+P_CLP/G33)/(1/F33+1/G33) -> 78.674356 | I33: 77 | J33: =4.2*I33/(10-0.058*I33) -> 58.438742 | K33: =25.4*(1000/J33-10) -> 180.64317 | L33: Cambissolos Háplicos | M33: =IFERROR(VLOOKUP(L33,Classes_K,2,FALSE),"") -> 0.047499999 | N33: Mata Nativa | O33: =IFERROR(VLOOKUP(N33,Classes_C,2,FALSE),"") -> 0.015 | P33: 0.47842357 | Q33: =IF(COUNT(M33,O33,P33)=3,1,0) -> 1 | R33: =IF(H33<=p_lambda*K33,0,(H33-p_lambda*K33)^2/(H33+(1-p_lambda)*K33)) -> 19.378024 | S33: =R33/1000*A_pixel*RI_mmh/R_evento_mm/3600 -> 0.00076993541 | T33: =IF(Q33=1,coef_W*MAX(R33*S33*A_pixel,0)^exp_M*M33*O33*fator_P*P33,"") -> 0.017198227 | U33: =IF(Q33=1,c_pura*T33,"") -> 0.0018351498 | V33: =IF(Q33=1,MIN(fator_f*R33,H33),"") -> 23.736579 | W33: =IF(Q33=1,V33/1000*A_pixel*RI_mmh/R_evento_mm/3600,"") -> 0.00094311127 | X33: =IF(Q33=1,coef_W*MAX(V33*W33*A_pixel,0)^exp_M*M33*O33*fator_P*P33,"") -> 0.021585661 | Y33: =IF(Q33=1,c_restr*X33,"") -> 0.0029866292
A34: 33 | B34: 11 | C34: 141 | D34: =X0_canto+(C34+0.5)*dx_pix -> 322890.15 | E34: =Y0_canto-(B34+0.5)*dy_pix -> 7434713.5 | F34: =(D34-x_DBT5)^2+(E34-y_DBT5)^2 -> 7.2579235e+08 | G34: =(D34-x_CLP)^2+(E34-y_CLP)^2 -> 15101133 | H34: =(P_DBT5/F34+P_CLP/G34)/(1/F34+1/G34) -> 78.669808 | I34: 77 | J34: =4.2*I34/(10-0.058*I34) -> 58.438742 | K34: =25.4*(1000/J34-10) -> 180.64317 | L34: Cambissolos Háplicos | M34: =IFERROR(VLOOKUP(L34,Classes_K,2,FALSE),"") -> 0.047499999 | N34: Mata Nativa | O34: =IFERROR(VLOOKUP(N34,Classes_C,2,FALSE),"") -> 0.015 | P34: 0.35242522 | Q34: =IF(COUNT(M34,O34,P34)=3,1,0) -> 1 | R34: =IF(H34<=p_lambda*K34,0,(H34-p_lambda*K34)^2/(H34+(1-p_lambda)*K34)) -> 19.375845 | S34: =R34/1000*A_pixel*RI_mmh/R_evento_mm/3600 -> 0.00076984884 | T34: =IF(Q34=1,coef_W*MAX(R34*S34*A_pixel,0)^exp_M*M34*O34*fator_P*P34,"") -> 0.012667281 | U34: =IF(Q34=1,c_pura*T34,"") -> 0.0013516718 | V34: =IF(Q34=1,MIN(fator_f*R34,H34),"") -> 23.73391 | W34: =IF(Q34=1,V34/1000*A_pixel*RI_mmh/R_evento_mm/3600,"") -> 0.00094300523 | X34: =IF(Q34=1,coef_W*MAX(V34*W34*A_pixel,0)^exp_M*M34*O34*fator_P*P34,"") -> 0.015898827 | Y34: =IF(Q34=1,c_restr*X34,"") -> 0.002199789
A35: 34 | B35: 11 | C35: 142 | D35: =X0_canto+(C35+0.5)*dx_pix -> 322920.15 | E35: =Y0_canto-(B35+0.5)*dy_pix -> 7434713.5 | F35: =(D35-x_DBT5)^2+(E35-y_DBT5)^2 -> 7.2425583e+08 | G35: =(D35-x_CLP)^2+(E35-y_CLP)^2 -> 15283648 | H35: =(P_DBT5/F35+P_CLP/G35)/(1/F35+1/G35) -> 78.665206 | I35: 77 | J35: =4.2*I35/(10-0.058*I35) -> 58.438742 | K35: =25.4*(1000/J35-10) -> 180.64317 | L35: Cambissolos Háplicos | M35: =IFERROR(VLOOKUP(L35,Classes_K,2,FALSE),"") -> 0.047499999 | N35: Mata Nativa | O35: =IFERROR(VLOOKUP(N35,Classes_C,2,FALSE),"") -> 0.015 | P35: 0.35676956 | Q35: =IF(COUNT(M35,O35,P35)=3,1,0) -> 1 | R35: =IF(H35<=p_lambda*K35,0,(H35-p_lambda*K35)^2/(H35+(1-p_lambda)*K35)) -> 19.37364 | S35: =R35/1000*A_pixel*RI_mmh/R_evento_mm/3600 -> 0.00076976124 | T35: =IF(Q35=1,coef_W*MAX(R35*S35*A_pixel,0)^exp_M*M35*O35*fator_P*P35,"") -> 0.012821796 | U35: =IF(Q35=1,c_pura*T35,"") -> 0.0013681594 | V35: =IF(Q35=1,MIN(fator_f*R35,H35),"") -> 23.731209 | W35: =IF(Q35=1,V35/1000*A_pixel*RI_mmh/R_evento_mm/3600,"") -> 0.00094289792 | X35: =IF(Q35=1,coef_W*MAX(V35*W35*A_pixel,0)^exp_M*M35*O35*fator_P*P35,"") -> 0.01609276 | Y35: =IF(Q35=1,c_restr*X35,"") -> 0.002226622
A36: 35 | B36: 11 | C36: 143 | D36: =X0_canto+(C36+0.5)*dx_pix -> 322950.14 | E36: =Y0_canto-(B36+0.5)*dy_pix -> 7434713.5 | F36: =(D36-x_DBT5)^2+(E36-y_DBT5)^2 -> 7.2272112e+08 | G36: =(D36-x_CLP)^2+(E36-y_CLP)^2 -> 15467962 | H36: =(P_DBT5/F36+P_CLP/G36)/(1/F36+1/G36) -> 78.660548 | I36: 77 | J36: =4.2*I36/(10-0.058*I36) -> 58.438742 | K36: =25.4*(1000/J36-10) -> 180.64317 | L36: Cambissolos Háplicos | M36: =IFERROR(VLOOKUP(L36,Classes_K,2,FALSE),"") -> 0.047499999 | N36: Mata Nativa | O36: =IFERROR(VLOOKUP(N36,Classes_C,2,FALSE),"") -> 0.015 | P36: 0.33504534 | Q36: =IF(COUNT(M36,O36,P36)=3,1,0) -> 1 | R36: =IF(H36<=p_lambda*K36,0,(H36-p_lambda*K36)^2/(H36+(1-p_lambda)*K36)) -> 19.371409 | S36: =R36/1000*A_pixel*RI_mmh/R_evento_mm/3600 -> 0.00076967259 | T36: =IF(Q36=1,coef_W*MAX(R36*S36*A_pixel,0)^exp_M*M36*O36*fator_P*P36,"") -> 0.012039505 | U36: =IF(Q36=1,c_pura*T36,"") -> 0.0012846845 | V36: =IF(Q36=1,MIN(fator_f*R36,H36),"") -> 23.728476 | W36: =IF(Q36=1,V36/1000*A_pixel*RI_mmh/R_evento_mm/3600,"") -> 0.00094278934 | X36: =IF(Q36=1,coef_W*MAX(V36*W36*A_pixel,0)^exp_M*M36*O36*fator_P*P36,"") -> 0.015110899 | Y36: =IF(Q36=1,c_restr*X36,"") -> 0.00209077
A37: 36 | B37: 11 | C37: 144 | D37: =X0_canto+(C37+0.5)*dx_pix -> 322980.13 | E37: =Y0_canto-(B37+0.5)*dy_pix -> 7434713.5 | F37: =(D37-x_DBT5)^2+(E37-y_DBT5)^2 -> 7.2118821e+08 | G37: =(D37-x_CLP)^2+(E37-y_CLP)^2 -> 15654076 | H37: =(P_DBT5/F37+P_CLP/G37)/(1/F37+1/G37) -> 78.655836 | I37: 85 | J37: =4.2*I37/(10-0.058*I37) -> 70.414201 | K37: =25.4*(1000/J37-10) -> 106.72269 | L37: Cambissolos Háplicos | M37: =IFERROR(VLOOKUP(L37,Classes_K,2,FALSE),"") -> 0.047499999 | N37: Área Urbanizada | O37: =IFERROR(VLOOKUP(N37,Classes_C,2,FALSE),"") -> 0 | P37: 0.31468385 | Q37: =IF(COUNT(M37,O37,P37)=3,1,0) -> 1 | R37: =IF(H37<=p_lambda*K37,0,(H37-p_lambda*K37)^2/(H37+(1-p_lambda)*K37)) -> 29.858405 | S37: =R37/1000*A_pixel*RI_mmh/R_evento_mm/3600 -> 0.0011863461 | T37: =IF(Q37=1,coef_W*MAX(R37*S37*A_pixel,0)^exp_M*M37*O37*fator_P*P37,"") -> 0 | U37: =IF(Q37=1,c_pura*T37,"") -> 0 | V37: =IF(Q37=1,MIN(fator_f*R37,H37),"") -> 36.574235 | W37: =IF(Q37=1,V37/1000*A_pixel*RI_mmh/R_evento_mm/3600,"") -> 0.0014531822 | X37: =IF(Q37=1,coef_W*MAX(V37*W37*A_pixel,0)^exp_M*M37*O37*fator_P*P37,"") -> 0 | Y37: =IF(Q37=1,c_restr*X37,"") -> 0
A38: 37 | B38: 11 | C38: 145 | D38: =X0_canto+(C38+0.5)*dx_pix -> 323010.12 | E38: =Y0_canto-(B38+0.5)*dy_pix -> 7434713.5 | F38: =(D38-x_DBT5)^2+(E38-y_DBT5)^2 -> 7.196571e+08 | G38: =(D38-x_CLP)^2+(E38-y_CLP)^2 -> 15841988 | H38: =(P_DBT5/F38+P_CLP/G38)/(1/F38+1/G38) -> 78.651069 | I38: 85 | J38: =4.2*I38/(10-0.058*I38) -> 70.414201 | K38: =25.4*(1000/J38-10) -> 106.72269 | L38: Área Urbana | M38: =IFERROR(VLOOKUP(L38,Classes_K,2,FALSE),"") -> 0 | N38: Campo | O38: =IFERROR(VLOOKUP(N38,Classes_C,2,FALSE),"") -> 0.050000001 | P38: 0.33557907 | Q38: =IF(COUNT(M38,O38,P38)=3,1,0) -> 1 | R38: =IF(H38<=p_lambda*K38,0,(H38-p_lambda*K38)^2/(H38+(1-p_lambda)*K38)) -> 29.855313 | S38: =R38/1000*A_pixel*RI_mmh/R_evento_mm/3600 -> 0.0011862233 | T38: =IF(Q38=1,coef_W*MAX(R38*S38*A_pixel,0)^exp_M*M38*O38*fator_P*P38,"") -> 0 | U38: =IF(Q38=1,c_pura*T38,"") -> 0 | V38: =IF(Q38=1,MIN(fator_f*R38,H38),"") -> 36.570447 | W38: =IF(Q38=1,V38/1000*A_pixel*RI_mmh/R_evento_mm/3600,"") -> 0.0014530317 | X38: =IF(Q38=1,coef_W*MAX(V38*W38*A_pixel,0)^exp_M*M38*O38*fator_P*P38,"") -> 0 | Y38: =IF(Q38=1,c_restr*X38,"") -> 0
A39: 38 | B39: 11 | C39: 154 | D39: =X0_canto+(C39+0.5)*dx_pix -> 323280.04 | E39: =Y0_canto-(B39+0.5)*dy_pix -> 7434713.5 | F39: =(D39-x_DBT5)^2+(E39-y_DBT5)^2 -> 7.0595803e+08 | G39: =(D39-x_CLP)^2+(E39-y_CLP)^2 -> 17614155 | H39: =(P_DBT5/F39+P_CLP/G39)/(1/F39+1/G39) -> 78.60564 | I39: 77 | J39: =4.2*I39/(10-0.058*I39) -> 58.438742 | K39: =25.4*(1000/J39-10) -> 180.64317 | M39: =IFERROR(VLOOKUP(L39,Classes_K,2,FALSE),"") | O39: =IFERROR(VLOOKUP(N39,Classes_C,2,FALSE),"") | Q39: =IF(COUNT(M39,O39,P39)=3,1,0) -> 0 | R39: =IF(H39<=p_lambda*K39,0,(H39-p_lambda*K39)^2/(H39+(1-p_lambda)*K39)) -> 19.345113 | S39: =R39/1000*A_pixel*RI_mmh/R_evento_mm/3600 -> 0.00076862779 | T39: =IF(Q39=1,coef_W*MAX(R39*S39*A_pixel,0)^exp_M*M39*O39*fator_P*P39,"") | U39: =IF(Q39=1,c_pura*T39,"") | V39: =IF(Q39=1,MIN(fator_f*R39,H39),"") | W39: =IF(Q39=1,V39/1000*A_pixel*RI_mmh/R_evento_mm/3600,"") | X39: =IF(Q39=1,coef_W*MAX(V39*W39*A_pixel,0)^exp_M*M39*O39*fator_P*P39,"") | Y39: =IF(Q39=1,c_restr*X39,"")
A40: 39 | B40: 11 | C40: 155 | D40: =X0_canto+(C40+0.5)*dx_pix -> 323310.04 | E40: =Y0_canto-(B40+0.5)*dy_pix -> 7434713.5 | F40: =(D40-x_DBT5)^2+(E40-y_DBT5)^2 -> 7.0444491e+08 | G40: =(D40-x_CLP)^2+(E40-y_CLP)^2 -> 17820057 | H40: =(P_DBT5/F40+P_CLP/G40)/(1/F40+1/G40) -> 78.600308 | I40: 77 | J40: =4.2*I40/(10-0.058*I40) -> 58.438742 | K40: =25.4*(1000/J40-10) -> 180.64317 | L40: Área Urbana | M40: =IFERROR(VLOOKUP(L40,Classes_K,2,FALSE),"") -> 0 | N40: Mata Nativa | O40: =IFERROR(VLOOKUP(N40,Classes_C,2,FALSE),"") -> 0.015 | P40: 0.44432473 | Q40: =IF(COUNT(M40,O40,P40)=3,1,0) -> 1 | R40: =IF(H40<=p_lambda*K40,0,(H40-p_lambda*K40)^2/(H40+(1-p_lambda)*K40)) -> 19.34256 | S40: =R40/1000*A_pixel*RI_mmh/R_evento_mm/3600 -> 0.00076852636 | T40: =IF(Q40=1,coef_W*MAX(R40*S40*A_pixel,0)^exp_M*M40*O40*fator_P*P40,"") -> 0 | U40: =IF(Q40=1,c_pura*T40,"") -> 0 | V40: =IF(Q40=1,MIN(fator_f*R40,H40),"") -> 23.693139 | W40: =IF(Q40=1,V40/1000*A_pixel*RI_mmh/R_evento_mm/3600,"") -> 0.00094138529 | X40: =IF(Q40=1,coef_W*MAX(V40*W40*A_pixel,0)^exp_M*M40*O40*fator_P*P40,"") -> 0 | Y40: =IF(Q40=1,c_restr*X40,"") -> 0
A41: 40 | B41: 11 | C41: 156 | D41: =X0_canto+(C41+0.5)*dx_pix -> 323340.03 | E41: =Y0_canto-(B41+0.5)*dy_pix -> 7434713.5 | F41: =(D41-x_DBT5)^2+(E41-y_DBT5)^2 -> 7.0293358e+08 | G41: =(D41-x_CLP)^2+(E41-y_CLP)^2 -> 18027759 | H41: =(P_DBT5/F41+P_CLP/G41)/(1/F41+1/G41) -> 78.594918 | I41: 77 | J41: =4.2*I41/(10-0.058*I41) -> 58.438742 | K41: =25.4*(1000/J41-10) -> 180.64317 | L41: Área Urbana | M41: =IFERROR(VLOOKUP(L41,Classes_K,2,FALSE),"") -> 0 | N41: Mata Nativa | O41: =IFERROR(VLOOKUP(N41,Classes_C,2,FALSE),"") -> 0.015 | P41: 0.49080786 | Q41: =IF(COUNT(M41,O41,P41)=3,1,0) -> 1 | R41: =IF(H41<=p_lambda*K41,0,(H41-p_lambda*K41)^2/(H41+(1-p_lambda)*K41)) -> 19.33998 | S41: =R41/1000*A_pixel*RI_mmh/R_evento_mm/3600 -> 0.00076842383 | T41: =IF(Q41=1,coef_W*MAX(R41*S41*A_pixel,0)^exp_M*M41*O41*fator_P*P41,"") -> 0 | U41: =IF(Q41=1,c_pura*T41,"") -> 0 | V41: =IF(Q41=1,MIN(fator_f*R41,H41),"") -> 23.689978 | W41: =IF(Q41=1,V41/1000*A_pixel*RI_mmh/R_evento_mm/3600,"") -> 0.0009412597 | X41: =IF(Q41=1,coef_W*MAX(V41*W41*A_pixel,0)^exp_M*M41*O41*fator_P*P41,"") -> 0 | Y41: =IF(Q41=1,c_restr*X41,"") -> 0
...

Sheet Resumo
A1: Resumo do evento 11 (todas as celulas sao formulas sobre a aba Pixels)
A3: Grandeza | B3: Valor | C3: Formula / comentario
A4: Pixels na tabela (com CN, logo com Q) | B4: =COUNT(Pixels!$R$2:$R$301) -> 300 | C4: numero de pixels da tabela
A5: Pixels validos para E_unit (com K, C e LS) | B5: =SUM(Pixels!$Q$2:$Q$301) -> 267 | C5: Valido=1
A6: Chuva IDW media sobre os pixels (mm) | B6: =AVERAGE(Pixels!$H$2:$H$301) -> 78.438092 | C6: media simples da chuva interpolada
A7: Escoamento Q medio sobre os pixels (mm) | B7: =AVERAGE(Pixels!$R$2:$R$301) -> 20.66907 | C7: media simples de Q
A8: V_calc, todos os pixels com Q, usando 900 m2 (m3) | B8: =SUM(Pixels!$R$2:$R$301)/1000*900 -> 5580.649 | C8: e o que os scripts Qvol*.tif / CSV do projeto usam (900 m2); gera 'erro de volume' de -17,76% contra T_R
A9: V_calc, todos os pixels com Q, usando A_pixel (m3) | B9: =SUM(Pixels!$R$2:$R$301)/1000*A_pixel -> 5565.0841 | C9: mesma soma com a area real do pixel
A10: V_calc, so pixels validos, usando A_pixel (m3) [usado no f] | B10: =SUMIF(Pixels!$Q$2:$Q$301,1,Pixels!$R$2:$R$301)/1000*A_pixel -> 4836.311 | C10: e o V_calc do script de volume restrito
A11: V_med (m3) - planilha de eventos | B11: =V_med_m3 -> 2436681.6 | C11: T_R_m3 = soma(Q)*3600 (inclui vazao de base)
A12: Erro do volume do SCS-CN (900 m2) em relacao a V_med (%) | B12: =(B8-B11)/B11*100 -> -99.770973 | C12: erro do volume do SCS-CN em relacao ao T_R (positivo = superestima)
A13: f = V_med / V_calc(validos) [fator do volume restrito] | B13: =B11/B10 -> 1.2249226 | C13: f > 1: o SCS-CN subestima o volume TOTAL medido; mas T_R inclui vazao de base (ver planilha 01)
A14: Pixels em que f*Q passou da chuva do pixel (Q limitado a P) | B14: =SUMPRODUCT((Pixels!$Q$2:$Q$301=1)*(fator_f*Pixels!$R$2:$R$301>Pixels!$H$2:$H$301)) -> 293 | C14: caso fisico: escoamento nao pode superar a chuva
A15: EROSAO / MUSLE
A16: SOMA de E_unit - previsao pura (t) | B16: =SUM(Pixels!$T$2:$T$301) -> 4.4865134 | C16: E_unit nao calibrado
A17: SOMA de E_unit - volume restrito (t) | B17: =SUM(Pixels!$X$2:$X$301) -> 5.6310663
A18: c da previsao pura (aba Calibracao_c) | B18: =c_pura -> 0.10670576 | C18: c = soma(E_n*SY_n)/soma(E_n^2), 17 eventos
A19: c do volume restrito (aba Calibracao_c) | B19: =c_restr -> 0.13836172
A20: SEDIMENTOS NO EXUTORIO DA BACIA
A21: SY simulado - previsao pura (t) = c * soma(E_unit) | B21: =SUM(Pixels!$U$2:$U$301) -> 0.4787368
A22: SY simulado - volume restrito (t) | B22: =SUM(Pixels!$Y$2:$Y$301) -> 0.77912402
A23: SY observado (t) = SYY_t | B23: =SY_obs_t -> 1821.7535
A24: Erro % - previsao pura = (sim-obs)/obs*100 | B24: =(B21-B23)/B23*100 -> -99.973721 | C24: negativo = subestima
A25: Erro % - volume restrito | B25: =(B22-B23)/B23*100 -> -99.957232
A26: NORMALIZACAO
A27: SY medio por pixel - previsao pura (t/pixel) | B27: =B21/B5 -> 0.0017930217
A28: SY medio por pixel - volume restrito (t/pixel) | B28: =B22/B5 -> 0.0029180675
A29: SY medio por hectare - previsao pura (t/ha) | B29: =B21/(B5*A_pixel/10000) -> 0.019978185 | C29: area dos pixels validos
A30: SY medio por hectare - volume restrito (t/ha) | B30: =B22/(B5*A_pixel/10000) -> 0.032513656

Sheet Calibracao_c
A1: Calibracao de c (minimos quadrados pela origem, 17 eventos) e metricas
A2: SY_sim = c * soma(E_unit). c = soma(E*SY_obs)/soma(E^2). SOMA(E_unit) dos eventos 1-10 e 12-17 vem dos rasters ja gerados (E_unit{n}.tif / E_unit{n}_obs.tif); a do evento 11 e a formula sobre a aba Pixels.
A4: Evento | B4: SY_obs (t) | C4: SOMA E pura (t) | D4: E*SY | E4: E^2 | F4: SY_sim (t) | G4: erro % | H4: (sim-obs)^2 | I4: (obs-media)^2 | J4: SY_sim LOO (t) | K4: erro LOO % | L4: SOMA E restrita (t) | M4: E*SY | N4: E^2 | O4: SY_sim (t) | P4: erro % | Q4: (sim-obs)^2 | R4: SY_sim LOO (t) | S4: erro LOO %
A5: 1 | B5: 266.3566 | C5: 842.9142 | D5: =C5*B5 -> 224515.76 | E5: =C5^2 -> 710504.36 | F5: =$B$22*C5 -> 89.943797 | G5: =(F5-B5)/B5*100 -> -66.231812 | H5: =(F5-B5)^2 -> 31121.476 | I5: =(B5-AVERAGE($B$5:$B$21))^2 -> 1291251.1 | J5: =(SUM(D$5:D$21)-D5)/(SUM(E$5:E$21)-E5)*C5 -> 89.903907 | K5: =(J5-B5)/B5*100 -> -66.246788 | L5: 3190.1666 | M5: =L5*B5 -> 849721.92 | N5: =L5^2 -> 10177163 | O5: =$L$22*L5 -> 441.39694 | P5: =(O5-B5)/B5*100 -> 65.716542 | Q5: =(O5-B5)^2 -> 30639.122 | R5: =(SUM(M$5:M$21)-M5)/(SUM(N$5:N$21)-N5)*L5 -> 442.24844 | S5: =(R5-B5)/B5*100 -> 66.036226
A6: 2 | B6: 2039.8855 | C6: 5580.6485 | D6: =C6*B6 -> 11383884 | E6: =C6^2 -> 31143638 | F6: =$B$22*C6 -> 595.48732 | G6: =(F6-B6)/B6*100 -> -70.807807 | H6: =(F6-B6)^2 -> 2086286.1 | I6: =(B6-AVERAGE($B$5:$B$21))^2 -> 406019.54 | J6: =(SUM(D$5:D$21)-D6)/(SUM(E$5:E$21)-E6)*C6 -> 581.03111 | K6: =(J6-B6)/B6*100 -> -71.516484 | L6: 13864.309 | M6: =L6*B6 -> 28281602 | N6: =L6^2 -> 1.9221905e+08 | O6: =$L$22*L6 -> 1918.2896 | P6: =(O6-B6)/B6*100 -> -5.9609183 | Q6: =(O6-B6)^2 -> 14785.565 | R6: =(SUM(M$5:M$21)-M6)/(SUM(N$5:N$21)-N6)*L6 -> 1906.0527 | S6: =(R6-B6)/B6*100 -> -6.5607994
A7: 3 | B7: 927.77597 | C7: 13120.268 | D7: =C7*B7 -> 12172669 | E7: =C7^2 -> 1.7214142e+08 | F7: =$B$22*C7 -> 1400.0081 | G7: =(F7-B7)/B7*100 -> 50.899368 | H7: =(F7-B7)^2 -> 223003.16 | I7: =(B7-AVERAGE($B$5:$B$21))^2 -> 225542.27 | J7: =(SUM(D$5:D$21)-D7)/(SUM(E$5:E$21)-E7)*C7 -> 1427.372 | K7: =(J7-B7)/B7*100 -> 53.848773 | L7: 8645.8209 | M7: =L7*B7 -> 8021384.9 | N7: =L7^2 -> 74750219 | O7: =$L$22*L7 -> 1196.2507 | P7: =(O7-B7)/B7*100 -> 28.937447 | Q7: =(O7-B7)^2 -> 72078.656 | R7: =(SUM(M$5:M$21)-M7)/(SUM(N$5:N$21)-N7)*L7 -> 1206.1487 | S7: =(R7-B7)/B7*100 -> 30.004309
A8: 4 | B8: 1379.8616 | C8: 3151.7594 | D8: =C8*B8 -> 4348991.7 | E8: =C8^2 -> 9933587.2 | F8: =$B$22*C8 -> 336.31087 | G8: =(F8-B8)/B8*100 -> -75.627202 | H8: =(F8-B8)^2 -> 1088998.1 | I8: =(B8-AVERAGE($B$5:$B$21))^2 -> 521.08622 | J8: =(SUM(D$5:D$21)-D8)/(SUM(E$5:E$21)-E8)*C8 -> 333.00209 | K8: =(J8-B8)/B8*100 -> -75.866993 | L8: 14952.076 | M8: =L8*B8 -> 20631795 | N8: =L8^2 -> 2.2356458e+08 | O8: =$L$22*L8 -> 2068.795 | P8: =(O8-B8)/B8*100 -> 49.92772 | Q8: =(O8-B8)^2 -> 474629.26 | R8: =(SUM(M$5:M$21)-M8)/(SUM(N$5:N$21)-N8)*L8 -> 2150.7777 | S8: =(R8-B8)/B8*100 -> 55.86909
A9: 5 | B9: 1371.7009 | C9: 10290.746 | D9: =C9*B9 -> 14115826 | E9: =C9^2 -> 1.0589946e+08 | F9: =$B$22*C9 -> 1098.0818 | G9: =(F9-B9)/B9*100 -> -19.947428 | H9: =(F9-B9)^2 -> 74867.388 | I9: =(B9-AVERAGE($B$5:$B$21))^2 -> 960.25479 | J9: =(SUM(D$5:D$21)-D9)/(SUM(E$5:E$21)-E9)*C9 -> 1088.5407 | K9: =(J9-B9)/B9*100 -> -20.642997 | L9: 13754.377 | M9: =L9*B9 -> 18866891 | N9: =L9^2 -> 1.8918288e+08 | O9: =$L$22*L9 -> 1903.0792 | P9: =(O9-B9)/B9*100 -> 38.738642 | Q9: =(O9-B9)^2 -> 282362.91 | R9: =(SUM(M$5:M$21)-M9)/(SUM(N$5:N$21)-N9)*L9 -> 1955.6266 | S9: =(R9-B9)/B9*100 -> 42.569465
A10: 6 | B10: 198.55858 | C10: 3165.9307 | D10: =C10*B10 -> 628622.7 | E10: =C10^2 -> 10023117 | F10: =$B$22*C10 -> 337.82303 | G10: =(F10-B10)/B10*100 -> 70.137712 | H10: =(F10-B10)^2 -> 19394.586 | I10: =(B10-AVERAGE($B$5:$B$21))^2 -> 1449929.8 | J10: =(SUM(D$5:D$21)-D10)/(SUM(E$5:E$21)-E10)*C10 -> 338.26858 | K10: =(J10-B10)/B10*100 -> 70.362107 | L10: 2453.3226 | M10: =L10*B10 -> 487128.26 | N10: =L10^2 -> 6018792 | O10: =$L$22*L10 -> 339.44594 | P10: =(O10-B10)/B10*100 -> 70.95506 | Q10: =(O10-B10)^2 -> 19849.248 | R10: =(SUM(M$5:M$21)-M10)/(SUM(N$5:N$21)-N10)*L10 -> 339.85046 | S10: =(R10-B10)/B10*100 -> 71.158787
