Workbook

Sheet Leia-me
A1: Planilha dos cálculos concentrados do TCC (bacia inteira, fora dos rasters)
A3: O que é | B3: Tudo o que o modelo calcula depois que os rasters já deram a soma de E_unit de cada evento: a calibração do coeficiente c, a validação cruzada, as métricas e as comparações. Também refaz, a partir da série horária, o volume, a vazão de base e a carga medida de cada evento.
A4: Como ler | B4: Cada aba tem: linha 1 = título; linha 2 = o que a aba faz; depois, uma linha de cabeçalhos (em azul) e, logo abaixo, uma linha em cinza dizendo como cada coluna é calculada. Clique numa célula para ver a fórmula.
A5: Cores | B5: Azul = cabeçalho. Amarelo = número que vem dos rasters (calculado em Python sobre os mapas; aqui entra como valor). Verde = resultado final da aba.
A7: Abas, na ordem
A8: Serie_horaria | B8: Dados horários da seção de controle (vazão Q e concentração CSS) e a vazão de base: a da planilha original e a recalculada aqui pelo filtro de Eckhardt (alfa = 0,995; BFImax = 0,70).
A9: Eventos | B9: Uma linha por evento: chuva, volume total, vazão de base, escoamento direto medido (V_dir), carga medida (SY_medido), e os números que vêm dos rasters (volume do SCS-CN e soma de E_unit no MC e no MFM).
A10: Volume | B10: Compara o escoamento direto calculado pelo SCS-CN com o medido (viés, erro, NSE do volume).
A11: MC | B11: Modelo Calculado: SY = c * soma(E_unit), com a água do SCS-CN (só chuva). Calibra c, faz a validação cruzada e calcula as métricas.
A12: MFM | B12: Modelo Forçado ao Medido: igual ao MC, mas com o escoamento direto medido distribuído pelo padrão do SCS-CN.
A13: Regra_chuva | B13: Regra simples SY = c * R (R = chuva do evento, mm). Referência para o MC (usa a mesma informação: só chuva).
A14: Regra_Vdir | B14: Regra simples SY = c * V_dir (escoamento direto medido). Referência para o MFM.
A15: Regra_TR | B15: Regra simples SY = c * TR (volume total medido, com a vazão de base). Só para comparação.
A16: IC_refeita | B16: Formulação concentrada da Iniciação Científica: SY = alfa * (TR * Qpico)^beta * K * LS * C, com alfa e beta ajustados por regressão em log.
A17: Resumo | B17: Tabela final comparando todos os modelos (puxa os resultados das outras abas).
A19: Calibração de c | B19: c é escolhido para minimizar o erro em escala log: ln c = média de [ln(SY_medido) - ln(x)], em que x é a soma de E_unit (MC, MFM) ou a grandeza da regra simples. Na prática, c é a média geométrica de SY_medido / x.
A20: Validação cruzada | B20: Leave-one-out: para prever cada evento, c é recalculado com os outros 16 eventos (sem ele). As métricas principais usam essas 17 previsões.
... A22: Unidades | B22: Volumes em m³; chuva em mm; vazão em m³/s; CSS em mg/L; sedimento em t. E_unit é um índice sem unidade física; c converte o índice em t.

Sheet Resumo
A1: Resumo: desempenho na validação cruzada (17 eventos, calibração em log, carga total)
A2: Todos os números vêm das outras abas. Erro mediano, fator 2, NSE em log e Spearman são as métricas principais; o NSE linear é secundário.
A4: Modelo | B4: Informação medida usada | C4: Coeficiente c | D4: Erro mediano (%) | E4: Dentro de fator 2 (%) | F4: NSE em log | G4: Spearman | H4: NSE linear (secundário)
C5: c com os 17 eventos | D5: validação cruzada | E5: validação cruzada | F5: validação cruzada | G5: validação cruzada | H5: validação cruzada
A6: MC (Modelo Calculado) | B6: chuva | C6: =MC!$D$26 | D6: =MC!$D$27 | E6: =MC!$D$28 | F6: =MC!$D$29 | G6: =MC!$D$31 | H6: =MC!$D$30
A7: Regra SY = c * chuva | B7: chuva | C7: =Regra_chuva!$D$26 | D7: =Regra_chuva!$D$27 | E7: =Regra_chuva!$D$28 | F7: =Regra_chuva!$D$29 | G7: =Regra_chuva!$D$31 | H7: =Regra_chuva!$D$30
A8: MFM (Modelo Forçado ao Medido) | B8: chuva e escoamento direto medido | C8: =MFM!$D$26 | D8: =MFM!$D$27 | E8: =MFM!$D$28 | F8: =MFM!$D$29 | G8: =MFM!$D$31 | H8: =MFM!$D$30
A9: Regra SY = c * V_dir | B9: escoamento direto medido | C9: =Regra_Vdir!$D$26 | D9: =Regra_Vdir!$D$27 | E9: =Regra_Vdir!$D$28 | F9: =Regra_Vdir!$D$29 | G9: =Regra_Vdir!$D$31 | H9: =Regra_Vdir!$D$30
A10: Regra SY = c * TR | B10: volume total medido | C10: =Regra_TR!$D$26 | D10: =Regra_TR!$D$27 | E10: =Regra_TR!$D$28 | F10: =Regra_TR!$D$29 | G10: =Regra_TR!$D$31 | H10: =Regra_TR!$D$30
A11: IC refeita (concentrada) | B11: volume total e vazão de pico medidos | C11: alfa e beta | D11: =IC_refeita!$D$34 | E11: =IC_refeita!$D$35 | F11: =IC_refeita!$D$36 | G11: =IC_refeita!$D$38 | H11: =IC_refeita!$D$37
A13: Escoamento direto do SCS-CN contra o medido (aba Volume)
A14: Viés do total (%) | C14: =Volume!$D$25
A15: Erro médio absoluto por evento (%) | C15: =Volume!$D$26
A16: Erro mediano por evento (%) | C16: =Volume!$D$27
A17: Eventos dentro de fator 2 (%) | C17: =Volume!$D$29
A18: NSE do volume | C18: =Volume!$D$30

Sheet Serie_horaria
A1: Série horária na seção de controle
A2: Fonte: Dados_finais_histereses_corrigido.xlsx. A vazão de base é recalculada pelo filtro de Eckhardt com os parâmetros das células J4 e J5.
A4: Data e hora | B4: Vazão Q (m³/s) | C4: Concentração de sedimento CSS (mg/L) | D4: Vazão de base da planilha original (m³/s) | E4: Vazão de base pelo filtro de Eckhardt (m³/s) | F4: Carga de sedimento na hora (t) | I4: alfa (parâmetro do filtro) | J4: 0.995
A5: dado | B5: dado | C5: dado | D5: dado | E5: = MIN(Q; ((1-BFImax)*alfa*base anterior + (1-alfa)*BFImax*Q) / (1-alfa*BFImax)) | F5: = Q * CSS * 3600 s / 1.000.000 (g -> t) | I5: BFImax (parâmetro do filtro) | J5: 0.7
A6: 43418.75 | B6: 1.278 | C6: 57.480757 | D6: 1.2638141 | E6: =D6 | F6: =B6*C6*3.6/1000
A7: 43418.792 | B7: 1.197 | C7: 61.834775 | D7: 1.197 | E7: =MIN(B7,((1-$J$5)*$J$4*E6+(1-$J$4)*$J$5*B7)/(1-$J$4*$J$5)) | F7: =B7*C7*3.6/1000
A8: 43418.833 | B8: 1.184 | C8: 67.923774 | D8: 1.184 | E8: =MIN(B8,((1-$J$5)*$J$4*E7+(1-$J$4)*$J$5*B8)/(1-$J$4*$J$5)) | F8: =B8*C8*3.6/1000
A9: 43418.875 | B9: 1.19 | C9: 51.755528 | D9: 1.1782163 | E9: =MIN(B9,((1-$J$5)*$J$4*E8+(1-$J$4)*$J$5*B9)/(1-$J$4*$J$5)) | F9: =B9*C9*3.6/1000
A10: 43418.917 | B10: 1.166 | C10: 51.884455 | D10: 1.166 | E10: =MIN(B10,((1-$J$5)*$J$4*E9+(1-$J$4)*$J$5*B10)/(1-$J$4*$J$5)) | F10: =B10*C10*3.6/1000
A11: 43418.958 | B11: 1.141 | C11: 56.095155 | D11: 1.141 | E11: =MIN(B11,((1-$J$5)*$J$4*E10+(1-$J$4)*$J$5*B11)/(1-$J$4*$J$5)) | F11: =B11*C11*3.6/1000
A12: 43419 | B12: 1.135 | C12: 62.129771 | D12: 1.135 | E12: =MIN(B12,((1-$J$5)*$J$4*E11+(1-$J$4)*$J$5*B12)/(1-$J$4*$J$5)) | F12: =B12*C12*3.6/1000
A13: 43419.042 | B13: 1.117 | C13: 68.164388 | D13: 1.117 | E13: =MIN(B13,((1-$J$5)*$J$4*E12+(1-$J$4)*$J$5*B13)/(1-$J$4*$J$5)) | F13: =B13*C13*3.6/1000
A14: 43419.083 | B14: 1.105 | C14: 56.852002 | D14: 1.105 | E14: =MIN(B14,((1-$J$5)*$J$4*E13+(1-$J$4)*$J$5*B14)/(1-$J$4*$J$5)) | F14: =B14*C14*3.6/1000
A15: 43419.125 | B15: 1.087 | C15: 50.591468 | D15: 1.087 | E15: =MIN(B15,((1-$J$5)*$J$4*E14+(1-$J$4)*$J$5*B15)/(1-$J$4*$J$5)) | F15: =B15*C15*3.6/1000
A16: 43419.167 | B16: 1.069 | C16: 47.584961 | D16: 1.069 | E16: =MIN(B16,((1-$J$5)*$J$4*E15+(1-$J$4)*$J$5*B16)/(1-$J$4*$J$5)) | F16: =B16*C16*3.6/1000
A17: 43419.208 | B17: 1.075 | C17: 46.527955 | D17: 1.0637847 | E17: =MIN(B17,((1-$J$5)*$J$4*E16+(1-$J$4)*$J$5*B17)/(1-$J$4*$J$5)) | F17: =B17*C17*3.6/1000
A18: 43419.25 | B18: 1.075 | C18: 53.041179 | D18: 1.0586549 | E18: =MIN(B18,((1-$J$5)*$J$4*E17+(1-$J$4)*$J$5*B18)/(1-$J$4*$J$5)) | F18: =B18*C18*3.6/1000
... A20843: 44286.958 | B20843: 0.473 | C20843: 50.46171 | D20843: 0.41972815 | E20843: =MIN(B20843,((1-$J$5)*$J$4*E20842+(1-$J$4)*$J$5*B20843)/(1-$J$4*$J$5)) | F20843: =B20843*C20843*3.6/1000

Sheet Eventos
A1: Os 17 eventos: dados medidos e números que vêm dos rasters
A2: Volumes e carga são somados na Série_horaria entre o início e o fim do evento. As colunas em amarelo vêm dos rasters (Python).
A4: Evento | B4: Início | C4: Fim | D4: Chuva no posto DBT5, P1 (mm) | E4: Chuva no posto Campo Limpo, P2 (mm) | F4: Chuva do evento R (mm) | G4: Intensidade máxima em 60 min RI (mm/h) | H4: Vazão de pico (m³/s) | I4: Volume total escoado TR (m³) | J4: Volume da vazão de base (m³) | K4: Volume da vazão de base, Eckhardt recalculado (m³) | L4: Escoamento direto medido V_dir (m³) | M4: Escoamento direto calculado pelo SCS-CN V_SCS (m³) | N4: Razão SCS-CN / medido | O4: Soma de E_unit no MC (índice) | P4: Soma de E_unit no MFM (índice) | Q4: Sedimento medido SY_medido (t)
B5: dado | C5: dado | D5: dado | E5: dado | F5: = 0,307*P1 + 0,693*P2 | G5: dado | H5: dado | I5: = soma de Q * 3600 na janela | J5: = soma da base da planilha * 3600 na janela | K5: = soma da base recalculada * 3600 (só para conferência) | L5: = TR - volume da base | M5: RASTERS: soma de Q de todos os pixels | N5: = V_SCS / V_dir | O5: RASTERS: soma do índice de erosão, água do SCS-CN | P5: RASTERS: soma do índice de erosão, água medida | Q5: = soma da carga horária na janela
A6: 1 | B6: 43426.375 | C6: 43427.958 | D6: 32.8 | E6: 19.2 | F6: =0.307*D6+0.693*E6 | G6: 23.6 | H6: 10.288 | I6: =SUMIFS(Serie_horaria!$B$6:$B$20843,Serie_horaria!$A$6:$A$20843,">="&B6,Serie_horaria!$A$6:$A$20843,"<="&C6)*3600 | J6: =SUMIFS(Serie_horaria!$D$6:$D$20843,Serie_horaria!$A$6:$A$20843,">="&B6,Serie_horaria!$A$6:$A$20843,"<="&C6)*3600 | K6: =SUMIFS(Serie_horaria!$E$6:$E$20843,Serie_horaria!$A$6:$A$20843,">="&B6,Serie_horaria!$A$6:$A$20843,"<="&C6)*3600 | L6: =I6-J6 | M6: 35538.542 | N6: =M6/L6 | O6: 2161.4044 | P6: 16090.092 | Q6: =SUMIFS(Serie_horaria!$F$6:$F$20843,Serie_horaria!$A$6:$A$20843,">="&B6,Serie_horaria!$A$6:$A$20843,"<="&C6)
A7: 2 | B7: 43434.917 | C7: 43437.167 | D7: 64 | E7: 54.4 | F7: =0.307*D7+0.693*E7 | G7: 19 | H7: 30.385 | I7: =SUMIFS(Serie_horaria!$B$6:$B$20843,Serie_horaria!$A$6:$A$20843,">="&B7,Serie_horaria!$A$6:$A$20843,"<="&C7)*3600 | J7: =SUMIFS(Serie_horaria!$D$6:$D$20843,Serie_horaria!$A$6:$A$20843,">="&B7,Serie_horaria!$A$6:$A$20843,"<="&C7)*3600 | K7: =SUMIFS(Serie_horaria!$E$6:$E$20843,Serie_horaria!$A$6:$A$20843,">="&B7,Serie_horaria!$A$6:$A$20843,"<="&C7)*3600 | L7: =I7-J7 | M7: 521004.91 | N7: =M7/L7 | O7: 28795.141 | P7: 109697.9 | Q7: =SUMIFS(Serie_horaria!$F$6:$F$20843,Serie_horaria!$A$6:$A$20843,">="&B7,Serie_horaria!$A$6:$A$20843,"<="&C7)
A8: 3 | B8: 43451.917 | C8: 43454.917 | D8: 51 | E8: 71.8 | F8: =0.307*D8+0.693*E8 | G8: 53.2 | H8: 16.56 | I8: =SUMIFS(Serie_horaria!$B$6:$B$20843,Serie_horaria!$A$6:$A$20843,">="&B8,Serie_horaria!$A$6:$A$20843,"<="&C8)*3600 | J8: =SUMIFS(Serie_horaria!$D$6:$D$20843,Serie_horaria!$A$6:$A$20843,">="&B8,Serie_horaria!$A$6:$A$20843,"<="&C8)*3600 | K8: =SUMIFS(Serie_horaria!$E$6:$E$20843,Serie_horaria!$A$6:$A$20843,">="&B8,Serie_horaria!$A$6:$A$20843,"<="&C8)*3600 | L8: =I8-J8 | M8: 750546.97 | N8: =M8/L8 | O8: 74334.639 | P8: 56223.997 | Q8: =SUMIFS(Serie_horaria!$F$6:$F$20843,Serie_horaria!$A$6:$A$20843,">="&B8,Serie_horaria!$A$6:$A$20843,"<="&C8)
A9: 4 | B9: 43458.25 | C9: 43460.958 | D9: 57 | E9: 27 | F9: =0.307*D9+0.693*E9 | G9: 35.2 | H9: 17.028 | I9: =SUMIFS(Serie_horaria!$B$6:$B$20843,Serie_horaria!$A$6:$A$20843,">="&B9,Serie_horaria!$A$6:$A$20843,"<="&C9)*3600 | J9: =SUMIFS(Serie_horaria!$D$6:$D$20843,Serie_horaria!$A$6:$A$20843,">="&B9,Serie_horaria!$A$6:$A$20843,"<="&C9)*3600 | K9: =SUMIFS(Serie_horaria!$E$6:$E$20843,Serie_horaria!$A$6:$A$20843,">="&B9,Serie_horaria!$A$6:$A$20843,"<="&C9)*3600 | L9: =I9-J9 | M9: 154471.27 | N9: =M9/L9 | O9: 12324.058 | P9: 96616.964 | Q9: =SUMIFS(Serie_horaria!$F$6:$F$20843,Serie_horaria!$A$6:$A$20843,">="&B9,Serie_horaria!$A$6:$A$20843,"<="&C9)
A10: 5 | B10: 43469.792 | C10: 43473.708 | D10: 24 | E10: 77.2 | F10: =0.307*D10+0.693*E10 | G10: 36.6 | H10: 22.085 | I10: =SUMIFS(Serie_horaria!$B$6:$B$20843,Serie_horaria!$A$6:$A$20843,">="&B10,Serie_horaria!$A$6:$A$20843,"<="&C10)*3600 | J10: =SUMIFS(Serie_horaria!$D$6:$D$20843,Serie_horaria!$A$6:$A$20843,">="&B10,Serie_horaria!$A$6:$A$20843,"<="&C10)*3600 | K10: =SUMIFS(Serie_horaria!$E$6:$E$20843,Serie_horaria!$A$6:$A$20843,">="&B10,Serie_horaria!$A$6:$A$20843,"<="&C10)*3600 | L10: =I10-J10 | M10: 694670.89 | N10: =M10/L10 | O10: 59172.952 | P10: 72421.336 | Q10: =SUMIFS(Serie_horaria!$F$6:$F$20843,Serie_horaria!$A$6:$A$20843,">="&B10,Serie_horaria!$A$6:$A$20843,"<="&C10)
A11: 6 | B11: 43481.5 | C11: 43482.542 | D11: 11 | E11: 44.8 | F11: =0.307*D11+0.693*E11 | G11: 29.4 | H11: 14.687 | I11: =SUMIFS(Serie_horaria!$B$6:$B$20843,Serie_horaria!$A$6:$A$20843,">="&B11,Serie_horaria!$A$6:$A$20843,"<="&C11)*3600 | J11: =SUMIFS(Serie_horaria!$D$6:$D$20843,Serie_horaria!$A$6:$A$20843,">="&B11,Serie_horaria!$A$6:$A$20843,"<="&C11)*3600 | K11: =SUMIFS(Serie_horaria!$E$6:$E$20843,Serie_horaria!$A$6:$A$20843,">="&B11,Serie_horaria!$A$6:$A$20843,"<="&C11)*3600 | L11: =I11-J11 | M11: 158263.92 | N11: =M11/L11 | O11: 13469.691 | P11: 15856.162 | Q11: =SUMIFS(Serie_horaria!$F$6:$F$20843,Serie_horaria!$A$6:$A$20843,">="&B11,Serie_horaria!$A$6:$A$20843,"<="&C11)
A12: 7 | B12: 43490 | C12: 43493.417 | D12: 29 | E12: 38.4 | F12: =0.307*D12+0.693*E12 | G12: 15.4 | H12: 16.419 | I12: =SUMIFS(Serie_horaria!$B$6:$B$20843,Serie_horaria!$A$6:$A$20843,">="&B12,Serie_horaria!$A$6:$A$20843,"<="&C12)*3600 | J12: =SUMIFS(Serie_horaria!$D$6:$D$20843,Serie_horaria!$A$6:$A$20843,">="&B12,Serie_horaria!$A$6:$A$20843,"<="&C12)*3600 | K12: =SUMIFS(Serie_horaria!$E$6:$E$20843,Serie_horaria!$A$6:$A$20843,">="&B12,Serie_horaria!$A$6:$A$20843,"<="&C12)*3600 | L12: =I12-J12 | M12: 141725.36 | N12: =M12/L12 | O12: 7822.2029 | P12: 42291.294 | Q12: =SUMIFS(Serie_horaria!$F$6:$F$20843,Serie_horaria!$A$6:$A$20843,">="&B12,Serie_horaria!$A$6:$A$20843,"<="&C12)
A13: 8 | B13: 43511.542 | C13: 43516.208 | D13: 48.4 | E13: 97.6 | F13: =0.307*D13+0.693*E13 | G13: 30.6 | H13: 20.389 | I13: =SUMIFS(Serie_horaria!$B$6:$B$20843,Serie_horaria!$A$6:$A$20843,">="&B13,Serie_horaria!$A$6:$A$20843,"<="&C13)*3600 | J13: =SUMIFS(Serie_horaria!$D$6:$D$20843,Serie_horaria!$A$6:$A$20843,">="&B13,Serie_horaria!$A$6:$A$20843,"<="&C13)*3600 | K13: =SUMIFS(Serie_horaria!$E$6:$E$20843,Serie_horaria!$A$6:$A$20843,">="&B13,Serie_horaria!$A$6:$A$20843,"<="&C13)*3600 | L13: =I13-J13 | M13: 1336334.2 | N13: =M13/L13 | O13: 93138.584 | P13: 86449.676 | Q13: =SUMIFS(Serie_horaria!$F$6:$F$20843,Serie_horaria!$A$6:$A$20843,">="&B13,Serie_horaria!$A$6:$A$20843,"<="&C13)
A14: 9 | B14: 43521.625 | C14: 43525.542 | D14: 57 | E14: 108.8 | F14: =0.307*D14+0.693*E14 | G14: 23 | H14: 11.792 | I14: =SUMIFS(Serie_horaria!$B$6:$B$20843,Serie_horaria!$A$6:$A$20843,">="&B14,Serie_horaria!$A$6:$A$20843,"<="&C14)*3600 | J14: =SUMIFS(Serie_horaria!$D$6:$D$20843,Serie_horaria!$A$6:$A$20843,">="&B14,Serie_horaria!$A$6:$A$20843,"<="&C14)*3600 | K14: =SUMIFS(Serie_horaria!$E$6:$E$20843,Serie_horaria!$A$6:$A$20843,">="&B14,Serie_horaria!$A$6:$A$20843,"<="&C14)*3600 | L14: =I14-J14 | M14: 1725171.3 | N14: =M14/L14 | O14: 98784.786 | P14: 41829.577 | Q14: =SUMIFS(Serie_horaria!$F$6:$F$20843,Serie_horaria!$A$6:$A$20843,">="&B14,Serie_horaria!$A$6:$A$20843,"<="&C14)
A15: 10 | B15: 43541.208 | C15: 43543.667 | D15: 14.4 | E15: 30.8 | F15: =0.307*D15+0.693*E15 | G15: 12.6 | H15: 10.618 | I15: =SUMIFS(Serie_horaria!$B$6:$B$20843,Serie_horaria!$A$6:$A$20843,">="&B15,Serie_horaria!$A$6:$A$20843,"<="&C15)*3600 | J15: =SUMIFS(Serie_horaria!$D$6:$D$20843,Serie_horaria!$A$6:$A$20843,">="&B15,Serie_horaria!$A$6:$A$20843,"<="&C15)*3600 | K15: =SUMIFS(Serie_horaria!$E$6:$E$20843,Serie_horaria!$A$6:$A$20843,">="&B15,Serie_horaria!$A$6:$A$20843,"<="&C15)*3600 | L15: =I15-J15 | M15: 56645.16 | N15: =M15/L15 | O15: 2920.9314 | P15: 35354.299 | Q15: =SUMIFS(Serie_horaria!$F$6:$F$20843,Serie_horaria!$A$6:$A$20843,">="&B15,Serie_horaria!$A$6:$A$20843,"<="&C15)
A16: 11 | B16: 43650.5 | C16: 43654.292 | D16: 62.8 | E16: 79 | F16: =0.307*D16+0.693*E16 | G16: 11.8 | H16: 20.95 | I16: =SUMIFS(Serie_horaria!$B$6:$B$20843,Serie_horaria!$A$6:$A$20843,">="&B16,Serie_horaria!$A$6:$A$20843,"<="&C16)*3600 | J16: =SUMIFS(Serie_horaria!$D$6:$D$20843,Serie_horaria!$A$6:$A$20843,">="&B16,Serie_horaria!$A$6:$A$20843,"<="&C16)*3600 | K16: =SUMIFS(Serie_horaria!$E$6:$E$20843,Serie_horaria!$A$6:$A$20843,">="&B16,Serie_horaria!$A$6:$A$20843,"<="&C16)*3600 | L16: =I16-J16 | M16: 997495.1 | N16: =M16/L16 | O16: 40884.592 | P16: 63450.887 | Q16: =SUMIFS(Serie_horaria!$F$6:$F$20843,Serie_horaria!$A$6:$A$20843,">="&B16,Serie_horaria!$A$6:$A$20843,"<="&C16)
A17: 12 | B17: 43829.375 | C17: 43830.333 | D17: 0 | E17: 34.2 | F17: =0.307*D17+0.693*E17 | G17: 32.8 | H17: 13.149 | I17: =SUMIFS(Serie_horaria!$B$6:$B$20843,Serie_horaria!$A$6:$A$20843,">="&B17,Serie_horaria!$A$6:$A$20843,"<="&C17)*3600 | J17: =SUMIFS(Serie_horaria!$D$6:$D$20843,Serie_horaria!$A$6:$A$20843,">="&B17,Serie_horaria!$A$6:$A$20843,"<="&C17)*3600 | K17: =SUMIFS(Serie_horaria!$E$6:$E$20843,Serie_horaria!$A$6:$A$20843,">="&B17,Serie_horaria!$A$6:$A$20843,"<="&C17)*3600 | L17: =I17-J17 | M17: 62527.378 | N17: =M17/L17 | O17: 5955.5812 | P17: 10157.349 | Q17: =SUMIFS(Serie_horaria!$F$6:$F$20843,Serie_horaria!$A$6:$A$20843,">="&B17,Serie_horaria!$A$6:$A$20843,"<="&C17)
... A22: 17 | B22: 43881.375 | C22: 43883.417 | D22: 68 | E22: 64.6 | F22: =0.307*D22+0.693*E22 | G22: 43 | H22: 21.362 | I22: =SUMIFS(Serie_horaria!$B$6:$B$20843,Serie_horaria!$A$6:$A$20843,">="&B22,Serie_horaria!$A$6:$A$20843,"<="&C22)*3600 | J22: =SUMIFS(Serie_horaria!$D$6:$D$20843,Serie_horaria!$A$6:$A$20843,">="&B22,Serie_horaria!$A$6:$A$20843,"<="&C22)*3600 | K22: =SUMIFS(Serie_horaria!$E$6:$E$20843,Serie_horaria!$A$6:$A$20843,">="&B22,Serie_horaria!$A$6:$A$20843,"<="&C22)*3600 | L22: =I22-J22 | M22: 734469.29 | N22: =M22/L22 | O22: 62732.823 | P22: 36170.302 | Q22: =SUMIFS(Serie_horaria!$F$6:$F$20843,Serie_horaria!$A$6:$A$20843,">="&B22,Serie_horaria!$A$6:$A$20843,"<="&C22)
A23: Total | I23: =SUM(I6:I22) | J23: =SUM(J6:J22) | L23: =SUM(L6:L22) | M23: =SUM(M6:M22) | Q23: =SUM(Q6:Q22)

Sheet Volume
A1: Escoamento direto: SCS-CN contra o medido
A2: Mostra quanto o SCS-CN (CN-I, lambda = 0,05 com S convertido) erra a água de cada evento.
A4: Evento | B4: Escoamento direto medido V_dir (m³) | C4: Escoamento direto do SCS-CN V_SCS (m³) | D4: Razão V_SCS / V_dir | E4: Erro (%) | F4: Erro absoluto (%) | G4: Dentro de fator 2?
B5: da aba Eventos | C5: da aba Eventos (rasters) | D5: = V_SCS / V_dir | E5: = (razão - 1) * 100 | F5: = |erro| | G5: sim se a razão está entre 0,5 e 2
A6: =Eventos!A6 | B6: =Eventos!L6 | C6: =Eventos!M6 | D6: =C6/B6 | E6: =(D6-1)*100 | F6: =ABS(E6) | G6: =IF(AND(D6>=0.5,D6<=2),"sim","não")
A7: =Eventos!A7 | B7: =Eventos!L7 | C7: =Eventos!M7 | D7: =C7/B7 | E7: =(D7-1)*100 | F7: =ABS(E7) | G7: =IF(AND(D7>=0.5,D7<=2),"sim","não")
A8: =Eventos!A8 | B8: =Eventos!L8 | C8: =Eventos!M8 | D8: =C8/B8 | E8: =(D8-1)*100 | F8: =ABS(E8) | G8: =IF(AND(D8>=0.5,D8<=2),"sim","não")
A9: =Eventos!A9 | B9: =Eventos!L9 | C9: =Eventos!M9 | D9: =C9/B9 | E9: =(D9-1)*100 | F9: =ABS(E9) | G9: =IF(AND(D9>=0.5,D9<=2),"sim","não")
A10: =Eventos!A10 | B10: =Eventos!L10 | C10: =Eventos!M10 | D10: =C10/B10 | E10: =(D10-1)*100 | F10: =ABS(E10) | G10: =IF(AND(D10>=0.5,D10<=2),"sim","não")
A11: =Eventos!A11 | B11: =Eventos!L11 | C11: =Eventos!M11 | D11: =C11/B11 | E11: =(D11-1)*100 | F11: =ABS(E11) | G11: =IF(AND(D11>=0.5,D11<=2),"sim","não")
A12: =Eventos!A12 | B12: =Eventos!L12 | C12: =Eventos!M12 | D12: =C12/B12 | E12: =(D12-1)*100 | F12: =ABS(E12) | G12: =IF(AND(D12>=0.5,D12<=2),"sim","não")
A13: =Eventos!A13 | B13: =Eventos!L13 | C13: =Eventos!M13 | D13: =C13/B13 | E13: =(D13-1)*100 | F13: =ABS(E13) | G13: =IF(AND(D13>=0.5,D13<=2),"sim","não")
A14: =Eventos!A14 | B14: =Eventos!L14 | C14: =Eventos!M14 | D14: =C14/B14 | E14: =(D14-1)*100 | F14: =ABS(E14) | G14: =IF(AND(D14>=0.5,D14<=2),"sim","não")
A15: =Eventos!A15 | B15: =Eventos!L15 | C15: =Eventos!M15 | D15: =C15/B15 | E15: =(D15-1)*100 | F15: =ABS(E15) | G15: =IF(AND(D15>=0.5,D15<=2),"sim","não")
A16: =Eventos!A16 | B16: =Eventos!L16 | C16: =Eventos!M16 | D16: =C16/B16 | E16: =(D16-1)*100 | F16: =ABS(E16) | G16: =IF(AND(D16>=0.5,D16<=2),"sim","não")
A17: =Eventos!A17 | B17: =Eventos!L17 | C17: =Eventos!M17 | D17: =C17/B17 | E17: =(D17-1)*100 | F17: =ABS(E17) | G17: =IF(AND(D17>=0.5,D17<=2),"sim","não")
... A22: =Eventos!A22 | B22: =Eventos!L22 | C22: =Eventos!M22 | D22: =C22/B22 | E22: =(D22-1)*100 | F22: =ABS(E22) | G22: =IF(AND(D22>=0.5,D22<=2),"sim","não")
A25: Viés do total (%) | D25: =(SUM(C6:C22)/SUM(B6:B22)-1)*100
A26: Erro médio absoluto por evento (%) | D26: =AVERAGE(F6:F22)
A27: Erro mediano por evento (%) | D27: =MEDIAN(F6:F22)
A28: Razão mediana | D28: =MEDIAN(D6:D22)
A29: Eventos dentro de fator 2 (%) | D29: =COUNTIF(G6:G22,"sim")/17*100
A30: NSE do volume | D30: =1-SUMXMY2(C6:C22,B6:B22)/DEVSQ(B6:B22)

Sheet MC
A1: Modelo Calculado (MC): SY = c * soma(E_unit), água calculada pelo SCS-CN
A2: x = soma de E_unit sobre os 153.855 pixels, com o escoamento direto do SCS-CN (só chuva). É a previsão.
A4: Evento | B4: Sedimento medido (t) | C4: x = soma de E_unit no MC (índice) | D4: ln(medido) | E4: ln(x) | F4: ln(medido) - ln(x) | G4: Simulado no ajuste (t) | H4: Erro no ajuste (%) | I4: c sem este evento (validação cruzada) | J4: Simulado na validação cruzada (t) | K4: Erro na validação cruzada (%) | L4: Erro absoluto (%) | M4: Razão simulado / medido | N4: Dentro de fator 2? | O4: ln(simulado) | P4: Posição do medido (1 = menor) | Q4: Posição do simulado (1 = menor)
B5: da aba Eventos | C5: da aba Eventos | D5: = LN(medido) | E5: = LN(x) | F5: = D - E (o c ótimo é a média desta coluna, em exp) | G5: = c (com os 17 eventos) * x | H5: = (simulado / medido - 1) * 100 | I5: = EXP(média de F nos outros 16 eventos) | J5: = c sem este evento * x | K5: = (simulado / medido - 1) * 100 | L5: = |erro na validação cruzada| | M5: = simulado na validação cruzada / medido | N5: sim se a razão está entre 0,5 e 2 | O5: = LN(simulado na validação cruzada); usado no NSE em log | P5: ranking, para o Spearman | Q5: ranking, para o Spearman
A6: =Eventos!A6 | B6: =Eventos!Q6 | C6: =Eventos!O6 | D6: =LN(B6) | E6: =LN(C6) | F6: =D6-E6 | G6: =$D$26*C6 | H6: =(G6/B6-1)*100 | I6: =EXP((SUM($F$6:$F$22)-F6)/16) | J6: =I6*C6 | K6: =(J6/B6-1)*100 | L6: =ABS(K6) | M6: =J6/B6 | N6: =IF(AND(M6>=0.5,M6<=2),"sim","não") | O6: =LN(J6) | P6: =RANK(B6,$B$6:$B$22,1)+(COUNTIF($B$6:$B$22,B6)-1)/2 | Q6: =RANK(J6,$J$6:$J$22,1)+(COUNTIF($J$6:$J$22,J6)-1)/2
A7: =Eventos!A7 | B7: =Eventos!Q7 | C7: =Eventos!O7 | D7: =LN(B7) | E7: =LN(C7) | F7: =D7-E7 | G7: =$D$26*C7 | H7: =(G7/B7-1)*100 | I7: =EXP((SUM($F$6:$F$22)-F7)/16) | J7: =I7*C7 | K7: =(J7/B7-1)*100 | L7: =ABS(K7) | M7: =J7/B7 | N7: =IF(AND(M7>=0.5,M7<=2),"sim","não") | O7: =LN(J7) | P7: =RANK(B7,$B$6:$B$22,1)+(COUNTIF($B$6:$B$22,B7)-1)/2 | Q7: =RANK(J7,$J$6:$J$22,1)+(COUNTIF($J$6:$J$22,J7)-1)/2
A8: =Eventos!A8 | B8: =Eventos!Q8 | C8: =Eventos!O8 | D8: =LN(B8) | E8: =LN(C8) | F8: =D8-E8 | G8: =$D$26*C8 | H8: =(G8/B8-1)*100 | I8: =EXP((SUM($F$6:$F$22)-F8)/16) | J8: =I8*C8 | K8: =(J8/B8-1)*100 | L8: =ABS(K8) | M8: =J8/B8 | N8: =IF(AND(M8>=0.5,M8<=2),"sim","não") | O8: =LN(J8) | P8: =RANK(B8,$B$6:$B$22,1)+(COUNTIF($B$6:$B$22,B8)-1)/2 | Q8: =RANK(J8,$J$6:$J$22,1)+(COUNTIF($J$6:$J$22,J8)-1)/2
A9: =Eventos!A9 | B9: =Eventos!Q9 | C9: =Eventos!O9 | D9: =LN(B9) | E9: =LN(C9) | F9: =D9-E9 | G9: =$D$26*C9 | H9: =(G9/B9-1)*100 | I9: =EXP((SUM($F$6:$F$22)-F9)/16) | J9: =I9*C9 | K9: =(J9/B9-1)*100 | L9: =ABS(K9) | M9: =J9/B9 | N9: =IF(AND(M9>=0.5,M9<=2),"sim","não") | O9: =LN(J9) | P9: =RANK(B9,$B$6:$B$22,1)+(COUNTIF($B$6:$B$22,B9)-1)/2 | Q9: =RANK(J9,$J$6:$J$22,1)+(COUNTIF($J$6:$J$22,J9)-1)/2
A10: =Eventos!A10 | B10: =Eventos!Q10 | C10: =Eventos!O10 | D10: =LN(B10) | E10: =LN(C10) | F10: =D10-E10 | G10: =$D$26*C10 | H10: =(G10/B10-1)*100 | I10: =EXP((SUM($F$6:$F$22)-F10)/16) | J10: =I10*C10 | K10: =(J10/B10-1)*100 | L10: =ABS(K10) | M10: =J10/B10 | N10: =IF(AND(M10>=0.5,M10<=2),"sim","não") | O10: =LN(J10) | P10: =RANK(B10,$B$6:$B$22,1)+(COUNTIF($B$6:$B$22,B10)-1)/2 | Q10: =RANK(J10,$J$6:$J$22,1)+(COUNTIF($J$6:$J$22,J10)-1)/2
A11: =Eventos!A11 | B11: =Eventos!Q11 | C11: =Eventos!O11 | D11: =LN(B11) | E11: =LN(C11) | F11: =D11-E11 | G11: =$D$26*C11 | H11: =(G11/B11-1)*100 | I11: =EXP((SUM($F$6:$F$22)-F11)/16) | J11: =I11*C11 | K11: =(J11/B11-1)*100 | L11: =ABS(K11) | M11: =J11/B11 | N11: =IF(AND(M11>=0.5,M11<=2),"sim","não") | O11: =LN(J11) | P11: =RANK(B11,$B$6:$B$22,1)+(COUNTIF($B$6:$B$22,B11)-1)/2 | Q11: =RANK(J11,$J$6:$J$22,1)+(COUNTIF($J$6:$J$22,J11)-1)/2
A12: =Eventos!A12 | B12: =Eventos!Q12 | C12: =Eventos!O12 | D12: =LN(B12) | E12: =LN(C12) | F12: =D12-E12 | G12: =$D$26*C12 | H12: =(G12/B12-1)*100 | I12: =EXP((SUM($F$6:$F$22)-F12)/16) | J12: =I12*C12 | K12: =(J12/B12-1)*100 | L12: =ABS(K12) | M12: =J12/B12 | N12: =IF(AND(M12>=0.5,M12<=2),"sim","não") | O12: =LN(J12) | P12: =RANK(B12,$B$6:$B$22,1)+(COUNTIF($B$6:$B$22,B12)-1)/2 | Q12: =RANK(J12,$J$6:$J$22,1)+(COUNTIF($J$6:$J$22,J12)-1)/2
A13: =Eventos!A13 | B13: =Eventos!Q13 | C13: =Eventos!O13 | D13: =LN(B13) | E13: =LN(C13) | F13: =D13-E13 | G13: =$D$26*C13 | H13: =(G13/B13-1)*100 | I13: =EXP((SUM($F$6:$F$22)-F13)/16) | J13: =I13*C13 | K13: =(J13/B13-1)*100 | L13: =ABS(K13) | M13: =J13/B13 | N13: =IF(AND(M13>=0.5,M13<=2),"sim","não") | O13: =LN(J13) | P13: =RANK(B13,$B$6:$B$22,1)+(COUNTIF($B$6:$B$22,B13)-1)/2 | Q13: =RANK(J13,$J$6:$J$22,1)+(COUNTIF($J$6:$J$22,J13)-1)/2
A14: =Eventos!A14 | B14: =Eventos!Q14 | C14: =Eventos!O14 | D14: =LN(B14) | E14: =LN(C14) | F14: =D14-E14 | G14: =$D$26*C14 | H14: =(G14/B14-1)*100 | I14: =EXP((SUM($F$6:$F$22)-F14)/16) | J14: =I14*C14 | K14: =(J14/B14-1)*100 | L14: =ABS(K14) | M14: =J14/B14 | N14: =IF(AND(M14>=0.5,M14<=2),"sim","não") | O14: =LN(J14) | P14: =RANK(B14,$B$6:$B$22,1)+(COUNTIF($B$6:$B$22,B14)-1)/2 | Q14: =RANK(J14,$J$6:$J$22,1)+(COUNTIF($J$6:$J$22,J14)-1)/2
A15: =Eventos!A15 | B15: =Eventos!Q15 | C15: =Eventos!O15 | D15: =LN(B15) | E15: =LN(C15) | F15: =D15-E15 | G15: =$D$26*C15 | H15: =(G15/B15-1)*100 | I15: =EXP((SUM($F$6:$F$22)-F15)/16) | J15: =I15*C15 | K15: =(J15/B15-1)*100 | L15: =ABS(K15) | M15: =J15/B15 | N15: =IF(AND(M15>=0.5,M15<=2),"sim","não") | O15: =LN(J15) | P15: =RANK(B15,$B$6:$B$22,1)+(COUNTIF($B$6:$B$22,B15)-1)/2 | Q15: =RANK(J15,$J$6:$J$22,1)+(COUNTIF($J$6:$J$22,J15)-1)/2
A16: =Eventos!A16 | B16: =Eventos!Q16 | C16: =Eventos!O16 | D16: =LN(B16) | E16: =LN(C16) | F16: =D16-E16 | G16: =$D$26*C16 | H16: =(G16/B16-1)*100 | I16: =EXP((SUM($F$6:$F$22)-F16)/16) | J16: =I16*C16 | K16: =(J16/B16-1)*100 | L16: =ABS(K16) | M16: =J16/B16 | N16: =IF(AND(M16>=0.5,M16<=2),"sim","não") | O16: =LN(J16) | P16: =RANK(B16,$B$6:$B$22,1)+(COUNTIF($B$6:$B$22,B16)-1)/2 | Q16: =RANK(J16,$J$6:$J$22,1)+(COUNTIF($J$6:$J$22,J16)-1)/2
A17: =Eventos!A17 | B17: =Eventos!Q17 | C17: =Eventos!O17 | D17: =LN(B17) | E17: =LN(C17) | F17: =D17-E17 | G17: =$D$26*C17 | H17: =(G17/B17-1)*100 | I17: =EXP((SUM($F$6:$F$22)-F17)/16) | J17: =I17*C17 | K17: =(J17/B17-1)*100 | L17: =ABS(K17) | M17: =J17/B17 | N17: =IF(AND(M17>=0.5,M17<=2),"sim","não") | O17: =LN(J17) | P17: =RANK(B17,$B$6:$B$22,1)+(COUNTIF($B$6:$B$22,B17)-1)/2 | Q17: =RANK(J17,$J$6:$J$22,1)+(COUNTIF($J$6:$J$22,J17)-1)/2
... A22: =Eventos!A22 | B22: =Eventos!Q22 | C22: =Eventos!O22 | D22: =LN(B22) | E22: =LN(C22) | F22: =D22-E22 | G22: =$D$26*C22 | H22: =(G22/B22-1)*100 | I22: =EXP((SUM($F$6:$F$22)-F22)/16) | J22: =I22*C22 | K22: =(J22/B22-1)*100 | L22: =ABS(K22) | M22: =J22/B22 | N22: =IF(AND(M22>=0.5,M22<=2),"sim","não") | O22: =LN(J22) | P22: =RANK(B22,$B$6:$B$22,1)+(COUNTIF($B$6:$B$22,B22)-1)/2 | Q22: =RANK(J22,$J$6:$J$22,1)+(COUNTIF($J$6:$J$22,J22)-1)/2
A25: Resultados
A26: c calibrado com os 17 eventos (t por unidade de E_unit) | D26: =EXP(AVERAGE(F6:F22))
A27: Erro mediano na validação cruzada (%) | D27: =MEDIAN(L6:L22)
A28: Eventos dentro de fator 2 (%) | D28: =COUNTIF(N6:N22,"sim")/17*100
A29: NSE em escala log (validação cruzada) | D29: =1-SUMXMY2(O6:O22,D6:D22)/DEVSQ(D6:D22)
A30: NSE linear (validação cruzada; secundário) | D30: =1-SUMXMY2(J6:J22,B6:B22)/DEVSQ(B6:B22)
A31: Spearman (validação cruzada) | D31: =CORREL(P6:P22,Q6:Q22)

Sheet MFM
A1: Modelo Forçado ao Medido (MFM): SY = c * soma(E_unit), água medida
A2: x = soma de E_unit com o escoamento direto medido distribuído pelo padrão do SCS-CN. Não é previsão: mostra o desempenho com a água certa.
A4: Evento | B4: Sedimento medido (t) | C4: x = soma de E_unit no MFM (índice) | D4: ln(medido) | E4: ln(x) | F4: ln(medido) - ln(x) | G4: Simulado no ajuste (t) | H4: Erro no ajuste (%) | I4: c sem este evento (validação cruzada) | J4: Simulado na validação cruzada (t) | K4: Erro na validação cruzada (%) | L4: Erro absoluto (%) | M4: Razão simulado / medido | N4: Dentro de fator 2? | O4: ln(simulado) | P4: Posição do medido (1 = menor) | Q4: Posição do simulado (1 = menor)
B5: da aba Eventos | C5: da aba Eventos | D5: = LN(medido) | E5: = LN(x) | F5: = D - E (o c ótimo é a média desta coluna, em exp) | G5: = c (com os 17 eventos) * x | H5: = (simulado / medido - 1) * 100 | I5: = EXP(média de F nos outros 16 eventos) | J5: = c sem este evento * x | K5: = (simulado / medido - 1) * 100 | L5: = |erro na validação cruzada| | M5: = simulado na validação cruzada / medido | N5: sim se a razão está entre 0,5 e 2 | O5: = LN(simulado na validação cruzada); usado no NSE em log | P5: ranking, para o Spearman | Q5: ranking, para o Spearman
A6: =Eventos!A6 | B6: =Eventos!Q6 | C6: =Eventos!P6 | D6: =LN(B6) | E6: =LN(C6) | F6: =D6-E6 | G6: =$D$26*C6 | H6: =(G6/B6-1)*100 | I6: =EXP((SUM($F$6:$F$22)-F6)/16) | J6: =I6*C6 | K6: =(J6/B6-1)*100 | L6: =ABS(K6) | M6: =J6/B6 | N6: =IF(AND(M6>=0.5,M6<=2),"sim","não") | O6: =LN(J6) | P6: =RANK(B6,$B$6:$B$22,1)+(COUNTIF($B$6:$B$22,B6)-1)/2 | Q6: =RANK(J6,$J$6:$J$22,1)+(COUNTIF($J$6:$J$22,J6)-1)/2
A7: =Eventos!A7 | B7: =Eventos!Q7 | C7: =Eventos!P7 | D7: =LN(B7) | E7: =LN(C7) | F7: =D7-E7 | G7: =$D$26*C7 | H7: =(G7/B7-1)*100 | I7: =EXP((SUM($F$6:$F$22)-F7)/16) | J7: =I7*C7 | K7: =(J7/B7-1)*100 | L7: =ABS(K7) | M7: =J7/B7 | N7: =IF(AND(M7>=0.5,M7<=2),"sim","não") | O7: =LN(J7) | P7: =RANK(B7,$B$6:$B$22,1)+(COUNTIF($B$6:$B$22,B7)-1)/2 | Q7: =RANK(J7,$J$6:$J$22,1)+(COUNTIF($J$6:$J$22,J7)-1)/2
A8: =Eventos!A8 | B8: =Eventos!Q8 | C8: =Eventos!P8 | D8: =LN(B8) | E8: =LN(C8) | F8: =D8-E8 | G8: =$D$26*C8 | H8: =(G8/B8-1)*100 | I8: =EXP((SUM($F$6:$F$22)-F8)/16) | J8: =I8*C8 | K8: =(J8/B8-1)*100 | L8: =ABS(K8) | M8: =J8/B8 | N8: =IF(AND(M8>=0.5,M8<=2),"sim","não") | O8: =LN(J8) | P8: =RANK(B8,$B$6:$B$22,1)+(COUNTIF($B$6:$B$22,B8)-1)/2 | Q8: =RANK(J8,$J$6:$J$22,1)+(COUNTIF($J$6:$J$22,J8)-1)/2
A9: =Eventos!A9 | B9: =Eventos!Q9 | C9: =Eventos!P9 | D9: =LN(B9) | E9: =LN(C9) | F9: =D9-E9 | G9: =$D$26*C9 | H9: =(G9/B9-1)*100 | I9: =EXP((SUM($F$6:$F$22)-F9)/16) | J9: =I9*C9 | K9: =(J9/B9-1)*100 | L9: =ABS(K9) | M9: =J9/B9 | N9: =IF(AND(M9>=0.5,M9<=2),"sim","não") | O9: =LN(J9) | P9: =RANK(B9,$B$6:$B$22,1)+(COUNTIF($B$6:$B$22,B9)-1)/2 | Q9: =RANK(J9,$J$6:$J$22,1)+(COUNTIF($J$6:$J$22,J9)-1)/2
A10: =Eventos!A10 | B10: =Eventos!Q10 | C10: =Eventos!P10 | D10: =LN(B10) | E10: =LN(C10) | F10: =D10-E10 | G10: =$D$26*C10 | H10: =(G10/B10-1)*100 | I10: =EXP((SUM($F$6:$F$22)-F10)/16) | J10: =I10*C10 | K10: =(J10/B10-1)*100 | L10: =ABS(K10) | M10: =J10/B10 | N10: =IF(AND(M10>=0.5,M10<=2),"sim","não") | O10: =LN(J10) | P10: =RANK(B10,$B$6:$B$22,1)+(COUNTIF($B$6:$B$22,B10)-1)/2 | Q10: =RANK(J10,$J$6:$J$22,1)+(COUNTIF($J$6:$J$22,J10)-1)/2
A11: =Eventos!A11 | B11: =Eventos!Q11 | C11: =Eventos!P11 | D11: =LN(B11) | E11: =LN(C11) | F11: =D11-E11 | G11: =$D$26*C11 | H11: =(G11/B11-1)*100 | I11: =EXP((SUM($F$6:$F$22)-F11)/16) | J11: =I11*C11 | K11: =(J11/B11-1)*100 | L11: =ABS(K11) | M11: =J11/B11 | N11: =IF(AND(M11>=0.5,M11<=2),"sim","não") | O11: =LN(J11) | P11: =RANK(B11,$B$6:$B$22,1)+(COUNTIF($B$6:$B$22,B11)-1)/2 | Q11: =RANK(J11,$J$6:$J$22,1)+(COUNTIF($J$6:$J$22,J11)-1)/2
A12: =Eventos!A12 | B12: =Eventos!Q12 | C12: =Eventos!P12 | D12: =LN(B12) | E12: =LN(C12) | F12: =D12-E12 | G12: =$D$26*C12 | H12: =(G12/B12-1)*100 | I12: =EXP((SUM($F$6:$F$22)-F12)/16) | J12: =I12*C12 | K12: =(J12/B12-1)*100 | L12: =ABS(K12) | M12: =J12/B12 | N12: =IF(AND(M12>=0.5,M12<=2),"sim","não") | O12: =LN(J12) | P12: =RANK(B12,$B$6:$B$22,1)+(COUNTIF($B$6:$B$22,B12)-1)/2 | Q12: =RANK(J12,$J$6:$J$22,1)+(COUNTIF($J$6:$J$22,J12)-1)/2
A13: =Eventos!A13 | B13: =Eventos!Q13 | C13: =Eventos!P13 | D13: =LN(B13) | E13: =LN(C13) | F13: =D13-E13 | G13: =$D$26*C13 | H13: =(G13/B13-1)*100 | I13: =EXP((SUM($F$6:$F$22)-F13)/16) | J13: =I13*C13 | K13: =(J13/B13-1)*100 | L13: =ABS(K13) | M13: =J13/B13 | N13: =IF(AND(M13>=0.5,M13<=2),"sim","não") | O13: =LN(J13) | P13: =RANK(B13,$B$6:$B$22,1)+(COUNTIF($B$6:$B$22,B13)-1)/2 | Q13: =RANK(J13,$J$6:$J$22,1)+(COUNTIF($J$6:$J$22,J13)-1)/2
A14: =Eventos!A14 | B14: =Eventos!Q14 | C14: =Eventos!P14 | D14: =LN(B14) | E14: =LN(C14) | F14: =D14-E14 | G14: =$D$26*C14 | H14: =(G14/B14-1)*100 | I14: =EXP((SUM($F$6:$F$22)-F14)/16) | J14: =I14*C14 | K14: =(J14/B14-1)*100 | L14: =ABS(K14) | M14: =J14/B14 | N14: =IF(AND(M14>=0.5,M14<=2),"sim","não") | O14: =LN(J14) | P14: =RANK(B14,$B$6:$B$22,1)+(COUNTIF($B$6:$B$22,B14)-1)/2 | Q14: =RANK(J14,$J$6:$J$22,1)+(COUNTIF($J$6:$J$22,J14)-1)/2
A15: =Eventos!A15 | B15: =Eventos!Q15 | C15: =Eventos!P15 | D15: =LN(B15) | E15: =LN(C15) | F15: =D15-E15 | G15: =$D$26*C15 | H15: =(G15/B15-1)*100 | I15: =EXP((SUM($F$6:$F$22)-F15)/16) | J15: =I15*C15 | K15: =(J15/B15-1)*100 | L15: =ABS(K15) | M15: =J15/B15 | N15: =IF(AND(M15>=0.5,M15<=2),"sim","não") | O15: =LN(J15) | P15: =RANK(B15,$B$6:$B$22,1)+(COUNTIF($B$6:$B$22,B15)-1)/2 | Q15: =RANK(J15,$J$6:$J$22,1)+(COUNTIF($J$6:$J$22,J15)-1)/2
A16: =Eventos!A16 | B16: =Eventos!Q16 | C16: =Eventos!P16 | D16: =LN(B16) | E16: =LN(C16) | F16: =D16-E16 | G16: =$D$26*C16 | H16: =(G16/B16-1)*100 | I16: =EXP((SUM($F$6:$F$22)-F16)/16) | J16: =I16*C16 | K16: =(J16/B16-1)*100 | L16: =ABS(K16) | M16: =J16/B16 | N16: =IF(AND(M16>=0.5,M16<=2),"sim","não") | O16: =LN(J16) | P16: =RANK(B16,$B$6:$B$22,1)+(COUNTIF($B$6:$B$22,B16)-1)/2 | Q16: =RANK(J16,$J$6:$J$22,1)+(COUNTIF($J$6:$J$22,J16)-1)/2
A17: =Eventos!A17 | B17: =Eventos!Q17 | C17: =Eventos!P17 | D17: =LN(B17) | E17: =LN(C17) | F17: =D17-E17 | G17: =$D$26*C17 | H17: =(G17/B17-1)*100 | I17: =EXP((SUM($F$6:$F$22)-F17)/16) | J17: =I17*C17 | K17: =(J17/B17-1)*100 | L17: =ABS(K17) | M17: =J17/B17 | N17: =IF(AND(M17>=0.5,M17<=2),"sim","não") | O17: =LN(J17) | P17: =RANK(B17,$B$6:$B$22,1)+(COUNTIF($B$6:$B$22,B17)-1)/2 | Q17: =RANK(J17,$J$6:$J$22,1)+(COUNTIF($J$6:$J$22,J17)-1)/2
... A22: =Eventos!A22 | B22: =Eventos!Q22 | C22: =Eventos!P22 | D22: =LN(B22) | E22: =LN(C22) | F22: =D22-E22 | G22: =$D$26*C22 | H22: =(G22/B22-1)*100 | I22: =EXP((SUM($F$6:$F$22)-F22)/16) | J22: =I22*C22 | K22: =(J22/B22-1)*100 | L22: =ABS(K22) | M22: =J22/B22 | N22: =IF(AND(M22>=0.5,M22<=2),"sim","não") | O22: =LN(J22) | P22: =RANK(B22,$B$6:$B$22,1)+(COUNTIF($B$6:$B$22,B22)-1)/2 | Q22: =RANK(J22,$J$6:$J$22,1)+(COUNTIF($J$6:$J$22,J22)-1)/2
A25: Resultados
A26: c calibrado com os 17 eventos (t por unidade de E_unit) | D26: =EXP(AVERAGE(F6:F22))
A27: Erro mediano na validação cruzada (%) | D27: =MEDIAN(L6:L22)
A28: Eventos dentro de fator 2 (%) | D28: =COUNTIF(N6:N22,"sim")/17*100
A29: NSE em escala log (validação cruzada) | D29: =1-SUMXMY2(O6:O22,D6:D22)/DEVSQ(D6:D22)
A30: NSE linear (validação cruzada; secundário) | D30: =1-SUMXMY2(J6:J22,B6:B22)/DEVSQ(B6:B22)
A31: Spearman (validação cruzada) | D31: =CORREL(P6:P22,Q6:Q22)

Sheet Regra_chuva
A1: Regra simples: SY = c * R (chuva do evento)
A2: Referência para o MC: usa só a chuva, como o MC.
A4: Evento | B4: Sedimento medido (t) | C4: x = chuva do evento R (mm) | D4: ln(medido) | E4: ln(x) | F4: ln(medido) - ln(x) | G4: Simulado no ajuste (t) | H4: Erro no ajuste (%) | I4: c sem este evento (validação cruzada) | J4: Simulado na validação cruzada (t) | K4: Erro na validação cruzada (%) | L4: Erro absoluto (%) | M4: Razão simulado / medido | N4: Dentro de fator 2? | O4: ln(simulado) | P4: Posição do medido (1 = menor) | Q4: Posição do simulado (1 = menor)
B5: da aba Eventos | C5: da aba Eventos | D5: = LN(medido) | E5: = LN(x) | F5: = D - E (o c ótimo é a média desta coluna, em exp) | G5: = c (com os 17 eventos) * x | H5: = (simulado / medido - 1) * 100 | I5: = EXP(média de F nos outros 16 eventos) | J5: = c sem este evento * x | K5: = (simulado / medido - 1) * 100 | L5: = |erro na validação cruzada| | M5: = simulado na validação cruzada / medido | N5: sim se a razão está entre 0,5 e 2 | O5: = LN(simulado na validação cruzada); usado no NSE em log | P5: ranking, para o Spearman | Q5: ranking, para o Spearman
A6: =Eventos!A6 | B6: =Eventos!Q6 | C6: =Eventos!F6 | D6: =LN(B6) | E6: =LN(C6) | F6: =D6-E6 | G6: =$D$26*C6 | H6: =(G6/B6-1)*100 | I6: =EXP((SUM($F$6:$F$22)-F6)/16) | J6: =I6*C6 | K6: =(J6/B6-1)*100 | L6: =ABS(K6) | M6: =J6/B6 | N6: =IF(AND(M6>=0.5,M6<=2),"sim","não") | O6: =LN(J6) | P6: =RANK(B6,$B$6:$B$22,1)+(COUNTIF($B$6:$B$22,B6)-1)/2 | Q6: =RANK(J6,$J$6:$J$22,1)+(COUNTIF($J$6:$J$22,J6)-1)/2
A7: =Eventos!A7 | B7: =Eventos!Q7 | C7: =Eventos!F7 | D7: =LN(B7) | E7: =LN(C7) | F7: =D7-E7 | G7: =$D$26*C7 | H7: =(G7/B7-1)*100 | I7: =EXP((SUM($F$6:$F$22)-F7)/16) | J7: =I7*C7 | K7: =(J7/B7-1)*100 | L7: =ABS(K7) | M7: =J7/B7 | N7: =IF(AND(M7>=0.5,M7<=2),"sim","não") | O7: =LN(J7) | P7: =RANK(B7,$B$6:$B$22,1)+(COUNTIF($B$6:$B$22,B7)-1)/2 | Q7: =RANK(J7,$J$6:$J$22,1)+(COUNTIF($J$6:$J$22,J7)-1)/2
A8: =Eventos!A8 | B8: =Eventos!Q8 | C8: =Eventos!F8 | D8: =LN(B8) | E8: =LN(C8) | F8: =D8-E8 | G8: =$D$26*C8 | H8: =(G8/B8-1)*100 | I8: =EXP((SUM($F$6:$F$22)-F8)/16) | J8: =I8*C8 | K8: =(J8/B8-1)*100 | L8: =ABS(K8) | M8: =J8/B8 | N8: =IF(AND(M8>=0.5,M8<=2),"sim","não") | O8: =LN(J8) | P8: =RANK(B8,$B$6:$B$22,1)+(COUNTIF($B$6:$B$22,B8)-1)/2 | Q8: =RANK(J8,$J$6:$J$22,1)+(COUNTIF($J$6:$J$22,J8)-1)/2
A9: =Eventos!A9 | B9: =Eventos!Q9 | C9: =Eventos!F9 | D9: =LN(B9) | E9: =LN(C9) | F9: =D9-E9 | G9: =$D$26*C9 | H9: =(G9/B9-1)*100 | I9: =EXP((SUM($F$6:$F$22)-F9)/16) | J9: =I9*C9 | K9: =(J9/B9-1)*100 | L9: =ABS(K9) | M9: =J9/B9 | N9: =IF(AND(M9>=0.5,M9<=2),"sim","não") | O9: =LN(J9) | P9: =RANK(B9,$B$6:$B$22,1)+(COUNTIF($B$6:$B$22,B9)-1)/2 | Q9: =RANK(J9,$J$6:$J$22,1)+(COUNTIF($J$6:$J$22,J9)-1)/2
A10: =Eventos!A10 | B10: =Eventos!Q10 | C10: =Eventos!F10 | D10: =LN(B10) | E10: =LN(C10) | F10: =D10-E10 | G10: =$D$26*C10 | H10: =(G10/B10-1)*100 | I10: =EXP((SUM($F$6:$F$22)-F10)/16) | J10: =I10*C10 | K10: =(J10/B10-1)*100 | L10: =ABS(K10) | M10: =J10/B10 | N10: =IF(AND(M10>=0.5,M10<=2),"sim","não") | O10: =LN(J10) | P10: =RANK(B10,$B$6:$B$22,1)+(COUNTIF($B$6:$B$22,B10)-1)/2 | Q10: =RANK(J10,$J$6:$J$22,1)+(COUNTIF($J$6:$J$22,J10)-1)/2
A11: =Eventos!A11 | B11: =Eventos!Q11 | C11: =Eventos!F11 | D11: =LN(B11) | E11: =LN(C11) | F11: =D11-E11 | G11: =$D$26*C11 | H11: =(G11/B11-1)*100 | I11: =EXP((SUM($F$6:$F$22)-F11)/16) | J11: =I11*C11 | K11: =(J11/B11-1)*100 | L11: =ABS(K11) | M11: =J11/B11 | N11: =IF(AND(M11>=0.5,M11<=2),"sim","não") | O11: =LN(J11) | P11: =RANK(B11,$B$6:$B$22,1)+(COUNTIF($B$6:$B$22,B11)-1)/2 | Q11: =RANK(J11,$J$6:$J$22,1)+(COUNTIF($J$6:$J$22,J11)-1)/2
A12: =Eventos!A12 | B12: =Eventos!Q12 | C12: =Eventos!F12 | D12: =LN(B12) | E12: =LN(C12) | F12: =D12-E12 | G12: =$D$26*C12 | H12: =(G12/B12-1)*100 | I12: =EXP((SUM($F$6:$F$22)-F12)/16) | J12: =I12*C12 | K12: =(J12/B12-1)*100 | L12: =ABS(K12) | M12: =J12/B12 | N12: =IF(AND(M12>=0.5,M12<=2),"sim","não") | O12: =LN(J12) | P12: =RANK(B12,$B$6:$B$22,1)+(COUNTIF($B$6:$B$22,B12)-1)/2 | Q12: =RANK(J12,$J$6:$J$22,1)+(COUNTIF($J$6:$J$22,J12)-1)/2
A13: =Eventos!A13 | B13: =Eventos!Q13 | C13: =Eventos!F13 | D13: =LN(B13) | E13: =LN(C13) | F13: =D13-E13 | G13: =$D$26*C13 | H13: =(G13/B13-1)*100 | I13: =EXP((SUM($F$6:$F$22)-F13)/16) | J13: =I13*C13 | K13: =(J13/B13-1)*100 | L13: =ABS(K13) | M13: =J13/B13 | N13: =IF(AND(M13>=0.5,M13<=2),"sim","não") | O13: =LN(J13) | P13: =RANK(B13,$B$6:$B$22,1)+(COUNTIF($B$6:$B$22,B13)-1)/2 | Q13: =RANK(J13,$J$6:$J$22,1)+(COUNTIF($J$6:$J$22,J13)-1)/2
A14: =Eventos!A14 | B14: =Eventos!Q14 | C14: =Eventos!F14 | D14: =LN(B14) | E14: =LN(C14) | F14: =D14-E14 | G14: =$D$26*C14 | H14: =(G14/B14-1)*100 | I14: =EXP((SUM($F$6:$F$22)-F14)/16) | J14: =I14*C14 | K14: =(J14/B14-1)*100 | L14: =ABS(K14) | M14: =J14/B14 | N14: =IF(AND(M14>=0.5,M14<=2),"sim","não") | O14: =LN(J14) | P14: =RANK(B14,$B$6:$B$22,1)+(COUNTIF($B$6:$B$22,B14)-1)/2 | Q14: =RANK(J14,$J$6:$J$22,1)+(COUNTIF($J$6:$J$22,J14)-1)/2
A15: =Eventos!A15 | B15: =Eventos!Q15 | C15: =Eventos!F15 | D15: =LN(B15) | E15: =LN(C15) | F15: =D15-E15 | G15: =$D$26*C15 | H15: =(G15/B15-1)*100 | I15: =EXP((SUM($F$6:$F$22)-F15)/16) | J15: =I15*C15 | K15: =(J15/B15-1)*100 | L15: =ABS(K15) | M15: =J15/B15 | N15: =IF(AND(M15>=0.5,M15<=2),"sim","não") | O15: =LN(J15) | P15: =RANK(B15,$B$6:$B$22,1)+(COUNTIF($B$6:$B$22,B15)-1)/2 | Q15: =RANK(J15,$J$6:$J$22,1)+(COUNTIF($J$6:$J$22,J15)-1)/2
A16: =Eventos!A16 | B16: =Eventos!Q16 | C16: =Eventos!F16 | D16: =LN(B16) | E16: =LN(C16) | F16: =D16-E16 | G16: =$D$26*C16 | H16: =(G16/B16-1)*100 | I16: =EXP((SUM($F$6:$F$22)-F16)/16) | J16: =I16*C16 | K16: =(J16/B16-1)*100 | L16: =ABS(K16) | M16: =J16/B16 | N16: =IF(AND(M16>=0.5,M16<=2),"sim","não") | O16: =LN(J16) | P16: =RANK(B16,$B$6:$B$22,1)+(COUNTIF($B$6:$B$22,B16)-1)/2 | Q16: =RANK(J16,$J$6:$J$22,1)+(COUNTIF($J$6:$J$22,J16)-1)/2
A17: =Eventos!A17 | B17: =Eventos!Q17 | C17: =Eventos!F17 | D17: =LN(B17) | E17: =LN(C17) | F17: =D17-E17 | G17: =$D$26*C17 | H17: =(G17/B17-1)*100 | I17: =EXP((SUM($F$6:$F$22)-F17)/16) | J17: =I17*C17 | K17: =(J17/B17-1)*100 | L17: =ABS(K17) | M17: =J17/B17 | N17: =IF(AND(M17>=0.5,M17<=2),"sim","não") | O17: =LN(J17) | P17: =RANK(B17,$B$6:$B$22,1)+(COUNTIF($B$6:$B$22,B17)-1)/2 | Q17: =RANK(J17,$J$6:$J$22,1)+(COUNTIF($J$6:$J$22,J17)-1)/2
... A22: =Eventos!A22 | B22: =Eventos!Q22 | C22: =Eventos!F22 | D22: =LN(B22) | E22: =LN(C22) | F22: =D22-E22 | G22: =$D$26*C22 | H22: =(G22/B22-1)*100 | I22: =EXP((SUM($F$6:$F$22)-F22)/16) | J22: =I22*C22 | K22: =(J22/B22-1)*100 | L22: =ABS(K22) | M22: =J22/B22 | N22: =IF(AND(M22>=0.5,M22<=2),"sim","não") | O22: =LN(J22) | P22: =RANK(B22,$B$6:$B$22,1)+(COUNTIF($B$6:$B$22,B22)-1)/2 | Q22: =RANK(J22,$J$6:$J$22,1)+(COUNTIF($J$6:$J$22,J22)-1)/2
A25: Resultados
A26: c calibrado com os 17 eventos (t por mm) | D26: =EXP(AVERAGE(F6:F22))
A27: Erro mediano na validação cruzada (%) | D27: =MEDIAN(L6:L22)
A28: Eventos dentro de fator 2 (%) | D28: =COUNTIF(N6:N22,"sim")/17*100
A29: NSE em escala log (validação cruzada) | D29: =1-SUMXMY2(O6:O22,D6:D22)/DEVSQ(D6:D22)
A30: NSE linear (validação cruzada; secundário) | D30: =1-SUMXMY2(J6:J22,B6:B22)/DEVSQ(B6:B22)
A31: Spearman (validação cruzada) | D31: =CORREL(P6:P22,Q6:Q22)

Sheet Regra_Vdir
A1: Regra simples: SY = c * V_dir (escoamento direto medido)
A2: Referência para o MFM: usa a mesma água medida, sem a MUSLE.
A4: Evento | B4: Sedimento medido (t) | C4: x = escoamento direto medido V_dir (m³) | D4: ln(medido) | E4: ln(x) | F4: ln(medido) - ln(x) | G4: Simulado no ajuste (t) | H4: Erro no ajuste (%) | I4: c sem este evento (validação cruzada) | J4: Simulado na validação cruzada (t) | K4: Erro na validação cruzada (%) | L4: Erro absoluto (%) | M4: Razão simulado / medido | N4: Dentro de fator 2? | O4: ln(simulado) | P4: Posição do medido (1 = menor) | Q4: Posição do simulado (1 = menor)
B5: da aba Eventos | C5: da aba Eventos | D5: = LN(medido) | E5: = LN(x) | F5: = D - E (o c ótimo é a média desta coluna, em exp) | G5: = c (com os 17 eventos) * x | H5: = (simulado / medido - 1) * 100 | I5: = EXP(média de F nos outros 16 eventos) | J5: = c sem este evento * x | K5: = (simulado / medido - 1) * 100 | L5: = |erro na validação cruzada| | M5: = simulado na validação cruzada / medido | N5: sim se a razão está entre 0,5 e 2 | O5: = LN(simulado na validação cruzada); usado no NSE em log | P5: ranking, para o Spearman | Q5: ranking, para o Spearman
A6: =Eventos!A6 | B6: =Eventos!Q6 | C6: =Eventos!L6 | D6: =LN(B6) | E6: =LN(C6) | F6: =D6-E6 | G6: =$D$26*C6 | H6: =(G6/B6-1)*100 | I6: =EXP((SUM($F$6:$F$22)-F6)/16) | J6: =I6*C6 | K6: =(J6/B6-1)*100 | L6: =ABS(K6) | M6: =J6/B6 | N6: =IF(AND(M6>=0.5,M6<=2),"sim","não") | O6: =LN(J6) | P6: =RANK(B6,$B$6:$B$22,1)+(COUNTIF($B$6:$B$22,B6)-1)/2 | Q6: =RANK(J6,$J$6:$J$22,1)+(COUNTIF($J$6:$J$22,J6)-1)/2
A7: =Eventos!A7 | B7: =Eventos!Q7 | C7: =Eventos!L7 | D7: =LN(B7) | E7: =LN(C7) | F7: =D7-E7 | G7: =$D$26*C7 | H7: =(G7/B7-1)*100 | I7: =EXP((SUM($F$6:$F$22)-F7)/16) | J7: =I7*C7 | K7: =(J7/B7-1)*100 | L7: =ABS(K7) | M7: =J7/B7 | N7: =IF(AND(M7>=0.5,M7<=2),"sim","não") | O7: =LN(J7) | P7: =RANK(B7,$B$6:$B$22,1)+(COUNTIF($B$6:$B$22,B7)-1)/2 | Q7: =RANK(J7,$J$6:$J$22,1)+(COUNTIF($J$6:$J$22,J7)-1)/2
A8: =Eventos!A8 | B8: =Eventos!Q8 | C8: =Eventos!L8 | D8: =LN(B8) | E8: =LN(C8) | F8: =D8-E8 | G8: =$D$26*C8 | H8: =(G8/B8-1)*100 | I8: =EXP((SUM($F$6:$F$22)-F8)/16) | J8: =I8*C8 | K8: =(J8/B8-1)*100 | L8: =ABS(K8) | M8: =J8/B8 | N8: =IF(AND(M8>=0.5,M8<=2),"sim","não") | O8: =LN(J8) | P8: =RANK(B8,$B$6:$B$22,1)+(COUNTIF($B$6:$B$22,B8)-1)/2 | Q8: =RANK(J8,$J$6:$J$22,1)+(COUNTIF($J$6:$J$22,J8)-1)/2
A9: =Eventos!A9 | B9: =Eventos!Q9 | C9: =Eventos!L9 | D9: =LN(B9) | E9: =LN(C9) | F9: =D9-E9 | G9: =$D$26*C9 | H9: =(G9/B9-1)*100 | I9: =EXP((SUM($F$6:$F$22)-F9)/16) | J9: =I9*C9 | K9: =(J9/B9-1)*100 | L9: =ABS(K9) | M9: =J9/B9 | N9: =IF(AND(M9>=0.5,M9<=2),"sim","não") | O9: =LN(J9) | P9: =RANK(B9,$B$6:$B$22,1)+(COUNTIF($B$6:$B$22,B9)-1)/2 | Q9: =RANK(J9,$J$6:$J$22,1)+(COUNTIF($J$6:$J$22,J9)-1)/2
A10: =Eventos!A10 | B10: =Eventos!Q10 | C10: =Eventos!L10 | D10: =LN(B10) | E10: =LN(C10) | F10: =D10-E10 | G10: =$D$26*C10 | H10: =(G10/B10-1)*100 | I10: =EXP((SUM($F$6:$F$22)-F10)/16) | J10: =I10*C10 | K10: =(J10/B10-1)*100 | L10: =ABS(K10) | M10: =J10/B10 | N10: =IF(AND(M10>=0.5,M10<=2),"sim","não") | O10: =LN(J10) | P10: =RANK(B10,$B$6:$B$22,1)+(COUNTIF($B$6:$B$22,B10)-1)/2 | Q10: =RANK(J10,$J$6:$J$22,1)+(COUNTIF($J$6:$J$22,J10)-1)/2
A11: =Eventos!A11 | B11: =Eventos!Q11 | C11: =Eventos!L11 | D11: =LN(B11) | E11: =LN(C11) | F11: =D11-E11 | G11: =$D$26*C11 | H11: =(G11/B11-1)*100 | I11: =EXP((SUM($F$6:$F$22)-F11)/16) | J11: =I11*C11 | K11: =(J11/B11-1)*100 | L11: =ABS(K11) | M11: =J11/B11 | N11: =IF(AND(M11>=0.5,M11<=2),"sim","não") | O11: =LN(J11) | P11: =RANK(B11,$B$6:$B$22,1)+(COUNTIF($B$6:$B$22,B11)-1)/2 | Q11: =RANK(J11,$J$6:$J$22,1)+(COUNTIF($J$6:$J$22,J11)-1)/2
A12: =Eventos!A12 | B12: =Eventos!Q12 | C12: =Eventos!L12 | D12: =LN(B12) | E12: =LN(C12) | F12: =D12-E12 | G12: =$D$26*C12 | H12: =(G12/B12-1)*100 | I12: =EXP((SUM($F$6:$F$22)-F12)/16) | J12: =I12*C12 | K12: =(J12/B12-1)*100 | L12: =ABS(K12) | M12: =J12/B12 | N12: =IF(AND(M12>=0.5,M12<=2),"sim","não") | O12: =LN(J12) | P12: =RANK(B12,$B$6:$B$22,1)+(COUNTIF($B$6:$B$22,B12)-1)/2 | Q12: =RANK(J12,$J$6:$J$22,1)+(COUNTIF($J$6:$J$22,J12)-1)/2
A13: =Eventos!A13 | B13: =Eventos!Q13 | C13: =Eventos!L13 | D13: =LN(B13) | E13: =LN(C13) | F13: =D13-E13 | G13: =$D$26*C13 | H13: =(G13/B13-1)*100 | I13: =EXP((SUM($F$6:$F$22)-F13)/16) | J13: =I13*C13 | K13: =(J13/B13-1)*100 | L13: =ABS(K13) | M13: =J13/B13 | N13: =IF(AND(M13>=0.5,M13<=2),"sim","não") | O13: =LN(J13) | P13: =RANK(B13,$B$6:$B$22,1)+(COUNTIF($B$6:$B$22,B13)-1)/2 | Q13: =RANK(J13,$J$6:$J$22,1)+(COUNTIF($J$6:$J$22,J13)-1)/2
A14: =Eventos!A14 | B14: =Eventos!Q14 | C14: =Eventos!L14 | D14: =LN(B14) | E14: =LN(C14) | F14: =D14-E14 | G14: =$D$26*C14 | H14: =(G14/B14-1)*100 | I14: =EXP((SUM($F$6:$F$22)-F14)/16) | J14: =I14*C14 | K14: =(J14/B14-1)*100 | L14: =ABS(K14) | M14: =J14/B14 | N14: =IF(AND(M14>=0.5,M14<=2),"sim","não") | O14: =LN(J14) | P14: =RANK(B14,$B$6:$B$22,1)+(COUNTIF($B$6:$B$22,B14)-1)/2 | Q14: =RANK(J14,$J$6:$J$22,1)+(COUNTIF($J$6:$J$22,J14)-1)/2
A15: =Eventos!A15 | B15: =Eventos!Q15 | C15: =Eventos!L15 | D15: =LN(B15) | E15: =LN(C15) | F15: =D15-E15 | G15: =$D$26*C15 | H15: =(G15/B15-1)*100 | I15: =EXP((SUM($F$6:$F$22)-F15)/16) | J15: =I15*C15 | K15: =(J15/B15-1)*100 | L15: =ABS(K15) | M15: =J15/B15 | N15: =IF(AND(M15>=0.5,M15<=2),"sim","não") | O15: =LN(J15) | P15: =RANK(B15,$B$6:$B$22,1)+(COUNTIF($B$6:$B$22,B15)-1)/2 | Q15: =RANK(J15,$J$6:$J$22,1)+(COUNTIF($J$6:$J$22,J15)-1)/2
A16: =Eventos!A16 | B16: =Eventos!Q16 | C16: =Eventos!L16 | D16: =LN(B16) | E16: =LN(C16) | F16: =D16-E16 | G16: =$D$26*C16 | H16: =(G16/B16-1)*100 | I16: =EXP((SUM($F$6:$F$22)-F16)/16) | J16: =I16*C16 | K16: =(J16/B16-1)*100 | L16: =ABS(K16) | M16: =J16/B16 | N16: =IF(AND(M16>=0.5,M16<=2),"sim","não") | O16: =LN(J16) | P16: =RANK(B16,$B$6:$B$22,1)+(COUNTIF($B$6:$B$22,B16)-1)/2 | Q16: =RANK(J16,$J$6:$J$22,1)+(COUNTIF($J$6:$J$22,J16)-1)/2
A17: =Eventos!A17 | B17: =Eventos!Q17 | C17: =Eventos!L17 | D17: =LN(B17) | E17: =LN(C17) | F17: =D17-E17 | G17: =$D$26*C17 | H17: =(G17/B17-1)*100 | I17: =EXP((SUM($F$6:$F$22)-F17)/16) | J17: =I17*C17 | K17: =(J17/B17-1)*100 | L17: =ABS(K17) | M17: =J17/B17 | N17: =IF(AND(M17>=0.5,M17<=2),"sim","não") | O17: =LN(J17) | P17: =RANK(B17,$B$6:$B$22,1)+(COUNTIF($B$6:$B$22,B17)-1)/2 | Q17: =RANK(J17,$J$6:$J$22,1)+(COUNTIF($J$6:$J$22,J17)-1)/2
... A22: =Eventos!A22 | B22: =Eventos!Q22 | C22: =Eventos!L22 | D22: =LN(B22) | E22: =LN(C22) | F22: =D22-E22 | G22: =$D$26*C22 | H22: =(G22/B22-1)*100 | I22: =EXP((SUM($F$6:$F$22)-F22)/16) | J22: =I22*C22 | K22: =(J22/B22-1)*100 | L22: =ABS(K22) | M22: =J22/B22 | N22: =IF(AND(M22>=0.5,M22<=2),"sim","não") | O22: =LN(J22) | P22: =RANK(B22,$B$6:$B$22,1)+(COUNTIF($B$6:$B$22,B22)-1)/2 | Q22: =RANK(J22,$J$6:$J$22,1)+(COUNTIF($J$6:$J$22,J22)-1)/2
A25: Resultados
A26: c calibrado com os 17 eventos (t por m³) | D26: =EXP(AVERAGE(F6:F22))
A27: Erro mediano na validação cruzada (%) | D27: =MEDIAN(L6:L22)
A28: Eventos dentro de fator 2 (%) | D28: =COUNTIF(N6:N22,"sim")/17*100
A29: NSE em escala log (validação cruzada) | D29: =1-SUMXMY2(O6:O22,D6:D22)/DEVSQ(D6:D22)
A30: NSE linear (validação cruzada; secundário) | D30: =1-SUMXMY2(J6:J22,B6:B22)/DEVSQ(B6:B22)
A31: Spearman (validação cruzada) | D31: =CORREL(P6:P22,Q6:Q22)

Sheet Regra_TR
A1: Regra simples: SY = c * TR (volume total medido)
A2: Só para comparação: usa o volume total, com a vazão de base.
A4: Evento | B4: Sedimento medido (t) | C4: x = volume total TR (m³) | D4: ln(medido) | E4: ln(x) | F4: ln(medido) - ln(x) | G4: Simulado no ajuste (t) | H4: Erro no ajuste (%) | I4: c sem este evento (validação cruzada) | J4: Simulado na validação cruzada (t) | K4: Erro na validação cruzada (%) | L4: Erro absoluto (%) | M4: Razão simulado / medido | N4: Dentro de fator 2? | O4: ln(simulado) | P4: Posição do medido (1 = menor) | Q4: Posição do simulado (1 = menor)
B5: da aba Eventos | C5: da aba Eventos | D5: = LN(medido) | E5: = LN(x) | F5: = D - E (o c ótimo é a média desta coluna, em exp) | G5: = c (com os 17 eventos) * x | H5: = (simulado / medido - 1) * 100 | I5: = EXP(média de F nos outros 16 eventos) | J5: = c sem este evento * x | K5: = (simulado / medido - 1) * 100 | L5: = |erro na validação cruzada| | M5: = simulado na validação cruzada / medido | N5: sim se a razão está entre 0,5 e 2 | O5: = LN(simulado na validação cruzada); usado no NSE em log | P5: ranking, para o Spearman | Q5: ranking, para o Spearman
A6: =Eventos!A6 | B6: =Eventos!Q6 | C6: =Eventos!I6 | D6: =LN(B6) | E6: =LN(C6) | F6: =D6-E6 | G6: =$D$26*C6 | H6: =(G6/B6-1)*100 | I6: =EXP((SUM($F$6:$F$22)-F6)/16) | J6: =I6*C6 | K6: =(J6/B6-1)*100 | L6: =ABS(K6) | M6: =J6/B6 | N6: =IF(AND(M6>=0.5,M6<=2),"sim","não") | O6: =LN(J6) | P6: =RANK(B6,$B$6:$B$22,1)+(COUNTIF($B$6:$B$22,B6)-1)/2 | Q6: =RANK(J6,$J$6:$J$22,1)+(COUNTIF($J$6:$J$22,J6)-1)/2
A7: =Eventos!A7 | B7: =Eventos!Q7 | C7: =Eventos!I7 | D7: =LN(B7) | E7: =LN(C7) | F7: =D7-E7 | G7: =$D$26*C7 | H7: =(G7/B7-1)*100 | I7: =EXP((SUM($F$6:$F$22)-F7)/16) | J7: =I7*C7 | K7: =(J7/B7-1)*100 | L7: =ABS(K7) | M7: =J7/B7 | N7: =IF(AND(M7>=0.5,M7<=2),"sim","não") | O7: =LN(J7) | P7: =RANK(B7,$B$6:$B$22,1)+(COUNTIF($B$6:$B$22,B7)-1)/2 | Q7: =RANK(J7,$J$6:$J$22,1)+(COUNTIF($J$6:$J$22,J7)-1)/2
A8: =Eventos!A8 | B8: =Eventos!Q8 | C8: =Eventos!I8 | D8: =LN(B8) | E8: =LN(C8) | F8: =D8-E8 | G8: =$D$26*C8 | H8: =(G8/B8-1)*100 | I8: =EXP((SUM($F$6:$F$22)-F8)/16) | J8: =I8*C8 | K8: =(J8/B8-1)*100 | L8: =ABS(K8) | M8: =J8/B8 | N8: =IF(AND(M8>=0.5,M8<=2),"sim","não") | O8: =LN(J8) | P8: =RANK(B8,$B$6:$B$22,1)+(COUNTIF($B$6:$B$22,B8)-1)/2 | Q8: =RANK(J8,$J$6:$J$22,1)+(COUNTIF($J$6:$J$22,J8)-1)/2
A9: =Eventos!A9 | B9: =Eventos!Q9 | C9: =Eventos!I9 | D9: =LN(B9) | E9: =LN(C9) | F9: =D9-E9 | G9: =$D$26*C9 | H9: =(G9/B9-1)*100 | I9: =EXP((SUM($F$6:$F$22)-F9)/16) | J9: =I9*C9 | K9: =(J9/B9-1)*100 | L9: =ABS(K9) | M9: =J9/B9 | N9: =IF(AND(M9>=0.5,M9<=2),"sim","não") | O9: =LN(J9) | P9: =RANK(B9,$B$6:$B$22,1)+(COUNTIF($B$6:$B$22,B9)-1)/2 | Q9: =RANK(J9,$J$6:$J$22,1)+(COUNTIF($J$6:$J$22,J9)-1)/2
A10: =Eventos!A10 | B10: =Eventos!Q10 | C10: =Eventos!I10 | D10: =LN(B10) | E10: =LN(C10) | F10: =D10-E10 | G10: =$D$26*C10 | H10: =(G10/B10-1)*100 | I10: =EXP((SUM($F$6:$F$22)-F10)/16) | J10: =I10*C10 | K10: =(J10/B10-1)*100 | L10: =ABS(K10) | M10: =J10/B10 | N10: =IF(AND(M10>=0.5,M10<=2),"sim","não") | O10: =LN(J10) | P10: =RANK(B10,$B$6:$B$22,1)+(COUNTIF($B$6:$B$22,B10)-1)/2 | Q10: =RANK(J10,$J$6:$J$22,1)+(COUNTIF($J$6:$J$22,J10)-1)/2
A11: =Eventos!A11 | B11: =Eventos!Q11 | C11: =Eventos!I11 | D11: =LN(B11) | E11: =LN(C11) | F11: =D11-E11 | G11: =$D$26*C11 | H11: =(G11/B11-1)*100 | I11: =EXP((SUM($F$6:$F$22)-F11)/16) | J11: =I11*C11 | K11: =(J11/B11-1)*100 | L11: =ABS(K11) | M11: =J11/B11 | N11: =IF(AND(M11>=0.5,M11<=2),"sim","não") | O11: =LN(J11) | P11: =RANK(B11,$B$6:$B$22,1)+(COUNTIF($B$6:$B$22,B11)-1)/2 | Q11: =RANK(J11,$J$6:$J$22,1)+(COUNTIF($J$6:$J$22,J11)-1)/2
A12: =Eventos!A12 | B12: =Eventos!Q12 | C12: =Eventos!I12 | D12: =LN(B12) | E12: =LN(C12) | F12: =D12-E12 | G12: =$D$26*C12 | H12: =(G12/B12-1)*100 | I12: =EXP((SUM($F$6:$F$22)-F12)/16) | J12: =I12*C12 | K12: =(J12/B12-1)*100 | L12: =ABS(K12) | M12: =J12/B12 | N12: =IF(AND(M12>=0.5,M12<=2),"sim","não") | O12: =LN(J12) | P12: =RANK(B12,$B$6:$B$22,1)+(COUNTIF($B$6:$B$22,B12)-1)/2 | Q12: =RANK(J12,$J$6:$J$22,1)+(COUNTIF($J$6:$J$22,J12)-1)/2
A13: =Eventos!A13 | B13: =Eventos!Q13 | C13: =Eventos!I13 | D13: =LN(B13) | E13: =LN(C13) | F13: =D13-E13 | G13: =$D$26*C13 | H13: =(G13/B13-1)*100 | I13: =EXP((SUM($F$6:$F$22)-F13)/16) | J13: =I13*C13 | K13: =(J13/B13-1)*100 | L13: =ABS(K13) | M13: =J13/B13 | N13: =IF(AND(M13>=0.5,M13<=2),"sim","não") | O13: =LN(J13) | P13: =RANK(B13,$B$6:$B$22,1)+(COUNTIF($B$6:$B$22,B13)-1)/2 | Q13: =RANK(J13,$J$6:$J$22,1)+(COUNTIF($J$6:$J$22,J13)-1)/2
A14: =Eventos!A14 | B14: =Eventos!Q14 | C14: =Eventos!I14 | D14: =LN(B14) | E14: =LN(C14) | F14: =D14-E14 | G14: =$D$26*C14 | H14: =(G14/B14-1)*100 | I14: =EXP((SUM($F$6:$F$22)-F14)/16) | J14: =I14*C14 | K14: =(J14/B14-1)*100 | L14: =ABS(K14) | M14: =J14/B14 | N14: =IF(AND(M14>=0.5,M14<=2),"sim","não") | O14: =LN(J14) | P14: =RANK(B14,$B$6:$B$22,1)+(COUNTIF($B$6:$B$22,B14)-1)/2 | Q14: =RANK(J14,$J$6:$J$22,1)+(COUNTIF($J$6:$J$22,J14)-1)/2
A15: =Eventos!A15 | B15: =Eventos!Q15 | C15: =Eventos!I15 | D15: =LN(B15) | E15: =LN(C15) | F15: =D15-E15 | G15: =$D$26*C15 | H15: =(G15/B15-1)*100 | I15: =EXP((SUM($F$6:$F$22)-F15)/16) | J15: =I15*C15 | K15: =(J15/B15-1)*100 | L15: =ABS(K15) | M15: =J15/B15 | N15: =IF(AND(M15>=0.5,M15<=2),"sim","não") | O15: =LN(J15) | P15: =RANK(B15,$B$6:$B$22,1)+(COUNTIF($B$6:$B$22,B15)-1)/2 | Q15: =RANK(J15,$J$6:$J$22,1)+(COUNTIF($J$6:$J$22,J15)-1)/2
A16: =Eventos!A16 | B16: =Eventos!Q16 | C16: =Eventos!I16 | D16: =LN(B16) | E16: =LN(C16) | F16: =D16-E16 | G16: =$D$26*C16 | H16: =(G16/B16-1)*100 | I16: =EXP((SUM($F$6:$F$22)-F16)/16) | J16: =I16*C16 | K16: =(J16/B16-1)*100 | L16: =ABS(K16) | M16: =J16/B16 | N16: =IF(AND(M16>=0.5,M16<=2),"sim","não") | O16: =LN(J16) | P16: =RANK(B16,$B$6:$B$22,1)+(COUNTIF($B$6:$B$22,B16)-1)/2 | Q16: =RANK(J16,$J$6:$J$22,1)+(COUNTIF($J$6:$J$22,J16)-1)/2
A17: =Eventos!A17 | B17: =Eventos!Q17 | C17: =Eventos!I17 | D17: =LN(B17) | E17: =LN(C17) | F17: =D17-E17 | G17: =$D$26*C17 | H17: =(G17/B17-1)*100 | I17: =EXP((SUM($F$6:$F$22)-F17)/16) | J17: =I17*C17 | K17: =(J17/B17-1)*100 | L17: =ABS(K17) | M17: =J17/B17 | N17: =IF(AND(M17>=0.5,M17<=2),"sim","não") | O17: =LN(J17) | P17: =RANK(B17,$B$6:$B$22,1)+(COUNTIF($B$6:$B$22,B17)-1)/2 | Q17: =RANK(J17,$J$6:$J$22,1)+(COUNTIF($J$6:$J$22,J17)-1)/2
... A22: =Eventos!A22 | B22: =Eventos!Q22 | C22: =Eventos!I22 | D22: =LN(B22) | E22: =LN(C22) | F22: =D22-E22 | G22: =$D$26*C22 | H22: =(G22/B22-1)*100 | I22: =EXP((SUM($F$6:$F$22)-F22)/16) | J22: =I22*C22 | K22: =(J22/B22-1)*100 | L22: =ABS(K22) | M22: =J22/B22 | N22: =IF(AND(M22>=0.5,M22<=2),"sim","não") | O22: =LN(J22) | P22: =RANK(B22,$B$6:$B$22,1)+(COUNTIF($B$6:$B$22,B22)-1)/2 | Q22: =RANK(J22,$J$6:$J$22,1)+(COUNTIF($J$6:$J$22,J22)-1)/2
A25: Resultados
A26: c calibrado com os 17 eventos (t por m³) | D26: =EXP(AVERAGE(F6:F22))
A27: Erro mediano na validação cruzada (%) | D27: =MEDIAN(L6:L22)
A28: Eventos dentro de fator 2 (%) | D28: =COUNTIF(N6:N22,"sim")/17*100
A29: NSE em escala log (validação cruzada) | D29: =1-SUMXMY2(O6:O22,D6:D22)/DEVSQ(D6:D22)
A30: NSE linear (validação cruzada; secundário) | D30: =1-SUMXMY2(J6:J22,B6:B22)/DEVSQ(B6:B22)
A31: Spearman (validação cruzada) | D31: =CORREL(P6:P22,Q6:Q22)

Sheet IC_refeita
A1: IC refeita: SY = alfa * (TR * Qpico)^beta * K * LS * C
A2: Formulação concentrada da Iniciação Científica, com K, LS e C médios da bacia (células D29 a D31). alfa e beta: regressão de ln(SY/KLSC) em ln(D).
A4: Evento | B4: Sedimento medido (t) | C4: D = TR * vazão de pico (m³ * m³/s) | D4: ln(D) | E4: ln(medido / KLSC) | F4: Simulado no ajuste (t) | G4: Erro no ajuste (%) | H4: beta sem este evento | I4: ln(alfa) sem este evento | J4: Simulado na validação cruzada (t) | K4: Erro na validação cruzada (%) | L4: Erro absoluto (%) | M4: Razão simulado / medido | N4: Dentro de fator 2? | O4: ln(simulado) | P4: Posição do medido (1 = menor) | Q4: Posição do simulado (1 = menor) | R4: ln(medido)
B5: da aba Eventos | C5: = TR * Qpico (aba Eventos) | D5: = LN(D) | E5: = LN(medido / (K*LS*C)) | F5: = alfa * D^beta * KLSC (alfa e beta dos 17 eventos) | G5: = (simulado / medido - 1) * 100 | H5: inclinação da regressão sem o evento (SLOPE nos outros 16) | I5: intercepto da regressão sem o evento | J5: = EXP(ln alfa + beta * ln D) * KLSC | K5: = (simulado / medido - 1) * 100 | L5: = |erro| | M5: = simulado / medido | N5: sim se a razão está entre 0,5 e 2 | O5: = LN(simulado na validação cruzada) | P5: ranking | Q5: ranking | R5: = LN(medido)
A6: =Eventos!A6 | B6: =Eventos!Q6 | C6: =Eventos!I6*Eventos!H6 | D6: =LN(C6) | E6: =LN(B6/$D$32) | F6: =$D$26*C6^$D$25*$D$32 | G6: =(F6/B6-1)*100 | H6: =(16*(SUMPRODUCT($D$6:$D$22,$E$6:$E$22)-D6*E6)-(SUM($D$6:$D$22)-D6)*(SUM($E$6:$E$22)-E6))/(16*(SUMSQ($D$6:$D$22)-D6^2)-(SUM($D$6:$D$22)-D6)^2) | I6: =((SUM($E$6:$E$22)-E6)-H6*(SUM($D$6:$D$22)-D6))/16 | J6: =EXP(I6+H6*D6)*$D$32 | K6: =(J6/B6-1)*100 | L6: =ABS(K6) | M6: =J6/B6 | N6: =IF(AND(M6>=0.5,M6<=2),"sim","não") | O6: =LN(J6) | P6: =RANK(B6,$B$6:$B$22,1)+(COUNTIF($B$6:$B$22,B6)-1)/2 | Q6: =RANK(J6,$J$6:$J$22,1)+(COUNTIF($J$6:$J$22,J6)-1)/2 | R6: =LN(B6)
A7: =Eventos!A7 | B7: =Eventos!Q7 | C7: =Eventos!I7*Eventos!H7 | D7: =LN(C7) | E7: =LN(B7/$D$32) | F7: =$D$26*C7^$D$25*$D$32 | G7: =(F7/B7-1)*100 | H7: =(16*(SUMPRODUCT($D$6:$D$22,$E$6:$E$22)-D7*E7)-(SUM($D$6:$D$22)-D7)*(SUM($E$6:$E$22)-E7))/(16*(SUMSQ($D$6:$D$22)-D7^2)-(SUM($D$6:$D$22)-D7)^2) | I7: =((SUM($E$6:$E$22)-E7)-H7*(SUM($D$6:$D$22)-D7))/16 | J7: =EXP(I7+H7*D7)*$D$32 | K7: =(J7/B7-1)*100 | L7: =ABS(K7) | M7: =J7/B7 | N7: =IF(AND(M7>=0.5,M7<=2),"sim","não") | O7: =LN(J7) | P7: =RANK(B7,$B$6:$B$22,1)+(COUNTIF($B$6:$B$22,B7)-1)/2 | Q7: =RANK(J7,$J$6:$J$22,1)+(COUNTIF($J$6:$J$22,J7)-1)/2 | R7: =LN(B7)
